Workbook

Sheet 0331
B1: 晉欣廠組合室生產人時性分析
B3: 日期 | D3: 03月31日 星期 二 | F3: 訂單量 | H3: 260891.4 | J3: 營業額 | L3: 8383382.9
B4: 項目 | D4: 項目 | F4: ➀ | H4: ➁ | J4: ➂ | L4: ➃ | N4: 異常停線 | P4: 短暫停線
B5: 人時性 | D5: 組合室 | F5: 全溫層 | H5: 4度C(含4度飯糰) | J5: 18度C 一配 | L5: 18度C 二配 | N5: 合計次數 | O5: 時間 | P5: 合計次數 | Q5: 設備次數
D6: 排關平均 | F6: =AVERAGE(D13:O13,P13:Q13,D30:E30,G30:H30,J30:M30) -> 386.82511 | H6: =AVERAGE(D13:P13,Q13) -> 145.72517 | J6: =AVERAGE(D30:E30,G30:H30) -> 736.25 | L6: =AVERAGE(J30:M30) -> 881.25 | N6: =[1]晉欣4度C0324!$Z$2 -> 0 | O6: =[1]晉欣4度C0324!$AA$2 -> 0 | P6: 4 | Q6: 3
D7: 實績平均 | F7: =AVERAGE(D14:O14,P14:Q14,D31:E31,J31:M31,G31:H31) -> 349.19636 | H7: =AVERAGE(D14:P14,Q14) -> 130.57841 | J7: =AVERAGE(D31:E31,G31:H31) -> 720.39209 | L7: =AVERAGE(J31:M31) -> 743.16343
D8: 達成率平均 | F8: =AVERAGE(D15:O15,P15:Q15,D32:E32,G32:H32,J32:K32,L32) -> 0.89258027 | H8: =AVERAGE(D15:O15,P15:Q15) -> 0.89923103 | J8: =AVERAGE(D32:E32,G32:H32) -> 0.95427064 | L8: =AVERAGE(J32:M32) -> 0.84040887
B10: 溫層 | D10: ➁4度C-各編組展開
B11: 編組 | D11: 1 | E11: 2 | F11: 3 | G11: 4 | H11: 5 | I11: 6 | J11: 7 | K11: 8 | L11: 9 | M11: 10 | N11: 11 | O11: 12 | P11: 13 | Q11: 14
D12: 4度一組 | E12: 4度二組A | F12: 4度二組B | G12: 4度二組C1 | H12: 4度二組C2 | I12: 4度三組 | J12: 4度四組 | K12: 4度五組 | L12: 綜合一組 | M12: 綜合二組 | N12: 綜合三組 | O12: 綜合四組 | P12: 便當組 | Q12: 壽司線
B13: 人時性 | C13: 排關 | D13: 126.55806 | E13: 114.93927 | F13: 159.31333 | G13: 392.85714 | H13: 223.21429 | I13: 88.487999 | J13: 76.174464 | K13: 103.33228 | L13: 160.438 | M13: 86.784086 | N13: 86.762208 | O13: 92.438095 | P13: 178.85319 | Q13: 150
C14: 實績 | D14: 113.6031 | E14: 106.77365 | F14: 136.26862 | G14: 333.31822 | H14: 208.86508 | I14: 75.707603 | J14: 69.466952 | K14: 92.338131 | L14: 145.802 | M14: 78.393833 | N14: 80.300148 | O14: 78.496963 | P14: 170.35158 | Q14: 138.41188
C15: 達成率 | D15: =D14/D13 -> 0.8976362 | E15: =E14/E13 -> 0.92895706 | F15: =F14/F13 -> 0.85534978 | G15: =G14/G13 -> 0.84844638 | H15: =H14/H13 -> 0.93571555 | I15: =I14/I13 -> 0.85556916 | J15: =J14/J13 -> 0.91194539 | K15: =K14/K13 -> 0.8936039 | ... Q15: =Q14/Q13 -> 0.92274589
B16: 作業 時間 | C16: 開始 | D16: 0.29166667 | E16: 0.16666667 | F16: 0.16666667 | G16: 0.16666667 | H16: 0.16666667 | I16: 0.29166667 | J16: 0.33333333 | K16: 0.33333333 | L16: 0.5 | M16: 0.5 | N16: 0.5 | O16: 0.70833333 | P16: 0.16666667 | Q16: 0.17361111
C17: 結束 | D17: 0.76527778 | E17: 0.60625 | F17: 0.56111111 | G17: 0.80208333 | H17: 0.73958333 | I17: 0.78888889 | J17: 0.80694444 | K17: 0.75833333 | L17: 0.89375 | M17: 0.99375 | N17: 0.96805556 | O17: 0.85486111 | P17: 0.57569444 | Q17: 0.58125
B18: 產線異常 (5分鐘以上) | C18: 次數
C19: 時間/分
B20: 短暫停線 (5分鐘以下) | C20: 次數 | D20: 1 | G20: 1 | L20: 1 | N20: 1
C21: 設備次數 | E21: 2 | M21: 1
B22: 配置人數 | D22: 19.714286 | E22: 17.5 | F22: 14 | G22: 5.8 | H22: 7 | I22: 17 | J22: 18.666667 | K22: 17.125 | L22: 15.5 | M22: 18.5 | N22: 17.375 | O22: 16.2 | P22: 13 | Q22: 11.2
B23: 主要應用設備 | D23: ET-600 | E23: ET-600 | F23: ET-600 | G23: 八爪機 | H23: 十爪機 | I23: ET-55 | J23: ET-55 | K23: ET-55 | L23: ET-55 | M23: ET-55 | N23: ET-55 | O23: ET-55 | P23: 伺服包裝機 | Q23: 伺服包裝機
B24: 次要應用設備
B25: 備註 | E25: 熱麵固定線 | G25: 烤飯糰 | H25: 烤飯糰 | K25: 吸收產線 | P25: 大口固定線
D27: ➂18度C 一配-各編組展開 | I27: ➃18度C 二配-各編組展開
B28: 編組 | D28: 1 | E28: 2 | F28: 3 | G28: 4 | H28: 5 | I28: 1 | J28: 2 | K28: 3 | L28: 4 | M28: 5
D29: 連續式 海苔機 | E29: 3300型 飯糰機A | F29: 3300型 飯糰機B | G29: 3600型 飯糰機A | H29: 3600型 飯糰機B | I29: 夾心型 飯糰機 | J29: 3300型 飯糰機A | K29: 3300型 飯糰機B | L29: 3600型 飯糰機A | M29: 3600型 飯糰機B
B30: 人時性 | C30: 排關 | D30: 320 | E30: 825 | F30: 825 | G30: 900 | H30: 900 | I30: 680 | J30: 825 | K30: 900 | L30: 900 | M30: 900
C31: 實績 | D31: 266.81053 | E31: 772.33057 | F31: 0 | G31: 899.60013 | H31: 942.82714 | I31: 0 | J31: 581 | K31: 590.1 | L31: 880.16367 | M31: 921.39007
C32: 達成率 | D32: =D31/D30 -> 0.83378289 | E32: =E31/E30 -> 0.93615827 | F32: =F31/F30 -> 0 | G32: =G31/G30 -> 0.9995557 | H32: =H31/H30 -> 1.0475857 | I32: =I31/I30 -> 0 | J32: =J31/J30 -> 0.70424242 | K32: =K31/K30 -> 0.65566667 | ... M32: =M31/M30 -> 1.0237667
B33: 作業 時間 | C33: 開始 | D33: 0.18055556 | E33: 0.18055556 | F33: 0 | G33: 3138 | H33: 0.18055556 | I33: 0 | J33: 0.72222222 | K33: 0.72222222 | L33: 0.72222222 | M33: 0.72222222
C34: 結束 | D34: 0.22847222 | E34: 0.32638889 | F34: 0 | G34: 1070.6897 | H34: 0.42638889 | I34: 0 | J34: 0.73263889 | K34: 0.82291667 | L34: 46113.118 | M34: 1.0256944
B35: 配置人數 | D35: 5.5 | E35: 3.6666667 | F35: 0 | G35: 3.6 | H35: 3.4 | I35: 0 | J35: 4 | K35: 3.6666667 | L35: 3.4 | M35: 3.5
B36: 主要應用設備 | D36: 連續式 海苔機 | E36: 3300型 | F36: 3300型 | G36: 3600型 | H36: 3600型 | I36: 夾心型 | J36: 3300型 | K36: 3300型 | L36: 3600型 | M36: 3600型
B37: 次要應用設備
B38: 備註

Sheet 晉欣18度C0331
A1: 晉欣廠18度C日報分析 | D1: 總生產量 | E1: =SUM(G5:G124) -> 80487 | F1: 營業額 | G1: =SUM(H5:H124) -> 1497428.9 | H1: 出勤人數 | I1: =+J16+J64+J24+J38+J51+J81+J100+J91+J57+J124+J111 -> 38.533333 | J1: 生產實績 | M1: 日報登錄
A2: 03月31日 星期二 | D2: 人時性 | E2: =AVERAGE(L16,L24,L38,L51,L100,L111,L91) -> 538.13611 | F2: 平均廠價 | G2: =G1/E1 -> 18.604606 | H2: 多次生產數 | I2: =COUNT(I5:I124) -> 0
A3: 線別 | B3: 品類 | D3: 品名 | F3: 廠價 | G3: 生產量 | H3: 營收 | I3: 多次 生產 | J3: 人數 | K3: 產能/時 | L3: 人時性 | M3: 生產時間 | O3: 換線/分 | P3: 稼動時間/分 | Q3: 休息時間
M4: 開始 | N4: 結束 | Q4: 開始 | R4: 結束
A5: 壽司線 | B5: 0 | D5: 雙饗雙手卷(捲) | F5: 0 | G5: 1258 | H5: =F5*G5 -> 0 | J5: 9 | K5: =G5/P5*60 -> 1509.6 | L5: =K5/J5 -> 167.73333 | M5: 0.17361111 | N5: 0.20833333 | O5: 10 | P5: =(N5-M5)*24*60 -> 50
B6: 0 | D6: 海饌雙手卷(捲) | F6: 0 | G6: 1315 | H6: =F6*G6 -> 0 | J6: 9 | K6: =G6/P6*60 -> 1578 | L6: =K6/J6 -> 175.33333 | M6: 0.21180556 | N6: 0.24652778 | O6: 5 | P6: =(N6-M6)*24*60 -> 50
B7: 壽司手卷 | D7: 雙倍德腸飯卷 | F7: 36.45 | G7: 1581 | H7: =F7*G7 -> 57627.45 | J7: 11 | K7: =G7/P7*60 -> 1459.3846 | L7: =K7/J7 -> 132.67133 | M7: 0.25 | N7: 0.29513889 | O7: 5 | P7: =(N7-M7)*24*60 -> 65
B8: 壽司手卷 | D8: 明太子泡菜牛飯卷 | F8: 27.05 | G8: 415 | H8: =F8*G8 -> 11225.75 | J8: 13 | K8: =G8/P8*60 -> 1383.3333 | L8: =K8/J8 -> 106.41026 | M8: 0.29861111 | N8: 0.31111111 | O8: 5 | P8: =(N8-M8)*24*60 -> 18 | Q8: 0.31805556 | R8: 0.34930556
B9: 壽司手卷 | D9: 銀鮭美乃滋脆卷 | F9: 19.7 | G9: 1846 | H9: =F9*G9 -> 36366.2 | J9: 13 | K9: =G9/P9*60 -> 1165.8947 | L9: =K9/J9 -> 89.684211 | M9: 0.35277778 | N9: 0.41875 | O9: 5 | P9: =(N9-M9)*24*60 -> 95
B10: 壽司手卷 | D10: 日式鮪魚美乃滋脆卷 | F10: 17.87 | G10: 831 | H10: =F10*G10 -> 14849.97 | J10: 13 | K10: =G10/P10*60 -> 1246.5 | L10: =K10/J10 -> 95.884615 | M10: 0.42222222 | N10: 0.45 | O10: 5 | P10: =(N10-M10)*24*60 -> 40
B11: 壽司手卷 | D11: 長野稻荷壽司 | F11: 25.64 | G11: 664 | H11: =F11*G11 -> 17024.96 | J11: 10 | K11: =G11/P11*60 -> 1593.6 | L11: =K11/J11 -> 159.36 | M11: 0.45347222 | N11: 0.47083333 | O11: 5 | P11: =(N11-M11)*24*60 -> 25
B12: 壽司手卷 | D12: 雙饗雙手卷 | F12: 29.52 | G12: 1258 | H12: =F12*G12 -> 37136.16 | J12: 12 | K12: =G12/P12*60 -> 1797.1429 | L12: =K12/J12 -> 149.7619 | M12: 0.47430556 | N12: 0.50347222 | O12: 5 | P12: =(N12-M12)*24*60 -> 42
B13: 壽司手卷 | D13: 海饌雙手卷 | F13: 29.857 | G13: 1315 | H13: =F13*G13 -> 39261.955 | J13: 12 | K13: =G13/P13*60 -> 1834.8837 | L13: =K13/J13 -> 152.90698 | M13: 0.50694444 | N13: 0.53680556 | O13: 5 | P13: =(N13-M13)*24*60 -> 43
B14: 飯糰 | D14: 兩粒飯糰(鮪魚.焦糖鮭魚) | F14: 28.57 | G14: 1518 | H14: =F14*G14 -> 43369.26 | J14: 10 | K14: =G14/P14*60 -> 1543.7288 | L14: =K14/J14 -> 154.37288 | M14: 0.54027778 | N14: 0.58125 | O14: 5 | P14: =(N14-M14)*24*60 -> 59
B15: 0 | F15: 0 | H15: =F15*G15 -> 0
B16: 0 | C16: 壽司線 | D16: 平均 | J16: =AVERAGE(J5:J15) -> 11.2 | K16: =AVERAGE(K5:K15) -> 1511.2068 | L16: =AVERAGE(L5:L15) -> 138.41188
A17: 捲壽司機 | B17: 壽司手卷 | D17: 雙鬆細卷 | F17: 14.03 | G17: 453 | H17: =F17*G17 -> 6355.59 | J17: 6 | K17: =G17/P17*60 -> 1430.5263 | L17: =K17/J17 -> 238.42105 | M17: 0.18055556 | N17: 0.19375 | O17: 20 | P17: =(N17-M17)*24*60 -> 19
B18: 飯糰 | D18: 經典鮪魚沙拉細卷 | F18: 14.49 | G18: 738 | H18: =F18*G18 -> 10693.62 | J18: 5 | K18: =G18/P18*60 -> 1476 | L18: =K18/J18 -> 295.2 | M18: 0.20763889 | N18: 0.22847222 | O18: 20 | P18: =(N18-M18)*24*60 -> 30
B19: 0 | F19: 0 | H19: =F19*G19 -> 0
B20: 0 | F20: 0 | H20: =F20*G20 -> 0
B21: 0 | F21: 0 | H21: =F21*G21 -> 0
B22: 0 | F22: 0 | H22: =F22*G22 -> 0
B23: 0 | F23: 0 | H23: =F23*G23 -> 0
B24: 0 | C24: 連續式 海苔機 | D24: 平均 | J24: =AVERAGE(J17:J23) -> 5.5 | K24: =AVERAGE(K17:K23) -> 1453.2632 | L24: =AVERAGE(L17:L23) -> 266.81053
A25: 3300型 飯糰機A | B25: 飯糰 | D25: 煙燻培根飯糰(區) | F25: 15.03 | G25: 2460 | H25: =F25*G25 -> 36973.8 | J25: 4 | K25: =G25/P25*60 -> 2784.9057 | L25: =K25/J25 -> 696.22642 | M25: 0.18055556 | N25: 0.21736111 | O25: 20 | P25: =(N25-M25)*24*60 -> 53
B26: 飯糰 | D26: 碳烤燒肉飯飯糰(區) | F26: 18.18 | G26: 3162 | H26: =F26*G26 -> 57485.16 | J26: 4 | K26: =G26/P26*60 -> 2790 | L26: =K26/J26 -> 697.5 | M26: 0.23125 | N26: 0.27847222 | O26: 20 | P26: =(N26-M26)*24*60 -> 68
B27: 飯糰 | D27: 鮭魚奶油醬油飯糰 | F27: 18.53 | G27: 2262 | H27: =F27*G27 -> 41914.86 | J27: 3 | K27: =G27/P27*60 -> 2769.7959 | L27: =K27/J27 -> 923.26531 | M27: 0.29236111 | N27: 0.32638889 | O27: 20 | P27: =(N27-M27)*24*60 -> 49
B28: 0
B29: 0
B30: 0
B31: 0
B32: 0 | F32: 0 | H32: =F32*G32 -> 0
B33: 0 | F33: 0 | H33: =F33*G33 -> 0
B34: 0 | F34: 0 | H34: =F34*G34 -> 0
B35: 0 | F35: 0 | H35: =F35*G35 -> 0
B36: 0 | F36: 0 | H36: =F36*G36 -> 0
B37: 0 | F37: 0 | H37: =F37*G37 -> 0
B38: 0 | C38: 3300型 飯糰機A | D38: 平均 | J38: =AVERAGE(J25:J37) -> 3.6666667 | K38: =AVERAGE(K25:K37) -> 2781.5672 | L38: =AVERAGE(L25:L37) -> 772.33057
A39: 3300型B 飯糰機 | B39: 0 | F39: 0 | H39: =F39*G39 -> 0
B40: 0 | F40: 0 | H40: =F40*G40 -> 0
...

Sheet 晉欣4度C0331
A1: 晉欣廠四度C日報分析 | D1: 總生產量 | E1: =SUM(G5:G173) -> 180404.4 | F1: 營業額 | G1: =SUM(H5:H173) -> 6885953.9 | H1: 出勤人數 | I1: =M17+M30+M43+M56+M69+M82+M95+M108+M121+M134+M147+M160+M173 -> 197.38095 | J1: 產線配置圖 | M1: 生產實績 | P1: 人時性差異分析 | T1: 日報登錄 | Z1: 合計 次數 | AA1: 合計 時間/分 | AB1: 產線異常分析 說明(5分鐘以上) | AD1: 合計 次數 | AE1: 合計 設備次數 | AF1: 產能差異分析
A2: 03月31日 星期 二 | D2: 人時性 | E2: =AVERAGE(O17,O30,O43,O56,O69,O82,O95,O108,O121,O134,O147,O160,O173) -> 129.50814 | F2: 平均廠價 | G2: =G1/E1 -> 38.169545 | H2: 多次生產數 | I2: =COUNT(I5:I173) -> 8 | Z2: =Z17+Z30+Z43+Z56+Z69+Z82+Z95+Z108+Z121+Z134+Z147+Z160+Z173 -> 0 | AA2: =AA17+AA30+AA43+AA56+AA69+AA82+AA95+AA108+AA121+AA134+AA147+AA160+AA173 -> 0 | AD2: =AD17+AD30+AD43+AD56+AD69+AD82+AD95+AD108+AD121+AD134+AD147+AD160+AD173 -> 4 | AE2: =AE17+AE30+AE43+AE56+AE69+AE82+AE95+AE108+AE121+AE134+AE147+AE160+AE173 -> 3
A3: 線別 | B3: 品類 | D3: 品名 | F3: 廠價 | G3: 生產量 | H3: 營收 | I3: 多次 生產 | J3: 人數 | K3: 產能/時 | L3: 人時性 | M3: 人數 | N3: 產能/時 | O3: 人時性 | P3: 人數 | Q3: 人時性 | R3: 達成率 | S3: 達成率平均 | T3: 生產時間 | V3: 前置、換線時間/分 | W3: 稼動時間/分 | X3: 休息時間 | Z3: 產線異常統計 (5分鐘以上) | AB3: 分析說明 | AD3: 短暫停線統計 (5分鐘以下) | AF3: 產能/時 | AG3: 達成率 | AH3: 達成率平均
T4: 開始 | U4: 結束 | X4: 開始 | Y4: 結束 | Z4: 次數 | AA4: 時間/分 | AD4: 總次數 | AE4: 設備因素(次數)
A5: 四度一組 (ET-600) | B5: 季節調理麵 | D5: 椒麻香蔥雞涼拌麵 | F5: 37.94 | G5: 4112.55 | H5: =F5*G5 -> 156030.15 | J5: 20 | K5: 2400 | L5: 120 | M5: 20 | N5: =G5/W5*60 -> 2243.2091 | O5: =N5/M5 -> 112.16045 | P5: =M5-J5 -> 0 | Q5: =O5-L5 -> -7.8395455 | R5: =O5/L5 -> 0.93467045 | S5: =R17 -> 0.89025061 | T5: 0.29166667 | U5: 0.36805556 | V5: 5 | W5: =(U5-T5)*24*60 -> 110 | AF5: =N5-K5 -> -156.79091 | AG5: =N5/K5 -> 0.93467045 | AH5: =AG17 -> 0.9354246
B6: 季節調理麵 | D6: 台式麻醬涼麵 | F6: 31.266132 | G6: 2633.8 | H6: =F6*G6 -> 82348.738 | J6: 18 | K6: 2600 | L6: 144.44444 | M6: 20 | N6: =G6/W6*60 -> 2469.1875 | O6: =N6/M6 -> 123.45937 | P6: =M6-J6 -> 2 | Q6: =O6-L6 -> -20.985069 | R6: =O6/L6 -> 0.85471875 | T6: 0.37291667 | U6: 0.41736111 | V6: 7 | W6: =(U6-T6)*24*60 -> 64 | AF6: =N6-K6 -> -130.8125 | AG6: =N6/K6 -> 0.9496875
B7: 季節調理麵 | D7: 大滿足麻醬涼麵 | F7: 38 | G7: 5032.2 | H7: =F7*G7 -> 191223.6 | J7: 19 | K7: 2600 | L7: 136.84211 | M7: 20 | N7: =G7/W7*60 -> 2516.1 | O7: =N7/M7 -> 125.805 | P7: =M7-J7 -> 1 | Q7: =O7-L7 -> -11.037105 | R7: =O7/L7 -> 0.91934423 | T7: 0.43263889 | U7: 0.51597222 | V7: 22 | W7: =(U7-T7)*24*60 -> 120 | X7: 0.42083333 | Y7: 0.42986111 | AD7: 1 | AF7: =N7-K7 -> -83.9 | AG7: =N7/K7 -> 0.96773077
B8: 季節調理麵 | D8: 大滿足麻醬涼麵 | F8: 38 | G8: 3354.8 | H8: =F8*G8 -> 127482.4 | J8: 19 | K8: 2600 | L8: 136.84211 | M8: 20 | N8: =G8/W8*60 -> 2485.037 | O8: =N8/M8 -> 124.25185 | P8: =M8-J8 -> 1 | Q8: =O8-L8 -> -12.590253 | R8: =O8/L8 -> 0.9079943 | T8: 0.55625 | U8: 0.6125 | V8: 5 | W8: =(U8-T8)*24*60 -> 81 | AF8: =N8-K8 -> -114.96296 | AG8: =N8/K8 -> 0.95578348
B9: 季節調理麵 | D9: 台式麻醬涼麵 | F9: 31.266132 | G9: 1418.2 | H9: =F9*G9 -> 44341.628 | J9: 18 | K9: 2600 | L9: 144.44444 | M9: 20 | N9: =G9/W9*60 -> 2431.2 | O9: =N9/M9 -> 121.56 | P9: =M9-J9 -> 2 | Q9: =O9-L9 -> -22.884444 | R9: =O9/L9 -> 0.84156923 | T9: 0.61736111 | U9: 0.64166667 | V9: 7 | W9: =(U9-T9)*24*60 -> 35 | AF9: =N9-K9 -> -168.8 | AG9: =N9/K9 -> 0.93507692
B10: 季節調理麵 | D10: 椒麻香蔥雞涼拌麵 | F10: 37.94 | G10: 2214.45 | H10: =F10*G10 -> 84016.233 | J10: 20 | K10: 2400 | L10: 120 | M10: 20 | N10: =G10/W10*60 -> 2109 | O10: =N10/M10 -> 105.45 | P10: =M10-J10 -> 0 | Q10: =O10-L10 -> -14.55 | R10: =O10/L10 -> 0.87875 | T10: 0.64722222 | U10: 0.69097222 | V10: 8 | W10: =(U10-T10)*24*60 -> 63 | AF10: =N10-K10 -> -291 | AG10: =N10/K10 -> 0.87875
B11: 微波主食 | D11: 二配濃起司燻腸紅醬焗烤飯 | F11: 50.67 | G11: 1915 | H11: =F11*G11 -> 97033.05 | J11: 18 | K11: 1500 | L11: 83.333333 | M11: 18 | N11: =G11/W11*60 -> 1367.8571 | O11: =N11/M11 -> 75.992063 | P11: =M11-J11 -> 0 | Q11: =O11-L11 -> -7.3412698 | R11: =O11/L11 -> 0.91190476 | T11: 0.70833333 | U11: 0.76666667 | V11: 5 | W11: =(U11-T11)*24*60 -> 84 | AF11: =N11-K11 -> -132.14286 | AG11: =N11/K11 -> 0.91190476
B12: 0 | F12: 0 | H12: =F12*G12 -> 0 | AF12: =N12-K12 -> 0 | AG12: =N12/K12 -> #DIV/0!
B13: 0 | F13: 0 | H13: =F13*G13 -> 0 | AF13: =N13-K13 -> 0 | AG13: =N13/K13 -> #DIV/0!
B14: 0 | F14: 0 | H14: =F14*G14 -> 0 | W14: =(U14-T14)*24*60 -> 0
B15: 0 | F15: 0 | H15: =F15*G15 -> 0 | W15: =(U15-T15)*24*60 -> 0
B16: 0 | F16: 0 | H16: =F16*G16 -> 0 | W16: =(U16-T16)*24*60 -> 0
B17: 0 | C17: 4度一組 | D17: 平均 | J17: 18.857143 | K17: 2385.7143 | L17: 126.55806 | M17: =AVERAGE(M5:M16) -> 19.714286 | N17: =AVERAGE(N5:N16) -> 2231.6558 | O17: =AVERAGE(O5:O16) -> 112.66839 | P17: =M17-J17 -> 0.85714286 | Q17: =O17-L17 -> -13.88967 | R17: =O17/L17 -> 0.89025061 | W17: =(U17-T17)*24*60 -> 0 | Z17: =SUM(Z5:Z16) -> 0 | AA17: =SUM(AA5:AA16) -> 0 | AD17: =SUM(AD5:AD16) -> 1 | AE17: =SUM(AE5:AE16) -> 0 | AF17: =N17-K17 -> -154.05846 | AG17: =N17/K17 -> 0.9354246
A18: 四度二組A 熱麵 固定線 (ET-55) | B18: 季節調理麵 | D18: 日式蕎麥沾麵 | F18: 36.86 | G18: 3405.6 | H18: =F18*G18 -> 125530.42 | J18: 17 | K18: 2250 | L18: 132.35294 | M18: 18 | N18: =G18/W18*60 -> 2245.4505 | O18: =N18/M18 -> 124.74725 | P18: =M18-J18 -> 1 | Q18: =O18-L18 -> -7.6056884 | R18: =O18/L18 -> 0.9425348 | S18: =R30 -> 0.93015782 | T18: 0.16666667 | U18: 0.22986111 | V18: 5 | W18: =(U18-T18)*24*60 -> 91 | AF18: =N18-K18 -> -4.5494505 | AG18: =N18/K18 -> 0.99797802 | AH18: =AG30 -> 0.97501333
B19: 熱食義麵 | D19: 愛恨椒芝麵 | F19: 38.39 | G19: 2606 | H19: =F19*G19 -> 100044.34 | J19: 16 | K19: 1636 | L19: 102.25 | M19: 17 | N19: =G19/W19*60 -> 1475.0943 | O19: =N19/M19 -> 86.770255 | P19: =M19-J19 -> 1 | Q19: =O19-L19 -> -15.479745 | R19: =O19/L19 -> 0.84860885 | T19: 0.24513889 | U19: 0.31875 | V19: 22 | W19: =(U19-T19)*24*60 -> 106 | X19: 0.23333333 | Y19: 0.24236111 | AF19: =N19-K19 -> -160.90566 | AG19: =N19/K19 -> 0.90164691
B20: 小菜微波 | D20: 古早味炒炊粉 | F20: 43.14 | G20: 2216 | H20: =F20*G20 -> 95598.24 | J20: 16 | K20: 1440 | L20: 90 | M20: 16 | N20: =G20/W20*60 -> 1429.6774 | O20: =N20/M20 -> 89.354839 | P20: =M20-J20 -> 0 | Q20: =O20-L20 -> -0.64516129 | R20: =O20/L20 -> 0.99283154 | T20: 0.32361111 | U20: 0.38819444 | V20: 7 | W20: =(U20-T20)*24*60 -> 93 | AE20: 1 | AF20: =N20-K20 -> -10.322581 | AG20: =N20/K20 -> 0.99283154
B21: 熱食義麵 | D21: 辣腐乳麻醬拌麵 | F21: 38.1 | G21: 1457 | H21: =F21*G21 -> 55511.7 | J21: 17 | K21: 1500 | L21: 88.235294 | M21: 16 | N21: =G21/W21*60 -> 1324.5455 | O21: =N21/M21 -> 82.784091 | P21: =M21-J21 -> -1 | Q21: =O21-L21 -> -5.4512032 | R21: =O21/L21 -> 0.9382197 | T21: 0.39305556 | U21: 0.43888889 | V21: 7 | W21: =(U21-T21)*24*60 -> 66 | AF21: =N21-K21 -> -175.45455 | AG21: =N21/K21 -> 0.8830303
B22: 季節調理麵 | D22: 大滿足香辣涼麵 | F22: 38.630952 | G22: 6049 | H22: =F22*G22 -> 233678.63 | J22: 18 | K22: 2600 | L22: 144.44444 | M22: 20 | N22: =G22/W22*60 -> 2688.4444 | O22: =N22/M22 -> 134.42222 | P22: =M22-J22 -> 2 | Q22: =O22-L22 -> -10.022222 | R22: =O22/L22 -> 0.93061538 | T22: 0.47916667 | U22: 0.57291667 | V22: 5 | W22: =(U22-T22)*24*60 -> 135 | AE22: 1 | AF22: =N22-K22 -> 88.444444 | AG22: =N22/K22 -> 1.0340171
B23: 季節調理麵 | D23: 日式蕎麥沾麵 | F23: 36.86 | G23: 851.4 | H23: =F23*G23 -> 31382.604 | I23: 1 | J23: 17 | K23: 2250 | L23: 132.35294 | M23: 18 | N23: =G23/W23*60 -> 2221.0435 | O23: =N23/M23 -> 123.3913 | P23: =M23-J23 -> 1 | Q23: =O23-L23 -> -8.9616368 | R23: =O23/L23 -> 0.93228986 | T23: 0.5875 | U23: 0.60347222 | V23: 21 | W23: =(U23-T23)*24*60 -> 23 | X23: 0.57638889 | Y23: 0.58472222 | AF23: =N23-K23 -> -28.956522 | AG23: =N23/K23 -> 0.98713043
B24: 0 | F24: 0 | H24: =F24*G24 -> 0 | W24: =(U24-T24)*24*60 -> 0 | AF24: =N24-K24 -> 0 | AG24: =N24/K24 -> #DIV/0!
B25: 0 | F25: 0 | H25: =F25*G25 -> 0 | W25: =(U25-T25)*24*60 -> 0 | AF25: =N25-K25 -> 0 | AG25: =N25/K25 -> #DIV/0!
B26: 0 | F26: 0 | H26: =F26*G26 -> 0 | W26: =(U26-T26)*24*60 -> 0 | AF26: =N26-K26 -> 0 | AG26: =N26/K26 -> #DIV/0!
B27: 0 | F27: 0 | H27: =F27*G27 -> 0 | W27: =(U27-T27)*24*60 -> 0 | AF27: =N27-K27 -> 0 | AG27: =N27/K27 -> #DIV/0!
B28: 0 | F28: 0 | H28: =F28*G28 -> 0 | W28: =(U28-T28)*24*60 -> 0 | AF28: =N28-K28 -> 0 | AG28: =N28/K28 -> #DIV/0!
B29: 0 | F29: 0 | H29: =F29*G29 -> 0 | W29: =(U29-T29)*24*60 -> 0 | AF29: =N29-K29 -> 0
B30: 0 | C30: 4度二組A | D30: 平均 | J30: 16.833333 | K30: 1946 | L30: 114.93927 | M30: =AVERAGE(M18:M29) -> 17.5 | N30: =AVERAGE(N18:N29) -> 1897.3759 | O30: =AVERAGE(O18:O29) -> 106.91166 | P30: =M30-J30 -> 0.66666667 | Q30: =O30-L30 -> -8.0276095 | R30: =O30/L30 -> 0.93015782 | Z30: =SUM(Z18:Z29) -> 0 | AA30: =SUM(AA18:AA29) -> 0 | AD30: =SUM(AD18:AD29) -> 0 | AE30: =SUM(AE18:AE29) -> 2 | AF30: =N30-K30 -> -48.624052 | AG30: =N30/K30 -> 0.97501333
A31: 四度二組 (ET-55) | B31: 飯糰 | D31: 大口日式塔塔醬蝦排飯糰 | F31: 35.33 | G31: 2292 | H31: =F31*G31 -> 80976.36 | J31: 12 | K31: 2118 | L31: 176.5 | M31: 12 | N31: =G31/W31*60 -> 1858.3784 | O31: =N31/M31 -> 154.86486 | P31: =M31-J31 -> 0 | Q31: =O31-L31 -> -21.635135 | R31: =O31/L31 -> 0.87742133 | S31: =R43 -> 0.84435444 | T31: 0.16666667 | U31: 0.21805556 | V31: 5 | W31: =(U31-T31)*24*60 -> 74 | AF31: =N31-K31 -> -259.62162 | AG31: =N31/K31 -> 0.87742133 | AH31: =AG43 -> 0.84518411
B32: 飯糰 | D32: 大口起司熔岩白醬炸魚飯糰 | F32: 34.23 | G32: 2208 | H32: =F32*G32 -> 75579.84 | J32: 12 | K32: 2118 | L32: 176.5 | M32: 12 | N32: =G32/W32*60 -> 1865.9155 | O32: =N32/M32 -> 155.49296 | P32: =M32-J32 -> 0 | Q32: =O32-L32 -> -21.007042 | R32: =O32/L32 -> 0.88097993 | T32: 0.22291667 | U32: 0.27222222 | V32: 7 | W32: =(U32-T32)*24*60 -> 71 | AF32: =N32-K32 -> -252.08451 | AG32: =N32/K32 -> 0.88097993
B33: 飯糰 | D33: 大口義式香草雞腿排飯糰 | F33: 36.41 | G33: 3762.9 | H33: =F33*G33 -> 137007.19 | J33: 10 | K33: 2769 | L33: 276.9 | M33: 10 | N33: =G33/W33*60 -> 2235.3861 | O33: =N33/M33 -> 223.53861 | P33: =M33-J33 -> 0 | Q33: =O33-L33 -> -53.361386 | R33: =O33/L33 -> 0.80729005 | T33: 0.2875 | U33: 0.35763889 | V33: 22 | W33: =(U33-T33)*24*60 -> 101 | X33: 0.27569444 | Y33: 0.28472222 | AF33: =N33-K33 -> -533.61386 | AG33: =N33/K33 -> 0.80729005
B34: 微波主食 | D34: 壹號醬壽喜燒牛丼 | F34: 54.09 | G34: 2670.75 | H34: =F34*G34 -> 144460.87 | J34: 18 | K34: 1500 | L34: 83.333333 | M34: 18 | N34: =G34/W34*60 -> 1261.7717 | O34: =N34/M34 -> 70.098425 | P34: =M34-J34 -> 0 | Q34: =O34-L34 -> -13.234908 | R34: =O34/L34 -> 0.8411811 | T34: 0.3625 | U34: 0.45069444 | V34: 7 | W34: =(U34-T34)*24*60 -> 127 | AF34: =N34-K34 -> -238.22835 | AG34: =N34/K34 -> 0.8411811
B35: 微波主食 | D35: 韓式泡菜豬肉豆腐丼飯 | F35: 50.67 | G35: 2140 | H35: =F35*G35 -> 108433.8 | J35: 18 | K35: 1500 | L35: 83.333333 | M35: 18 | N35: =G35/W35*60 -> 1234.6154 | O35: =N35/M35 -> 68.589744 | P35: =M35-J35 -> 0 | Q35: =O35-L35 -> -14.74359 | R35: =O35/L35 -> 0.82307692 | T35: 0.49097222 | U35: 0.56319444 | V35: 5 | W35: =(U35-T35)*24*60 -> 104 | AF35: =N35-K35 -> -265.38462 | AG35: =N35/K35 -> 0.82307692
B36: 0 | F36: 0 | H36: =F36*G36 -> 0 | W36: =(U36-T36)*24*60 -> 0 | AF36: =N36-K36 -> 0 | AG36: =N36/K36 -> #DIV/0!
B37: 0 | F37: 0 | H37: =F37*G37 -> 0 | W37: =(U37-T37)*24*60 -> 0 | AF37: =N37-K37 -> 0 | AG37: =N37/K37 -> #DIV/0!
B38: 0 | F38: 0 | H38: =F38*G38 -> 0 | W38: =(U38-T38)*24*60 -> 0 | AF38: =N38-K38 -> 0 | AG38: =N38/K38 -> #DIV/0!
B39: 0 | F39: 0 | H39: =F39*G39 -> 0 | W39: =(U39-T39)*24*60 -> 0 | AF39: =N39-K39 -> 0 | AG39: =N39/K39 -> #DIV/0!
B40: 0 | F40: 0 | H40: =F40*G40 -> 0 | W40: =(U40-T40)*24*60 -> 0 | AF40: =N40-K40 -> 0 | AG40: =N40/K40 -> #DIV/0!
...

Sheet 0401
B1: 晉欣廠組合室生產人時性分析
B3: 日期 | D3: 04月01日 星期 三 | F3: 訂單量 | H3: 240100 | J3: 營業額 | L3: 7614477.1
B4: 項目 | D4: 項目 | F4: ➀ | H4: ➁ | J4: ➂ | L4: ➃ | N4: 異常停線 | P4: 短暫停線
B5: 人時性 | D5: 組合室 | F5: 全溫層 | H5: 4度C(含4度飯糰) | J5: 18度C 一配 | L5: 18度C 二配 | N5: 合計次數 | O5: 時間 | P5: 合計次數 | Q5: 設備次數
D6: 排關平均 | F6: =AVERAGE(D13:O13,P13:Q13,D30:E30,G30:H30,J30:M30) -> 384.43154 | H6: =AVERAGE(D13:P13,Q13) -> 141.96386 | J6: =AVERAGE(D30:E30,G30:H30) -> 736.25 | L6: =AVERAGE(J30:M30) -> 881.25 | N6: 0 | O6: 0 | P6: 3 | Q6: 4
D7: 實績平均 | F7: =AVERAGE(D14:O14,P14:Q14,D31:E31,J31:M31,G31:H31) -> 363.4615 | H7: =AVERAGE(D14:P14,Q14) -> 129.04502 | J7: =AVERAGE(D31:E31,G31:H31) -> 751.41981 | L7: =AVERAGE(J31:M31) -> 795.96085
D8: 達成率平均 | F8: =AVERAGE(D15:O15,P15:Q15,D32:E32,G32:H32,J32:K32,L32) -> 0.91750855 | H8: =AVERAGE(D15:O15,P15:Q15) -> 0.90433582 | J8: =AVERAGE(D32:E32,G32:H32) -> 0.99723807 | L8: =AVERAGE(J32:M32) -> 0.90239337
B10: 溫層 | D10: ➁4度C-各編組展開
B11: 編組 | D11: 1 | E11: 2 | F11: 3 | G11: 4 | H11: 5 | I11: 6 | J11: 7 | K11: 8 | L11: 9 | M11: 10 | N11: 11 | O11: 12 | P11: 13 | Q11: 14
D12: 4度一組 | E12: 4度二組A | F12: 4度二組B | G12: 4度二組C1 | H12: 4度二組C2 | I12: 4度三組 | J12: 4度四組 | K12: 4度五組 | L12: 綜合一組 | M12: 綜合二組 | N12: 綜合三組 | O12: 綜合四組 | P12: 便當組 | Q12: 壽司線
B13: 人時性 | C13: 排關 | D13: 133.76218 | E13: 119.1543 | F13: 159.31333 | G13: 369.04762 | H13: 228.57143 | I13: 90.547526 | J13: 76.020468 | K13: 117.8634 | L13: 116.16878 | M13: 84.016229 | N13: 84.321731 | O13: 79.853801 | P13: 178.85319 | Q13: 150
C14: 實績 | D14: 123.34542 | E14: 104.32713 | F14: 134.81201 | G14: 330.12525 | H14: 225.18679 | I14: 81.147574 | J14: 69.242305 | K14: 109.19166 | L14: 102.89307 | M14: 74.91065 | N14: 77.768797 | O14: 67.131015 | P14: 167.67167 | Q14: 138.87697
C15: 達成率 | D15: =D14/D13 -> 0.92212472 | E15: =E14/E13 -> 0.87556331 | F15: =F14/F13 -> 0.84620673 | G15: =G14/G13 -> 0.89453294 | H15: =H14/H13 -> 0.98519222 | I15: =I14/I13 -> 0.89618765 | J15: =J14/J13 -> 0.91083766 | K15: =K14/K13 -> 0.92642549 | ... Q15: =Q14/Q13 -> 0.92584646
B16: 作業 時間 | C16: 開始 | D16: 0.29166667 | E16: 0.16666667 | F16: 0.16666667 | G16: 0.16666667 | H16: 0.16666667 | I16: 0.29166667 | J16: 0.33333333 | K16: 0.33333333 | L16: 0.5 | M16: 0.5 | N16: 0.5 | O16: 0.70833333 | P16: 0.16666667 | Q16: 0.17361111
C17: 結束 | D17: 0.6875 | E17: 0.60138889 | F17: 0.57569444 | G17: 0.76041667 | H17: 0.75416667 | I17: 0.67777778 | J17: 0.72569444 | K17: 0.65069444 | L17: 0.92777778 | M17: 0.91458333 | N17: 0.95902778 | O17: 0.91319444 | P17: 0.57083333 | Q17: 0.55555556
B18: 產線異常 (5分鐘以上) | C18: 次數
C19: 時間/分
B20: 短暫停線 (5分鐘以下) | C20: 次數 | D20: 1 | L20: 1 | P20: 1
C21: 設備次數 | E21: 2 | J21: 1 | N21: 1
B22: 配置人數 | D22: 19.666667 | E22: 17.571429 | F22: 14 | G22: 5.6666667 | H22: 6.6 | I22: 16.4 | J22: 18.8 | K22: 15.8 | L22: 15.444444 | M22: 18.625 | N22: 17.75 | O22: 18.833333 | P22: 13 | Q22: 11.4
B23: 主要應用設備 | D23: ET-600 | E23: ET-600 | F23: ET-600 | G23: 八爪機 | H23: 十爪機 | I23: ET-55 | J23: ET-55 | K23: ET-55 | L23: ET-55 | M23: ET-55 | N23: ET-55 | O23: ET-55 | P23: 伺服包裝機 | Q23: 伺服包裝機
B24: 次要應用設備
B25: 備註 | E25: 熱麵固定線 | G25: 烤飯糰 | H25: 烤飯糰 | K25: 吸收產線 | P25: 大口固定線
D27: ➂18度C 一配-各編組展開 | I27: ➃18度C 二配-各編組展開
B28: 編組 | D28: 1 | E28: 2 | F28: 3 | G28: 4 | H28: 5 | I28: 1 | J28: 2 | K28: 3 | L28: 4 | M28: 5
D29: 連續式 海苔機 | E29: 3300型 飯糰機A | F29: 3300型 飯糰機B | G29: 3600型 飯糰機A | H29: 3600型 飯糰機B | I29: 夾心型 飯糰機 | J29: 3300型 飯糰機A | K29: 3300型 飯糰機B | L29: 3600型 飯糰機A | M29: 3600型 飯糰機B
B30: 人時性 | C30: 排關 | D30: 320 | E30: 825 | F30: 825 | G30: 900 | H30: 900 | I30: 680 | J30: 825 | K30: 900 | L30: 900 | M30: 900
C31: 實績 | D31: 282.84722 | E31: 788.88933 | F31: 0 | G31: 946.46795 | H31: 987.47474 | I31: 0 | J31: 712.5 | K31: 612.21825 | L31: 966.73229 | M31: 892.39286
C32: 達成率 | D32: =D31/D30 -> 0.88389757 | E32: =E31/E30 -> 0.95622949 | F32: =F31/F30 -> 0 | G32: =G31/G30 -> 1.0516311 | H32: =H31/H30 -> 1.0971942 | I32: =I31/I30 -> 0 | J32: =J31/J30 -> 0.86363636 | K32: =K31/K30 -> 0.6802425 | ... M32: =M31/M30 -> 0.99154762
B33: 作業 時間 | C33: 開始 | D33: 0.1875 | E33: 0.18055556 | F33: 0 | G33: 3265.1613 | H33: 0.18055556 | I33: 0 | J33: 0.72222222 | K33: 0.72222222 | L33: 0.72222222 | M33: 0.72222222
C34: 結束 | D34: 0.23125 | E34: 0.32083333 | F34: 0 | G34: 1108 | H34: 0.41319444 | I34: 0 | J34: 0.72916667 | K34: 0.81944444 | L34: 1.0347222 | M34: 46114.017
B35: 配置人數 | D35: 5.5 | E35: 3.6666667 | F35: 0 | G35: 3.6 | H35: 3.4 | I35: 0 | J35: 4 | K35: 3.6666667 | L35: 3.4 | M35: 3.5
B36: 主要應用設備 | D36: 連續式 海苔機 | E36: 3300型 | F36: 3300型 | G36: 3600型 | H36: 3600型 | I36: 夾心型 | J36: 3300型 | K36: 3300型 | L36: 3600型 | M36: 3600型
B37: 次要應用設備
B38: 備註

Sheet 晉欣18度C0401
A1: 晉欣廠18度C日報分析 | D1: 總生產量 | E1: =SUM(G5:G124) -> 76254 | F1: 營業額 | G1: =SUM(H5:H124) -> 1414195.5 | H1: 出勤人數 | I1: =+J16+J64+J24+J38+J51+J81+J100+J91+J57+J124+J111 -> 38.733333 | J1: 生產實績 | M1: 日報登錄
A2: 04月01日 星期三 | D2: 人時性 | E2: =AVERAGE(L16,L24,L38,L51,L100,L111,L91) -> 583.67734 | F2: 平均廠價 | G2: =G1/E1 -> 18.545853 | H2: 多次生產數 | I2: =COUNT(I5:I124) -> 0
A3: 線別 | B3: 品類 | D3: 品名 | F3: 廠價 | G3: 生產量 | H3: 營收 | I3: 多次 生產 | J3: 人數 | K3: 產能/時 | L3: 人時性 | M3: 生產時間 | O3: 換線/分 | P3: 稼動時間/分 | Q3: 休息時間
M4: 開始 | N4: 結束 | Q4: 開始 | R4: 結束
A5: 壽司線 | B5: 0 | D5: 雙饗雙手卷(捲) | F5: 0 | G5: 1209 | H5: =F5*G5 -> 0 | J5: 9 | K5: =G5/P5*60 -> 1612 | L5: =K5/J5 -> 179.11111 | M5: 0.17361111 | N5: 0.20486111 | O5: 10 | P5: =(N5-M5)*24*60 -> 45
B6: 0 | D6: 海饌雙手卷(捲) | F6: 0 | G6: 1273 | H6: =F6*G6 -> 0 | J6: 9 | K6: =G6/P6*60 -> 1697.3333 | L6: =K6/J6 -> 188.59259 | M6: 0.20833333 | N6: 0.23958333 | O6: 5 | P6: =(N6-M6)*24*60 -> 45
B7: 壽司手卷 | D7: 雙倍德腸飯卷 | F7: 36.45 | G7: 1456 | H7: =F7*G7 -> 53071.2 | J7: 13 | K7: =G7/P7*60 -> 1456 | L7: =K7/J7 -> 112 | M7: 0.24305556 | N7: 0.28472222 | O7: 5 | P7: =(N7-M7)*24*60 -> 60
B8: 壽司手卷 | D8: 明太子泡菜牛飯卷 | F8: 27.05 | G8: 379 | H8: =F8*G8 -> 10251.95 | J8: 13 | K8: =G8/P8*60 -> 1516 | L8: =K8/J8 -> 116.61538 | M8: 0.28819444 | N8: 0.29861111 | O8: 5 | P8: =(N8-M8)*24*60 -> 15 | Q8: 0.30555556 | R8: 0.33680556
B9: 壽司手卷 | D9: 銀鮭美乃滋脆卷 | F9: 19.7 | G9: 1678 | H9: =F9*G9 -> 33056.6 | J9: 13 | K9: =G9/P9*60 -> 1184.4706 | L9: =K9/J9 -> 91.113122 | M9: 0.34027778 | N9: 0.39930556 | O9: 5 | P9: =(N9-M9)*24*60 -> 85
B10: 壽司手卷 | D10: 日式鮪魚美乃滋脆卷 | F10: 17.87 | G10: 732 | H10: =F10*G10 -> 13080.84 | J10: 13 | K10: =G10/P10*60 -> 1254.8571 | L10: =K10/J10 -> 96.527473 | M10: 0.40277778 | N10: 0.42708333 | O10: 5 | P10: =(N10-M10)*24*60 -> 35
B11: 壽司手卷 | D11: 長野稻荷壽司 | F11: 25.64 | G11: 609 | H11: =F11*G11 -> 15614.76 | J11: 10 | K11: =G11/P11*60 -> 1461.6 | L11: =K11/J11 -> 146.16 | M11: 0.43055556 | N11: 0.44791667 | O11: 5 | P11: =(N11-M11)*24*60 -> 25
B12: 壽司手卷 | D12: 雙饗雙手卷 | F12: 29.52 | G12: 1209 | H12: =F12*G12 -> 35689.68 | J12: 12 | K12: =G12/P12*60 -> 1813.5 | L12: =K12/J12 -> 151.125 | M12: 0.45138889 | N12: 0.47916667 | O12: 5 | P12: =(N12-M12)*24*60 -> 40
B13: 壽司手卷 | D13: 海饌雙手卷 | F13: 29.857 | G13: 1273 | H13: =F13*G13 -> 38007.961 | J13: 12 | K13: =G13/P13*60 -> 1909.5 | L13: =K13/J13 -> 159.125 | M13: 0.48263889 | N13: 0.51041667 | O13: 5 | P13: =(N13-M13)*24*60 -> 40
B14: 飯糰 | D14: 兩粒飯糰(鮪魚.焦糖鮭魚) | F14: 28.57 | G14: 1484 | H14: =F14*G14 -> 42397.88 | J14: 10 | K14: =G14/P14*60 -> 1484 | L14: =K14/J14 -> 148.4 | M14: 0.51388889 | N14: 0.55555556 | O14: 5 | P14: =(N14-M14)*24*60 -> 60
B15: 0 | F15: 0 | H15: =F15*G15 -> 0
B16: 0 | C16: 壽司線 | D16: 平均 | J16: =AVERAGE(J5:J15) -> 11.4 | K16: =AVERAGE(K5:K15) -> 1538.9261 | L16: =AVERAGE(L5:L15) -> 138.87697
A17: 捲壽司機 | B17: 壽司手卷 | D17: 雙鬆細卷 | F17: 14.03 | G17: 418 | H17: =F17*G17 -> 5864.54 | J17: 6 | K17: =G17/P17*60 -> 1567.5 | L17: =K17/J17 -> 261.25 | M17: 0.1875 | N17: 0.19861111 | O17: 30 | P17: =(N17-M17)*24*60 -> 16
B18: 飯糰 | D18: 經典鮪魚沙拉細卷 | F18: 14.49 | G18: 685 | H18: =F18*G18 -> 9925.65 | J18: 5 | K18: =G18/P18*60 -> 1522.2222 | L18: =K18/J18 -> 304.44444 | M18: 0.2125 | N18: 0.23125 | O18: 20 | P18: =(N18-M18)*24*60 -> 27
B19: 0 | F19: 0 | H19: =F19*G19 -> 0
B20: 0 | F20: 0 | H20: =F20*G20 -> 0
B21: 0 | F21: 0 | H21: =F21*G21 -> 0
B22: 0 | F22: 0 | H22: =F22*G22 -> 0
B23: 0 | F23: 0 | H23: =F23*G23 -> 0
B24: 0 | C24: 連續式 海苔機 | D24: 平均 | J24: =AVERAGE(J17:J23) -> 5.5 | K24: =AVERAGE(K17:K23) -> 1544.8611 | L24: =AVERAGE(L17:L23) -> 282.84722
A25: 3300型 飯糰機A | B25: 飯糰 | D25: 煙燻培根飯糰(區) | F25: 15.03 | G25: 2380 | H25: =F25*G25 -> 35771.4 | J25: 4 | K25: =G25/P25*60 -> 2856 | L25: =K25/J25 -> 714 | M25: 0.18055556 | N25: 0.21527778 | O25: 20 | P25: =(N25-M25)*24*60 -> 50
B26: 飯糰 | D26: 碳烤燒肉飯飯糰(區) | F26: 18.18 | G26: 3086 | H26: =F26*G26 -> 56103.48 | J26: 4 | K26: =G26/P26*60 -> 2805.4545 | L26: =K26/J26 -> 701.36364 | M26: 0.22916667 | N26: 0.275 | O26: 20 | P26: =(N26-M26)*24*60 -> 66
B27: 飯糰 | D27: 鮭魚奶油醬油飯糰 | F27: 18.53 | G27: 2188 | H27: =F27*G27 -> 40543.64 | J27: 3 | K27: =G27/P27*60 -> 2853.913 | L27: =K27/J27 -> 951.30435 | M27: 0.28888889 | N27: 0.32083333 | O27: 20 | P27: =(N27-M27)*24*60 -> 46
B28: 0
B29: 0
B30: 0
B31: 0
B32: 0 | F32: 0 | H32: =F32*G32 -> 0
B33: 0 | F33: 0 | H33: =F33*G33 -> 0
B34: 0 | F34: 0 | H34: =F34*G34 -> 0
B35: 0 | F35: 0 | H35: =F35*G35 -> 0
B36: 0 | F36: 0 | H36: =F36*G36 -> 0
B37: 0 | F37: 0 | H37: =F37*G37 -> 0
B38: 0 | C38: 3300型 飯糰機A | D38: 平均 | J38: =AVERAGE(J25:J37) -> 3.6666667 | K38: =AVERAGE(K25:K37) -> 2838.4559 | L38: =AVERAGE(L25:L37) -> 788.88933
A39: 3300型B 飯糰機 | B39: 0 | F39: 0 | H39: =F39*G39 -> 0
B40: 0 | F40: 0 | H40: =F40*G40 -> 0
...

Sheet 晉欣4度C0401
A1: 晉欣廠四度C日報分析 | D1: 總生產量 | E1: =SUM(G5:G173) -> 163846 | F1: 營業額 | G1: =SUM(H5:H173) -> 6200281.6 | H1: 出勤人數 | I1: =M17+M30+M43+M56+M69+M82+M95+M108+M121+M134+M147+M160+M173 -> 198.15754 | J1: 產線配置圖 | M1: 生產實績 | P1: 人時性差異分析 | T1: 日報登錄 | Z1: 合計 次數 | AA1: 合計 時間/分 | AB1: 產線異常分析 說明(5分鐘以上) | AD1: 合計 次數 | AE1: 合計 設備次數 | AF1: 產能差異分析
A2: 04月01日 星期 三 | D2: 人時性 | E2: =AVERAGE(O17,O30,O43,O56,O69,O82,O95,O108,O121,O134,O147,O160,O173) -> 128.28872 | F2: 平均廠價 | G2: =G1/E1 -> 37.84213 | H2: 多次生產數 | I2: =COUNT(I5:I173) -> 6 | Z2: =Z17+Z30+Z43+Z56+Z69+Z82+Z95+Z108+Z121+Z134+Z147+Z160+Z173 -> 0 | AA2: =AA17+AA30+AA43+AA56+AA69+AA82+AA95+AA108+AA121+AA134+AA147+AA160+AA173 -> 0 | AD2: =AD17+AD30+AD43+AD56+AD69+AD82+AD95+AD108+AD121+AD134+AD147+AD160+AD173 -> 3 | AE2: =AE17+AE30+AE43+AE56+AE69+AE82+AE95+AE108+AE121+AE134+AE147+AE160+AE173 -> 4
A3: 線別 | B3: 品類 | D3: 品名 | F3: 廠價 | G3: 生產量 | H3: 營收 | I3: 多次 生產 | J3: 人數 | K3: 產能/時 | L3: 人時性 | M3: 人數 | N3: 產能/時 | O3: 人時性 | P3: 人數 | Q3: 人時性 | R3: 達成率 | S3: 達成率平均 | T3: 生產時間 | V3: 前置、換線時間/分 | W3: 稼動時間/分 | X3: 休息時間 | Z3: 產線異常統計 (5分鐘以上) | AB3: 分析說明 | AD3: 短暫停線統計 (5分鐘以下) | AF3: 產能/時 | AG3: 達成率 | AH3: 達成率平均
T4: 開始 | U4: 結束 | X4: 開始 | Y4: 結束 | Z4: 次數 | AA4: 時間/分 | AD4: 總次數 | AE4: 設備因素(次數)
A5: 四度一組 (ET-600) | B5: 季節調理麵 | D5: 椒麻香蔥雞涼拌麵 | F5: 37.94 | G5: 3939 | H5: =F5*G5 -> 149445.66 | J5: 20 | K5: 2400 | L5: 120 | M5: 20 | N5: =G5/W5*60 -> 2250.8571 | O5: =N5/M5 -> 112.54286 | P5: =M5-J5 -> 0 | Q5: =O5-L5 -> -7.4571429 | R5: =O5/L5 -> 0.93785714 | S5: =R17 -> 0.92212472 | T5: 0.29166667 | U5: 0.36458333 | V5: 5 | W5: =(U5-T5)*24*60 -> 105 | AF5: =N5-K5 -> -149.14286 | AG5: =N5/K5 -> 0.93785714 | AH5: =AG17 -> 0.95643507
B6: 季節調理麵 | D6: 台式麻醬涼麵 | F6: 31.266132 | G6: 2531.1 | H6: =F6*G6 -> 79137.706 | J6: 18 | K6: 2600 | L6: 144.44444 | M6: 19 | N6: =G6/W6*60 -> 2531.1 | O6: =N6/M6 -> 133.21579 | P6: =M6-J6 -> 1 | Q6: =O6-L6 -> -11.228655 | R6: =O6/L6 -> 0.92226316 | T6: 0.36944444 | U6: 0.41111111 | V6: 7 | W6: =(U6-T6)*24*60 -> 60 | AF6: =N6-K6 -> -68.9 | AG6: =N6/K6 -> 0.9735
B7: 季節調理麵 | D7: 大滿足麻醬涼麵 | F7: 38 | G7: 4687.76 | H7: =F7*G7 -> 178134.88 | J7: 19 | K7: 2600 | L7: 136.84211 | M7: 20 | N7: =G7/W7*60 -> 2533.9243 | O7: =N7/M7 -> 126.69622 | P7: =M7-J7 -> 1 | Q7: =O7-L7 -> -10.145889 | R7: =O7/L7 -> 0.92585696 | T7: 0.42708333 | U7: 0.50416667 | V7: 23 | W7: =(U7-T7)*24*60 -> 111 | X7: 0.41458333 | Y7: 0.42430556 | AD7: 1 | AF7: =N7-K7 -> -66.075676 | AG7: =N7/K7 -> 0.97458628
B8: 季節調理麵 | D8: 大滿足麻醬涼麵 | F8: 38 | G8: 3683.24 | H8: =F8*G8 -> 139963.12 | J8: 19 | K8: 2600 | L8: 136.84211 | M8: 20 | N8: =G8/W8*60 -> 2511.3 | O8: =N8/M8 -> 125.565 | P8: =M8-J8 -> 1 | Q8: =O8-L8 -> -11.277105 | R8: =O8/L8 -> 0.91759038 | T8: 0.54375 | U8: 0.60486111 | V8: 5 | W8: =(U8-T8)*24*60 -> 88 | AF8: =N8-K8 -> -88.7 | AG8: =N8/K8 -> 0.96588462
B9: 季節調理麵 | D9: 台式麻醬涼麵 | F9: 31.266132 | G9: 1362.9 | H9: =F9*G9 -> 42612.611 | J9: 18 | K9: 2600 | L9: 144.44444 | M9: 19 | N9: =G9/W9*60 -> 2478 | O9: =N9/M9 -> 130.42105 | P9: =M9-J9 -> 1 | Q9: =O9-L9 -> -14.023392 | R9: =O9/L9 -> 0.90291498 | T9: 0.62013889 | U9: 0.64305556 | V9: 22 | W9: =(U9-T9)*24*60 -> 33 | X9: 0.60833333 | Y9: 0.61736111 | AF9: =N9-K9 -> -122 | AG9: =N9/K9 -> 0.95307692
B10: 季節調理麵 | D10: 椒麻香蔥雞涼拌麵 | F10: 37.94 | G10: 2121 | H10: =F10*G10 -> 80470.74 | J10: 20 | K10: 2400 | L10: 120 | M10: 20 | N10: =G10/W10*60 -> 2232.6316 | O10: =N10/M10 -> 111.63158 | P10: =M10-J10 -> 0 | Q10: =O10-L10 -> -8.3684211 | R10: =O10/L10 -> 0.93026316 | T10: 0.64791667 | U10: 0.6875 | V10: 7 | W10: =(U10-T10)*24*60 -> 57 | AF10: =N10-K10 -> -167.36842 | AG10: =N10/K10 -> 0.93026316
B11: 0 | F11: 0 | H11: =F11*G11 -> 0 | AF11: =N11-K11 -> 0 | AG11: =N11/K11 -> #DIV/0!
B12: 0 | F12: 0 | H12: =F12*G12 -> 0 | AF12: =N12-K12 -> 0 | AG12: =N12/K12 -> #DIV/0!
B13: 0 | F13: 0 | H13: =F13*G13 -> 0 | AF13: =N13-K13 -> 0 | AG13: =N13/K13 -> #DIV/0!
B14: 0 | F14: 0 | H14: =F14*G14 -> 0 | W14: =(U14-T14)*24*60 -> 0
B15: 0 | F15: 0 | H15: =F15*G15 -> 0 | W15: =(U15-T15)*24*60 -> 0
B16: 0 | F16: 0 | H16: =F16*G16 -> 0 | W16: =(U16-T16)*24*60 -> 0
B17: 0 | C17: 4度一組 | D17: 平均 | J17: 19 | K17: 2533.3333 | L17: 133.76218 | M17: =AVERAGE(M5:M16) -> 19.666667 | N17: =AVERAGE(N5:N16) -> 2422.9688 | O17: =AVERAGE(O5:O16) -> 123.34542 | P17: =M17-J17 -> 0.66666667 | Q17: =O17-L17 -> -10.416768 | R17: =O17/L17 -> 0.92212472 | W17: =(U17-T17)*24*60 -> 0 | Z17: =SUM(Z5:Z16) -> 0 | AA17: =SUM(AA5:AA16) -> 0 | AD17: =SUM(AD5:AD16) -> 1 | AE17: =SUM(AE5:AE16) -> 0 | AF17: =N17-K17 -> -110.36449 | AG17: =N17/K17 -> 0.95643507
A18: 四度二組A 熱麵 固定線 (ET-55) | B18: 季節調理麵 | D18: 日式蕎麥沾麵 | F18: 36.86 | G18: 2853.9 | H18: =F18*G18 -> 105194.75 | J18: 17 | K18: 2250 | L18: 132.35294 | M18: 18 | N18: =G18/W18*60 -> 2167.519 | O18: =N18/M18 -> 120.41772 | P18: =M18-J18 -> 1 | Q18: =O18-L18 -> -11.93522 | R18: =O18/L18 -> 0.90982278 | S18: =R30 -> 0.87556331 | T18: 0.16666667 | U18: 0.22152778 | V18: 5 | W18: =(U18-T18)*24*60 -> 79 | AF18: =N18-K18 -> -82.481013 | AG18: =N18/K18 -> 0.96334177 | AH18: =AG30 -> 0.90844142
B19: 季節調理麵 | D19: 大滿足香辣涼麵 | F19: 38.630952 | G19: 1179 | H19: =F19*G19 -> 45545.893 | J19: 18 | K19: 2600 | L19: 144.44444 | M19: 19 | N19: =G19/W19*60 -> 2358 | O19: =N19/M19 -> 124.10526 | P19: =M19-J19 -> 1 | Q19: =O19-L19 -> -20.339181 | R19: =O19/L19 -> 0.85919028 | T19: 0.22708333 | U19: 0.24791667 | V19: 8 | W19: =(U19-T19)*24*60 -> 30 | AF19: =N19-K19 -> -242 | AG19: =N19/K19 -> 0.90692308
B20: 熱食義麵 | D20: 愛恨椒芝麵 | F20: 38.39 | G20: 2395 | H20: =F20*G20 -> 91944.05 | J20: 16 | K20: 1636 | L20: 102.25 | M20: 17 | N20: =G20/W20*60 -> 1437 | O20: =N20/M20 -> 84.529412 | P20: =M20-J20 -> 1 | Q20: =O20-L20 -> -17.720588 | R20: =O20/L20 -> 0.82669351 | T20: 0.26388889 | U20: 0.33333333 | V20: 23 | W20: =(U20-T20)*24*60 -> 100 | X20: 0.25138889 | Y20: 0.26111111 | AE20: 1 | AF20: =N20-K20 -> -199 | AG20: =N20/K20 -> 0.87836186
B21: 小菜微波 | D21: 古早味炒炊粉 | F21: 43.14 | G21: 1852 | H21: =F21*G21 -> 79895.28 | J21: 16 | K21: 1440 | L21: 90 | M21: 16 | N21: =G21/W21*60 -> 1406.5823 | O21: =N21/M21 -> 87.911392 | P21: =M21-J21 -> 0 | Q21: =O21-L21 -> -2.0886076 | R21: =O21/L21 -> 0.97679325 | T21: 0.33819444 | U21: 0.39305556 | V21: 7 | W21: =(U21-T21)*24*60 -> 79 | AF21: =N21-K21 -> -33.417722 | AG21: =N21/K21 -> 0.97679325
B22: 熱食義麵 | D22: 辣腐乳麻醬拌麵 | F22: 38.1 | G22: 1470 | H22: =F22*G22 -> 56007 | J22: 17 | K22: 1500 | L22: 88.235294 | M22: 16 | N22: =G22/W22*60 -> 1297.0588 | O22: =N22/M22 -> 81.066176 | P22: =M22-J22 -> -1 | Q22: =O22-L22 -> -7.1691176 | R22: =O22/L22 -> 0.91875 | T22: 0.39861111 | U22: 0.44583333 | V22: 8 | W22: =(U22-T22)*24*60 -> 68 | AE22: 1 | AF22: =N22-K22 -> -202.94118 | AG22: =N22/K22 -> 0.86470588
B23: 季節調理麵 | D23: 大滿足香辣涼麵 | F23: 38.630952 | G23: 4716 | H23: =F23*G23 -> 182183.57 | J23: 18 | K23: 2600 | L23: 144.44444 | M23: 19 | N23: =G23/W23*60 -> 2319.3443 | O23: =N23/M23 -> 122.07075 | P23: =M23-J23 -> 1 | Q23: =O23-L23 -> -22.373694 | R23: =O23/L23 -> 0.8451052 | T23: 0.48611111 | U23: 0.57083333 | V23: 5 | W23: =(U23-T23)*24*60 -> 122 | AF23: =N23-K23 -> -280.65574 | AG23: =N23/K23 -> 0.89205549
B24: 季節調理麵 | D24: 日式蕎麥沾麵 | F24: 36.86 | G24: 1223.1 | H24: =F24*G24 -> 45083.466 | J24: 17 | K24: 2250 | L24: 132.35294 | M24: 18 | N24: =G24/W24*60 -> 1983.4054 | O24: =N24/M24 -> 110.18919 | P24: =M24-J24 -> 1 | Q24: =O24-L24 -> -22.163752 | R24: =O24/L24 -> 0.83254054 | T24: 0.57569444 | U24: 0.60138889 | V24: 7 | W24: =(U24-T24)*24*60 -> 37 | AF24: =N24-K24 -> -266.59459 | AG24: =N24/K24 -> 0.88151351
B25: 0 | F25: 0 | H25: =F25*G25 -> 0 | W25: =(U25-T25)*24*60 -> 0 | AF25: =N25-K25 -> 0 | AG25: =N25/K25 -> #DIV/0!
B26: 0 | F26: 0 | H26: =F26*G26 -> 0 | W26: =(U26-T26)*24*60 -> 0 | AF26: =N26-K26 -> 0 | AG26: =N26/K26 -> #DIV/0!
B27: 0 | F27: 0 | H27: =F27*G27 -> 0 | W27: =(U27-T27)*24*60 -> 0 | AF27: =N27-K27 -> 0 | AG27: =N27/K27 -> #DIV/0!
B28: 0 | F28: 0 | H28: =F28*G28 -> 0 | W28: =(U28-T28)*24*60 -> 0 | AF28: =N28-K28 -> 0 | AG28: =N28/K28 -> #DIV/0!
B29: 0 | F29: 0 | H29: =F29*G29 -> 0 | W29: =(U29-T29)*24*60 -> 0 | AF29: =N29-K29 -> 0
B30: 0 | C30: 4度二組A | D30: 平均 | J30: 17 | K30: 2039.4286 | L30: 119.1543 | M30: =AVERAGE(M18:M29) -> 17.571429 | N30: =AVERAGE(N18:N29) -> 1852.7014 | O30: =AVERAGE(O18:O29) -> 104.32713 | P30: =M30-J30 -> 0.57142857 | Q30: =O30-L30 -> -14.827166 | R30: =O30/L30 -> 0.87556331 | Z30: =SUM(Z18:Z29) -> 0 | AA30: =SUM(AA18:AA29) -> 0 | AD30: =SUM(AD18:AD29) -> 0 | AE30: =SUM(AE18:AE29) -> 2 | AF30: =N30-K30 -> -186.72718 | AG30: =N30/K30 -> 0.90844142
A31: 四度二組 (ET-55) | B31: 飯糰 | D31: 大口日式塔塔醬蝦排飯糰 | F31: 35.33 | G31: 1982 | H31: =F31*G31 -> 70024.06 | J31: 12 | K31: 2118 | L31: 176.5 | M31: 12 | N31: =G31/W31*60 -> 1887.619 | O31: =N31/M31 -> 157.30159 | P31: =M31-J31 -> 0 | Q31: =O31-L31 -> -19.198413 | R31: =O31/L31 -> 0.89122712 | S31: =R43 -> 0.84620673 | T31: 0.16666667 | U31: 0.21041667 | V31: 5 | W31: =(U31-T31)*24*60 -> 63 | AF31: =N31-K31 -> -230.38095 | AG31: =N31/K31 -> 0.89122712 | AH31: =AG43 -> 0.84913746
B32: 飯糰 | D32: 大口起司熔岩白醬炸魚飯糰 | F32: 34.23 | G32: 2094 | H32: =F32*G32 -> 71677.62 | J32: 12 | K32: 2118 | L32: 176.5 | M32: 12 | N32: =G32/W32*60 -> 1903.6364 | O32: =N32/M32 -> 158.63636 | P32: =M32-J32 -> 0 | Q32: =O32-L32 -> -17.863636 | R32: =O32/L32 -> 0.8987896 | T32: 0.21527778 | U32: 0.26111111 | V32: 7 | W32: =(U32-T32)*24*60 -> 66 | AF32: =N32-K32 -> -214.36364 | AG32: =N32/K32 -> 0.8987896
B33: 飯糰 | D33: 大口義式香草雞腿排飯糰 | F33: 36.41 | G33: 2612.75 | H33: =F33*G33 -> 95130.227 | J33: 10 | K33: 2769 | L33: 276.9 | M33: 10 | N33: =G33/W33*60 -> 2177.2917 | O33: =N33/M33 -> 217.72917 | P33: =M33-J33 -> 0 | Q33: =O33-L33 -> -59.170833 | R33: =O33/L33 -> 0.78630974 | T33: 0.27638889 | U33: 0.32638889 | V33: 22 | W33: =(U33-T33)*24*60 -> 72 | X33: 0.26458333 | Y33: 0.27361111 | AF33: =N33-K33 -> -591.70833 | AG33: =N33/K33 -> 0.78630974
B34: 微波主食 | D34: 壹號醬壽喜燒牛丼 | F34: 54.09 | G34: 4071 | H34: =F34*G34 -> 220200.39 | J34: 18 | K34: 1500 | L34: 83.333333 | M34: 18 | N34: =G34/W34*60 -> 1252.6154 | O34: =N34/M34 -> 69.589744 | P34: =M34-J34 -> 0 | Q34: =O34-L34 -> -13.74359 | R34: =O34/L34 -> 0.83507692 | T34: 0.34236111 | U34: 0.47777778 | V34: 23 | W34: =(U34-T34)*24*60 -> 195 | X34: 0.32986111 | Y34: 0.33958333 | AF34: =N34-K34 -> -247.38462 | AG34: =N34/K34 -> 0.83507692
B35: 微波主食 | D35: 韓式泡菜豬肉豆腐丼飯 | F35: 50.67 | G35: 1763 | H35: =F35*G35 -> 89331.21 | J35: 18 | K35: 1500 | L35: 83.333333 | M35: 18 | N35: =G35/W35*60 -> 1274.4578 | O35: =N35/M35 -> 70.803213 | P35: =M35-J35 -> 0 | Q35: =O35-L35 -> -12.53012 | R35: =O35/L35 -> 0.84963855 | T35: 0.51805556 | U35: 0.57569444 | V35: 5 | W35: =(U35-T35)*24*60 -> 83 | AF35: =N35-K35 -> -225.54217 | AG35: =N35/K35 -> 0.84963855
B36: 0 | F36: 0 | H36: =F36*G36 -> 0 | W36: =(U36-T36)*24*60 -> 0 | AF36: =N36-K36 -> 0 | AG36: =N36/K36 -> #DIV/0!
B37: 0 | F37: 0 | H37: =F37*G37 -> 0 | W37: =(U37-T37)*24*60 -> 0 | AF37: =N37-K37 -> 0 | AG37: =N37/K37 -> #DIV/0!
B38: 0 | F38: 0 | H38: =F38*G38 -> 0 | W38: =(U38-T38)*24*60 -> 0 | AF38: =N38-K38 -> 0 | AG38: =N38/K38 -> #DIV/0!
B39: 0 | F39: 0 | H39: =F39*G39 -> 0 | W39: =(U39-T39)*24*60 -> 0 | AF39: =N39-K39 -> 0 | AG39: =N39/K39 -> #DIV/0!
B40: 0 | F40: 0 | H40: =F40*G40 -> 0 | W40: =(U40-T40)*24*60 -> 0 | AF40: =N40-K40 -> 0 | AG40: =N40/K40 -> #DIV/0!
...

Sheet 0402
B1: 晉欣廠組合室生產人時性分析
B3: 日期 | D3: 04月02日 星期 四 | F3: 訂單量 | H3: 217741 | J3: 營業額 | L3: 6900619.2
B4: 項目 | D4: 項目 | F4: ➀ | H4: ➁ | J4: ➂ | L4: ➃ | N4: 異常停線 | P4: 短暫停線
B5: 人時性 | D5: 組合室 | F5: 全溫層 | H5: 4度C(含4度飯糰) | J5: 18度C 一配 | L5: 18度C 二配 | N5: 合計次數 | O5: 時間 | P5: 合計次數 | Q5: 設備次數
D6: 排關平均 | F6: =AVERAGE(D13:O13,P13:Q13,D30:E30,G30:H30,J30:M30) -> 383.4619 | H6: =AVERAGE(D13:P13,Q13) -> 140.44012 | J6: =AVERAGE(D30:E30,G30:H30) -> 736.25 | L6: =AVERAGE(J30:M30) -> 881.25 | N6: 0 | O6: 0 | P6: 2 | Q6: 3
D7: 實績平均 | F7: =AVERAGE(D14:O14,P14:Q14,D31:E31,J31:M31,G31:H31) -> 356.08261 | H7: =AVERAGE(D14:P14,Q14) -> 126.70885 | J7: =AVERAGE(D31:E31,G31:H31) -> 711.76999 | L7: =AVERAGE(J31:M31) -> 803.2034
D8: 達成率平均 | F8: =AVERAGE(D15:O15,P15:Q15,D32:E32,G32:H32,J32:K32,L32) -> 0.90541334 | H8: =AVERAGE(D15:O15,P15:Q15) -> 0.89834598 | J8: =AVERAGE(D32:E32,G32:H32) -> 0.94736299 | L8: =AVERAGE(J32:M32) -> 0.91228724
B10: 溫層 | D10: ➁4度C-各編組展開
B11: 編組 | D11: 1 | E11: 2 | F11: 3 | G11: 4 | H11: 5 | I11: 6 | J11: 7 | K11: 8 | L11: 9 | M11: 10 | N11: 11 | O11: 12 | P11: 13 | Q11: 14
D12: 4度一組 | E12: 4度二組A | F12: 4度二組B | G12: 4度二組C1 | H12: 4度二組C2 | I12: 4度三組 | J12: 4度四組 | K12: 4度五組 | L12: 綜合一組 | M12: 綜合二組 | N12: 綜合三組 | O12: 綜合四組 | P12: 便當組 | Q12: 壽司線
B13: 人時性 | C13: 排關 | D13: 133.76218 | E13: 119.1543 | F13: 159.31333 | G13: 369.04762 | H13: 228.57143 | I13: 89.34516 | J13: 75.981969 | K13: 117.8634 | L13: 96.077381 | M13: 84.016229 | N13: 84.321731 | O13: 79.853801 | P13: 178.85319 | Q13: 150
C14: 實績 | D14: 123.77064 | E14: 103.75107 | F14: 133.84792 | G14: 325.06133 | H14: 224.10438 | I14: 78.614648 | J14: 69.921342 | K14: 108.23373 | L14: 81.787357 | M14: 75.501947 | N14: 77.465813 | O14: 67.380947 | P14: 168.62233 | Q14: 135.8605
C15: 達成率 | D15: =D14/D13 -> 0.92530368 | E15: =E14/E13 -> 0.87072876 | F15: =F14/F13 -> 0.84015517 | G15: =G14/G13 -> 0.88081135 | H15: =H14/H13 -> 0.98045665 | I15: =I14/I13 -> 0.87989823 | J15: =J14/J13 -> 0.92023598 | K15: =K14/K13 -> 0.91829807 | ... Q15: =Q14/Q13 -> 0.90573666
B16: 作業 時間 | C16: 開始 | D16: 0.29166667 | E16: 0.16666667 | F16: 0.16666667 | G16: 0.16666667 | H16: 0.16666667 | I16: 0.29166667 | J16: 0.33333333 | K16: 0.33333333 | L16: 0.5 | M16: 0.5 | N16: 0.5 | O16: 0.70833333 | P16: 0.16666667 | Q16: 0.17361111
C17: 結束 | D17: 0.67847222 | E17: 0.5625 | F17: 0.50694444 | G17: 0.72777778 | H17: 0.73472222 | I17: 0.65763889 | J17: 0.68680556 | K17: 0.62847222 | L17: 0.90833333 | M17: 0.89791667 | N17: 0.94166667 | O17: 0.90069444 | P17: 0.57847222 | Q17: 0.51388889
B18: 產線異常 (5分鐘以上) | C18: 次數
C19: 時間/分
B20: 短暫停線 (5分鐘以下) | C20: 次數 | D20: 1 | F20: 1
C21: 設備次數 | E21: 1 | H21: 1 | J21: 1
B22: 配置人數 | D22: 19.666667 | E22: 17.571429 | F22: 14 | G22: 5.6666667 | H22: 6.6 | I22: 16.666667 | J22: 18.666667 | K22: 15.8 | L22: 15.875 | M22: 18.625 | N22: 17.75 | O22: 18.833333 | P22: 13 | Q22: 11.4
B23: 主要應用設備 | D23: ET-600 | E23: ET-600 | F23: ET-600 | G23: 八爪機 | H23: 十爪機 | I23: ET-55 | J23: ET-55 | K23: ET-55 | L23: ET-55 | M23: ET-55 | N23: ET-55 | O23: ET-55 | P23: 伺服包裝機 | Q23: 伺服包裝機
B24: 次要應用設備
B25: 備註 | E25: 熱麵固定線 | G25: 烤飯糰 | H25: 烤飯糰 | K25: 吸收產線 | P25: 大口固定線
D27: ➂18度C 一配-各編組展開 | I27: ➃18度C 二配-各編組展開
B28: 編組 | D28: 1 | E28: 2 | F28: 3 | G28: 4 | H28: 5 | I28: 1 | J28: 2 | K28: 3 | L28: 4 | M28: 5
D29: 連續式 海苔機 | E29: 3300型 飯糰機A | F29: 3300型 飯糰機B | G29: 3600型 飯糰機A | H29: 3600型 飯糰機B | I29: 夾心型 飯糰機 | J29: 3300型 飯糰機A | K29: 3300型 飯糰機B | L29: 3600型 飯糰機A | M29: 3600型 飯糰機B
B30: 人時性 | C30: 排關 | D30: 320 | E30: 825 | F30: 825 | G30: 900 | H30: 900 | I30: 680 | J30: 825 | K30: 900 | L30: 900 | M30: 900
C31: 實績 | D31: 272.3125 | E31: 768.46442 | F31: 0 | G31: 886.86136 | H31: 919.44167 | I31: 0 | J31: 785.625 | K31: 624 | L31: 901.60051 | M31: 901.5881
C32: 達成率 | D32: =D31/D30 -> 0.85097656 | E32: =E31/E30 -> 0.93147203 | F32: =F31/F30 -> 0 | G32: =G31/G30 -> 0.98540151 | H32: =H31/H30 -> 1.0216019 | I32: =I31/I30 -> 0 | J32: =J31/J30 -> 0.95227273 | K32: =K31/K30 -> 0.69333333 | ... M32: =M31/M30 -> 1.0017646
B33: 作業 時間 | C33: 開始 | D33: 0.18055556 | E33: 0.18055556 | F33: 0 | G33: 3063.75 | H33: 0.18055556 | I33: 0 | J33: 0.72222222 | K33: 0.72222222 | L33: 0.72222222 | M33: 0.72222222
C34: 結束 | D34: 0.22222222 | E34: 0.30555556 | F34: 0 | G34: 1062.6087 | H34: 0.40138889 | I34: 0 | J34: 0.72777778 | K34: 0.8125 | L34: 1.0659722 | M34: 46115.014
B35: 配置人數 | D35: 5.5 | E35: 3.6666667 | F35: 0 | G35: 3.6 | H35: 3.4 | I35: 0 | J35: 4 | K35: 3.6666667 | L35: 3.4 | M35: 3.5
B36: 主要應用設備 | D36: 連續式 海苔機 | E36: 3300型 | F36: 3300型 | G36: 3600型 | H36: 3600型 | I36: 夾心型 | J36: 3300型 | K36: 3300型 | L36: 3600型 | M36: 3600型
B37: 次要應用設備
B38: 備註

Sheet 晉欣18度C0402
A1: 晉欣廠18度C日報分析 | D1: 總生產量 | E1: =SUM(G5:G124) -> 67186 | F1: 營業額 | G1: =SUM(H5:H124) -> 1250717.1 | H1: 出勤人數 | I1: =+J16+J64+J24+J38+J51+J81+J100+J91+J57+J124+J111 -> 38.733333 | J1: 生產實績 | M1: 日報登錄
A2: 04月02日 星期三 | D2: 人時性 | E2: =AVERAGE(L16,L24,L38,L51,L100,L111,L91) -> 581.31049 | F2: 平均廠價 | G2: =G1/E1 -> 18.61574 | H2: 多次生產數 | I2: =COUNT(I5:I124) -> 0
A3: 線別 | B3: 品類 | D3: 品名 | F3: 廠價 | G3: 生產量 | H3: 營收 | I3: 多次 生產 | J3: 人數 | K3: 產能/時 | L3: 人時性 | M3: 生產時間 | O3: 換線/分 | P3: 稼動時間/分 | Q3: 休息時間
M4: 開始 | N4: 結束 | Q4: 開始 | R4: 結束
A5: 壽司線 | B5: 0 | D5: 雙饗雙手卷(捲) | F5: 0 | G5: 1194 | H5: =F5*G5 -> 0 | J5: 9 | K5: =G5/P5*60 -> 1592 | L5: =K5/J5 -> 176.88889 | M5: 0.17361111 | N5: 0.20486111 | O5: 10 | P5: =(N5-M5)*24*60 -> 45
B6: 0 | D6: 海饌雙手卷(捲) | F6: 0 | G6: 1257 | H6: =F6*G6 -> 0 | J6: 9 | K6: =G6/P6*60 -> 1676 | L6: =K6/J6 -> 186.22222 | M6: 0.20833333 | N6: 0.23958333 | O6: 5 | P6: =(N6-M6)*24*60 -> 45
B7: 壽司手卷 | D7: 雙倍德腸飯卷 | F7: 36.45 | G7: 1378 | H7: =F7*G7 -> 50228.1 | J7: 13 | K7: =G7/P7*60 -> 1503.2727 | L7: =K7/J7 -> 115.63636 | M7: 0.24305556 | N7: 0.28125 | O7: 5 | P7: =(N7-M7)*24*60 -> 55
B8: 壽司手卷 | D8: 明太子泡菜牛飯卷 | F8: 27.05 | G8: 411 | H8: =F8*G8 -> 11117.55 | J8: 13 | K8: =G8/P8*60 -> 1233 | L8: =K8/J8 -> 94.846154 | M8: 0.28472222 | N8: 0.29861111 | O8: 5 | P8: =(N8-M8)*24*60 -> 20 | Q8: 0.30555556 | R8: 0.33680556
B9: 壽司手卷 | D9: 銀鮭美乃滋脆卷 | F9: 19.7 | G9: 891 | H9: =F9*G9 -> 17552.7 | J9: 13 | K9: =G9/P9*60 -> 1188 | L9: =K9/J9 -> 91.384615 | M9: 0.34027778 | N9: 0.37152778 | O9: 5 | P9: =(N9-M9)*24*60 -> 45
B10: 壽司手卷 | D10: 日式鮪魚美乃滋脆卷 | F10: 17.87 | G10: 441 | H10: =F10*G10 -> 7880.67 | J10: 13 | K10: =G10/P10*60 -> 1058.4 | L10: =K10/J10 -> 81.415385 | M10: 0.375 | N10: 0.39236111 | O10: 5 | P10: =(N10-M10)*24*60 -> 25
B11: 壽司手卷 | D11: 長野稻荷壽司 | F11: 25.64 | G11: 534 | H11: =F11*G11 -> 13691.76 | J11: 10 | K11: =G11/P11*60 -> 1602 | L11: =K11/J11 -> 160.2 | M11: 0.39583333 | N11: 0.40972222 | O11: 5 | P11: =(N11-M11)*24*60 -> 20
B12: 壽司手卷 | D12: 雙饗雙手卷 | F12: 29.52 | G12: 1194 | H12: =F12*G12 -> 35246.88 | J12: 12 | K12: =G12/P12*60 -> 1791 | L12: =K12/J12 -> 149.25 | M12: 0.41319444 | N12: 0.44097222 | O12: 5 | P12: =(N12-M12)*24*60 -> 40
B13: 壽司手卷 | D13: 海饌雙手卷 | F13: 29.857 | G13: 1257 | H13: =F13*G13 -> 37530.249 | J13: 12 | K13: =G13/P13*60 -> 1885.5 | L13: =K13/J13 -> 157.125 | M13: 0.44444444 | N13: 0.47222222 | O13: 5 | P13: =(N13-M13)*24*60 -> 40
B14: 飯糰 | D14: 兩粒飯糰(鮪魚.焦糖鮭魚) | F14: 28.57 | G14: 1335 | H14: =F14*G14 -> 38140.95 | J14: 10 | K14: =G14/P14*60 -> 1456.3636 | L14: =K14/J14 -> 145.63636 | M14: 0.47569444 | N14: 0.51388889 | O14: 5 | P14: =(N14-M14)*24*60 -> 55
B15: 0 | F15: 0 | H15: =F15*G15 -> 0
B16: 0 | C16: 壽司線 | D16: 平均 | J16: =AVERAGE(J5:J15) -> 11.4 | K16: =AVERAGE(K5:K15) -> 1498.5536 | L16: =AVERAGE(L5:L15) -> 135.8605
A17: 捲壽司機 | B17: 壽司手卷 | D17: 雙鬆細卷 | F17: 14.03 | G17: 393 | H17: =F17*G17 -> 5513.79 | J17: 6 | K17: =G17/P17*60 -> 1473.75 | L17: =K17/J17 -> 245.625 | M17: 0.18055556 | N17: 0.19166667 | O17: 20 | P17: =(N17-M17)*24*60 -> 16
B18: 飯糰 | D18: 經典鮪魚沙拉細卷 | F18: 14.49 | G18: 598 | H18: =F18*G18 -> 8665.02 | J18: 5 | K18: =G18/P18*60 -> 1495 | L18: =K18/J18 -> 299 | M18: 0.20555556 | N18: 0.22222222 | O18: 20 | P18: =(N18-M18)*24*60 -> 24
B19: 0 | F19: 0 | H19: =F19*G19 -> 0
B20: 0 | F20: 0 | H20: =F20*G20 -> 0
B21: 0 | F21: 0 | H21: =F21*G21 -> 0
B22: 0 | F22: 0 | H22: =F22*G22 -> 0
B23: 0 | F23: 0 | H23: =F23*G23 -> 0
B24: 0 | C24: 連續式 海苔機 | D24: 平均 | J24: =AVERAGE(J17:J23) -> 5.5 | K24: =AVERAGE(K17:K23) -> 1484.375 | L24: =AVERAGE(L17:L23) -> 272.3125
A25: 3300型 飯糰機A | B25: 飯糰 | D25: 煙燻培根飯糰(區) | F25: 15.03 | G25: 1828 | H25: =F25*G25 -> 27474.84 | J25: 4 | K25: =G25/P25*60 -> 2742 | L25: =K25/J25 -> 685.5 | M25: 0.18055556 | N25: 0.20833333 | O25: 20 | P25: =(N25-M25)*24*60 -> 40
B26: 飯糰 | D26: 碳烤燒肉飯飯糰(區) | F26: 18.18 | G26: 2686 | H26: =F26*G26 -> 48831.48 | J26: 4 | K26: =G26/P26*60 -> 2778.6207 | L26: =K26/J26 -> 694.65517 | M26: 0.22222222 | N26: 0.2625 | O26: 20 | P26: =(N26-M26)*24*60 -> 58
B27: 飯糰 | D27: 鮭魚奶油醬油飯糰 | F27: 18.53 | G27: 1943 | H27: =F27*G27 -> 36003.79 | J27: 3 | K27: =G27/P27*60 -> 2775.7143 | L27: =K27/J27 -> 925.2381 | M27: 0.27638889 | N27: 0.30555556 | O27: 20 | P27: =(N27-M27)*24*60 -> 42
B28: 0
B29: 0
B30: 0
B31: 0
B32: 0 | F32: 0 | H32: =F32*G32 -> 0
B33: 0 | F33: 0 | H33: =F33*G33 -> 0
B34: 0 | F34: 0 | H34: =F34*G34 -> 0
B35: 0 | F35: 0 | H35: =F35*G35 -> 0
B36: 0 | F36: 0 | H36: =F36*G36 -> 0
B37: 0 | F37: 0 | H37: =F37*G37 -> 0
B38: 0 | C38: 3300型 飯糰機A | D38: 平均 | J38: =AVERAGE(J25:J37) -> 3.6666667 | K38: =AVERAGE(K25:K37) -> 2765.445 | L38: =AVERAGE(L25:L37) -> 768.46442
A39: 3300型B 飯糰機 | B39: 0 | F39: 0 | H39: =F39*G39 -> 0
B40: 0 | F40: 0 | H40: =F40*G40 -> 0
...

Sheet 晉欣4度C0402
A1: 晉欣廠四度C日報分析 | D1: 總生產量 | E1: =SUM(G5:G173) -> 150555 | F1: 營業額 | G1: =SUM(H5:H173) -> 5649902.1 | H1: 出勤人數 | I1: =M17+M30+M43+M56+M69+M82+M95+M108+M121+M134+M147+M160+M173 -> 198.72143 | J1: 產線配置圖 | M1: 生產實績 | P1: 人時性差異分析 | T1: 日報登錄 | Z1: 合計 次數 | AA1: 合計 時間/分 | AB1: 產線異常分析 說明(5分鐘以上) | AD1: 合計 次數 | AE1: 合計 設備次數 | AF1: 產能差異分析
A2: 04月02日 星期 四 | D2: 人時性 | E2: =AVERAGE(O17,O30,O43,O56,O69,O82,O95,O108,O121,O134,O147,O160,O173) -> 126.00488 | F2: 平均廠價 | G2: =G1/E1 -> 37.527163 | H2: 多次生產數 | I2: =COUNT(I5:I173) -> 5 | Z2: =Z17+Z30+Z43+Z56+Z69+Z82+Z95+Z108+Z121+Z134+Z147+Z160+Z173 -> 0 | AA2: =AA17+AA30+AA43+AA56+AA69+AA82+AA95+AA108+AA121+AA134+AA147+AA160+AA173 -> 0 | AD2: =AD17+AD30+AD43+AD56+AD69+AD82+AD95+AD108+AD121+AD134+AD147+AD160+AD173 -> 2 | AE2: =AE17+AE30+AE43+AE56+AE69+AE82+AE95+AE108+AE121+AE134+AE147+AE160+AE173 -> 3
A3: 線別 | B3: 品類 | D3: 品名 | F3: 廠價 | G3: 生產量 | H3: 營收 | I3: 多次 生產 | J3: 人數 | K3: 產能/時 | L3: 人時性 | M3: 人數 | N3: 產能/時 | O3: 人時性 | P3: 人數 | Q3: 人時性 | R3: 達成率 | S3: 達成率平均 | T3: 生產時間 | V3: 前置、換線時間/分 | W3: 稼動時間/分 | X3: 休息時間 | Z3: 產線異常統計 (5分鐘以上) | AB3: 分析說明 | AD3: 短暫停線統計 (5分鐘以下) | AF3: 產能/時 | AG3: 達成率 | AH3: 達成率平均
T4: 開始 | U4: 結束 | X4: 開始 | Y4: 結束 | Z4: 次數 | AA4: 時間/分 | AD4: 總次數 | AE4: 設備因素(次數)
A5: 四度一組 (ET-600) | B5: 季節調理麵 | D5: 椒麻香蔥雞涼拌麵 | F5: 37.94 | G5: 3785.6 | H5: =F5*G5 -> 143625.66 | J5: 20 | K5: 2400 | L5: 120 | M5: 20 | N5: =G5/W5*60 -> 2294.303 | O5: =N5/M5 -> 114.71515 | P5: =M5-J5 -> 0 | Q5: =O5-L5 -> -5.2848485 | R5: =O5/L5 -> 0.9559596 | S5: =R17 -> 0.92530368 | T5: 0.29166667 | U5: 0.36041667 | V5: 5 | W5: =(U5-T5)*24*60 -> 99 | AF5: =N5-K5 -> -105.69697 | AG5: =N5/K5 -> 0.9559596 | AH5: =AG17 -> 0.95982774
B6: 季節調理麵 | D6: 台式麻醬涼麵 | F6: 31.266132 | G6: 2525.9 | H6: =F6*G6 -> 78975.122 | J6: 18 | K6: 2600 | L6: 144.44444 | M6: 19 | N6: =G6/W6*60 -> 2525.9 | O6: =N6/M6 -> 132.94211 | P6: =M6-J6 -> 1 | Q6: =O6-L6 -> -11.502339 | R6: =O6/L6 -> 0.92036842 | T6: 0.36597222 | U6: 0.40763889 | V6: 8 | W6: =(U6-T6)*24*60 -> 60 | AD6: 1 | AF6: =N6-K6 -> -74.1 | AG6: =N6/K6 -> 0.9715
B7: 季節調理麵 | D7: 大滿足麻醬涼麵 | F7: 38 | G7: 4579.68 | H7: =F7*G7 -> 174027.84 | J7: 19 | K7: 2600 | L7: 136.84211 | M7: 20 | N7: =G7/W7*60 -> 2520.9248 | O7: =N7/M7 -> 126.04624 | P7: =M7-J7 -> 1 | Q7: =O7-L7 -> -10.795867 | R7: =O7/L7 -> 0.92110713 | T7: 0.42291667 | U7: 0.49861111 | V7: 22 | W7: =(U7-T7)*24*60 -> 109 | X7: 0.41111111 | Y7: 0.42013889 | AF7: =N7-K7 -> -79.075229 | AG7: =N7/K7 -> 0.96958645
B8: 季節調理麵 | D8: 大滿足麻醬涼麵 | F8: 38 | G8: 3598.32 | H8: =F8*G8 -> 136736.16 | J8: 19 | K8: 2600 | L8: 136.84211 | M8: 20 | N8: =G8/W8*60 -> 2510.4558 | O8: =N8/M8 -> 125.52279 | P8: =M8-J8 -> 1 | Q8: =O8-L8 -> -11.319315 | R8: =O8/L8 -> 0.91728193 | T8: 0.53819444 | U8: 0.59791667 | V8: 5 | W8: =(U8-T8)*24*60 -> 86 | AF8: =N8-K8 -> -89.544186 | AG8: =N8/K8 -> 0.96555993
B9: 季節調理麵 | D9: 台式麻醬涼麵 | F9: 31.266132 | G9: 1360.1 | H9: =F9*G9 -> 42525.066 | J9: 18 | K9: 2600 | L9: 144.44444 | M9: 19 | N9: =G9/W9*60 -> 2472.9091 | O9: =N9/M9 -> 130.15311 | P9: =M9-J9 -> 1 | Q9: =O9-L9 -> -14.291334 | R9: =O9/L9 -> 0.90105999 | T9: 0.61388889 | U9: 0.63680556 | V9: 23 | W9: =(U9-T9)*24*60 -> 33 | X9: 0.60138889 | Y9: 0.61111111 | AF9: =N9-K9 -> -127.09091 | AG9: =N9/K9 -> 0.95111888
B10: 季節調理麵 | D10: 椒麻香蔥雞涼拌麵 | F10: 37.94 | G10: 2038.4 | H10: =F10*G10 -> 77336.896 | J10: 20 | K10: 2400 | L10: 120 | M10: 20 | N10: =G10/W10*60 -> 2264.8889 | O10: =N10/M10 -> 113.24444 | P10: =M10-J10 -> 0 | Q10: =O10-L10 -> -6.7555556 | R10: =O10/L10 -> 0.9437037 | T10: 0.64097222 | U10: 0.67847222 | V10: 6 | W10: =(U10-T10)*24*60 -> 54 | AF10: =N10-K10 -> -135.11111 | AG10: =N10/K10 -> 0.9437037
B11: 0 | F11: 0 | H11: =F11*G11 -> 0 | AF11: =N11-K11 -> 0 | AG11: =N11/K11 -> #DIV/0!
B12: 0 | F12: 0 | H12: =F12*G12 -> 0 | AF12: =N12-K12 -> 0 | AG12: =N12/K12 -> #DIV/0!
B13: 0 | F13: 0 | H13: =F13*G13 -> 0 | AF13: =N13-K13 -> 0 | AG13: =N13/K13 -> #DIV/0!
B14: 0 | F14: 0 | H14: =F14*G14 -> 0 | W14: =(U14-T14)*24*60 -> 0
B15: 0 | F15: 0 | H15: =F15*G15 -> 0 | W15: =(U15-T15)*24*60 -> 0
B16: 0 | F16: 0 | H16: =F16*G16 -> 0 | W16: =(U16-T16)*24*60 -> 0
B17: 0 | C17: 4度一組 | D17: 平均 | J17: 19 | K17: 2533.3333 | L17: 133.76218 | M17: =AVERAGE(M5:M16) -> 19.666667 | N17: =AVERAGE(N5:N16) -> 2431.5636 | O17: =AVERAGE(O5:O16) -> 123.77064 | P17: =M17-J17 -> 0.66666667 | Q17: =O17-L17 -> -9.9915432 | R17: =O17/L17 -> 0.92530368 | W17: =(U17-T17)*24*60 -> 0 | Z17: =SUM(Z5:Z16) -> 0 | AA17: =SUM(AA5:AA16) -> 0 | AD17: =SUM(AD5:AD16) -> 1 | AE17: =SUM(AE5:AE16) -> 0 | AF17: =N17-K17 -> -101.76973 | AG17: =N17/K17 -> 0.95982774
A18: 四度二組A 熱麵 固定線 (ET-55) | B18: 季節調理麵 | D18: 日式蕎麥沾麵 | F18: 36.86 | G18: 2734.9 | H18: =F18*G18 -> 100808.41 | J18: 17 | K18: 2250 | L18: 132.35294 | M18: 18 | N18: =G18/W18*60 -> 2131.0909 | O18: =N18/M18 -> 118.39394 | P18: =M18-J18 -> 1 | Q18: =O18-L18 -> -13.959002 | R18: =O18/L18 -> 0.89453199 | S18: =R30 -> 0.87072876 | T18: 0.16666667 | U18: 0.22013889 | V18: 5 | W18: =(U18-T18)*24*60 -> 77 | AF18: =N18-K18 -> -118.90909 | AG18: =N18/K18 -> 0.94715152 | AH18: =AG30 -> 0.90376186
B19: 季節調理麵 | D19: 大滿足香辣涼麵 | F19: 38.630952 | G19: 1166.2 | H19: =F19*G19 -> 45051.417 | J19: 18 | K19: 2600 | L19: 144.44444 | M19: 19 | N19: =G19/W19*60 -> 2332.4 | O19: =N19/M19 -> 122.75789 | P19: =M19-J19 -> 1 | Q19: =O19-L19 -> -21.68655 | R19: =O19/L19 -> 0.84986235 | T19: 0.225 | U19: 0.24583333 | V19: 7 | W19: =(U19-T19)*24*60 -> 30 | AE19: 1 | AF19: =N19-K19 -> -267.6 | AG19: =N19/K19 -> 0.89707692
B20: 熱食義麵 | D20: 愛恨椒芝麵 | F20: 38.39 | G20: 1983 | H20: =F20*G20 -> 76127.37 | J20: 16 | K20: 1636 | L20: 102.25 | M20: 17 | N20: =G20/W20*60 -> 1450.9756 | O20: =N20/M20 -> 85.351506 | P20: =M20-J20 -> 1 | Q20: =O20-L20 -> -16.898494 | R20: =O20/L20 -> 0.83473356 | T20: 0.26111111 | U20: 0.31805556 | V20: 22 | W20: =(U20-T20)*24*60 -> 82 | X20: 0.24930556 | Y20: 0.25833333 | AF20: =N20-K20 -> -185.02439 | AG20: =N20/K20 -> 0.88690441
B21: 小菜微波 | D21: 古早味炒炊粉 | F21: 43.14 | G21: 1620 | H21: =F21*G21 -> 69886.8 | J21: 16 | K21: 1440 | L21: 90 | M21: 16 | N21: =G21/W21*60 -> 1369.0141 | O21: =N21/M21 -> 85.56338 | P21: =M21-J21 -> 0 | Q21: =O21-L21 -> -4.4366197 | R21: =O21/L21 -> 0.95070423 | T21: 0.32291667 | U21: 0.37222222 | V21: 7 | W21: =(U21-T21)*24*60 -> 71 | AF21: =N21-K21 -> -70.985915 | AG21: =N21/K21 -> 0.95070423
B22: 熱食義麵 | D22: 辣腐乳麻醬拌麵 | F22: 38.1 | G22: 1013 | H22: =F22*G22 -> 38595.3 | J22: 17 | K22: 1500 | L22: 88.235294 | M22: 16 | N22: =G22/W22*60 -> 1293.1915 | O22: =N22/M22 -> 80.824468 | P22: =M22-J22 -> -1 | Q22: =O22-L22 -> -7.410826 | R22: =O22/L22 -> 0.91601064 | T22: 0.37708333 | U22: 0.40972222 | V22: 7 | W22: =(U22-T22)*24*60 -> 47 | AF22: =N22-K22 -> -206.80851 | AG22: =N22/K22 -> 0.86212766
B23: 季節調理麵 | D23: 大滿足香辣涼麵 | F23: 38.630952 | G23: 4664.8 | H23: =F23*G23 -> 180205.67 | J23: 18 | K23: 2600 | L23: 144.44444 | M23: 19 | N23: =G23/W23*60 -> 2371.9322 | O23: =N23/M23 -> 124.83854 | P23: =M23-J23 -> 1 | Q23: =O23-L23 -> -19.605907 | R23: =O23/L23 -> 0.86426679 | T23: 0.45 | U23: 0.53194444 | V23: 5 | W23: =(U23-T23)*24*60 -> 118 | AF23: =N23-K23 -> -228.0678 | AG23: =N23/K23 -> 0.91228162
B24: 季節調理麵 | D24: 日式蕎麥沾麵 | F24: 36.86 | G24: 1172.1 | H24: =F24*G24 -> 43203.606 | J24: 17 | K24: 2250 | L24: 132.35294 | M24: 18 | N24: =G24/W24*60 -> 1953.5 | O24: =N24/M24 -> 108.52778 | P24: =M24-J24 -> 1 | Q24: =O24-L24 -> -23.825163 | R24: =O24/L24 -> 0.81998765 | T24: 0.5375 | U24: 0.5625 | V24: 8 | W24: =(U24-T24)*24*60 -> 36 | AF24: =N24-K24 -> -296.5 | AG24: =N24/K24 -> 0.86822222
B25: 0 | F25: 0 | H25: =F25*G25 -> 0 | W25: =(U25-T25)*24*60 -> 0 | AF25: =N25-K25 -> 0 | AG25: =N25/K25 -> #DIV/0!
B26: 0 | F26: 0 | H26: =F26*G26 -> 0 | W26: =(U26-T26)*24*60 -> 0 | AF26: =N26-K26 -> 0 | AG26: =N26/K26 -> #DIV/0!
B27: 0 | F27: 0 | H27: =F27*G27 -> 0 | W27: =(U27-T27)*24*60 -> 0 | AF27: =N27-K27 -> 0 | AG27: =N27/K27 -> #DIV/0!
B28: 0 | F28: 0 | H28: =F28*G28 -> 0 | W28: =(U28-T28)*24*60 -> 0 | AF28: =N28-K28 -> 0 | AG28: =N28/K28 -> #DIV/0!
B29: 0 | F29: 0 | H29: =F29*G29 -> 0 | W29: =(U29-T29)*24*60 -> 0 | AF29: =N29-K29 -> 0
B30: 0 | C30: 4度二組A | D30: 平均 | J30: 17 | K30: 2039.4286 | L30: 119.1543 | M30: =AVERAGE(M18:M29) -> 17.571429 | N30: =AVERAGE(N18:N29) -> 1843.1578 | O30: =AVERAGE(O18:O29) -> 103.75107 | P30: =M30-J30 -> 0.57142857 | Q30: =O30-L30 -> -15.403223 | R30: =O30/L30 -> 0.87072876 | Z30: =SUM(Z18:Z29) -> 0 | AA30: =SUM(AA18:AA29) -> 0 | AD30: =SUM(AD18:AD29) -> 0 | AE30: =SUM(AE18:AE29) -> 1 | AF30: =N30-K30 -> -196.27081 | AG30: =N30/K30 -> 0.90376186
A31: 四度二組 (ET-55) | B31: 飯糰 | D31: 大口日式塔塔醬蝦排飯糰 | F31: 35.33 | G31: 1850 | H31: =F31*G31 -> 65360.5 | J31: 12 | K31: 2118 | L31: 176.5 | M31: 12 | N31: =G31/W31*60 -> 1850 | O31: =N31/M31 -> 154.16667 | P31: =M31-J31 -> 0 | Q31: =O31-L31 -> -22.333333 | R31: =O31/L31 -> 0.87346553 | S31: =R43 -> 0.84015517 | T31: 0.16666667 | U31: 0.20833333 | V31: 5 | W31: =(U31-T31)*24*60 -> 60 | AF31: =N31-K31 -> -268 | AG31: =N31/K31 -> 0.87346553 | AH31: =AG43 -> 0.84312468
