Workbook

Sheet 0303
B1: 晉欣廠組合室生產人時性分析
B3: 日期 | D3: 03月03日 星期二 | F3: 訂單量 | H3: 260347.6 | J3: 營業額 | L3: 8657869.4
B4: 項目 | D4: 項目 | F4: ➀ | H4: ➁ | J4: ➂ | L4: ➃ | N4: 異常停線 | P4: 短暫停線
B5: 人時性 | D5: 組合室 | F5: 全溫層 | H5: 4度C(含4度飯糰) | J5: 18度C 一配 | L5: 18度C 二配 | N5: 合計次數 | O5: 時間 | P5: 合計次數 | Q5: 設備次數
D6: 排關平均 | F6: =AVERAGE(D13:O13,P13:Q13,D30:F30,H30,J30:M30) -> 378.1383 | H6: =AVERAGE(D13:P13,Q13) -> 137.43162 | J6: =AVERAGE(D30:H30) -> 754 | L6: =AVERAGE(J30:M30) -> 881.25 | N6: 0 | O6: 0 | P6: 1 | Q6: 3
D7: 實績平均 | F7: =AVERAGE(D14:O14,P14:Q14,D31:F31,J31:M31,H31) -> 354.35194 | H7: =AVERAGE(D14:P14,Q14) -> 124.0391 | J7: =AVERAGE(D31:H31) -> 740.39645 | L7: =AVERAGE(J31:M31) -> 809.43253
D8: 達成率平均 | F8: =AVERAGE(D15:O15,P15:Q15,D32:F32,H32,J32:K32,L32) -> 0.90689419 | H8: =AVERAGE(D15:O15,P15:Q15) -> 0.8943668 | J8: =AVERAGE(D32:H32) -> 0.96426376 | L8: =AVERAGE(J32:M32) -> 0.91953538
B10: 溫層 | D10: ➁4度C-各編組展開
B11: 編組 | D11: 1 | E11: 2 | F11: 3 | G11: 4 | H11: 5 | I11: 6 | J11: 7 | K11: 8 | L11: 9 | M11: 10 | N11: 11 | O11: 12 | P11: 13 | Q11: 14
D12: 4度一組 | E12: 4度二組A | F12: 4度二組B | G12: 4度二組C1 | H12: 4度一組B | I12: 4度三組 | J12: 4度四組 | K12: 4度五組 | L12: 綜合一組 | M12: 綜合二組 | N12: 綜合三組 | O12: 綜合四組 | P12: 便當組 | Q12: 壽司線
B13: 人時性 | C13: 排關 | D13: 126.30306 | E13: 100.21471 | F13: 131.28694 | G13: 368.5 | H13: 228.57143 | I13: 90.799253 | J13: 75.913945 | K13: 113.47619 | L13: 85.272067 | M13: 81.34291 | N13: 83.75586 | O13: 87.786458 | P13: 200.81986 | Q13: 150
C14: 實績 | D14: 117.90461 | E14: 89.679646 | F14: 116.56997 | G14: 324.41384 | H14: 223.20726 | I14: 79.51994 | J14: 64.416768 | K14: 97.987085 | L14: 73.901291 | M14: 72.200257 | N14: 76.131914 | O14: 73.643662 | P14: 190.7482 | Q14: 136.22297
C15: 達成率 | D15: =D14/D13 -> 0.93350559 | E15: =E14/E13 -> 0.89487511 | F15: =F14/F13 -> 0.88790221 | G15: =G14/G13 -> 0.88036319 | H15: =H14/H13 -> 0.97653177 | I15: =I14/I13 -> 0.87577747 | J15: =J14/J13 -> 0.84854987 | K15: =K14/K13 -> 0.86350347 | ... Q15: =Q14/Q13 -> 0.90815311
B16: 作業 時間 | C16: 開始 | D16: 0.29166667 | E16: 0.16666667 | F16: 0.16666667 | G16: 0.16666667 | H16: 0.16666667 | I16: 0.29166667 | J16: 0.33333333 | K16: 0.33333333 | L16: 0.5 | M16: 0.5 | N16: 0.70833333 | O16: 0.70833333 | P16: 0.16666667 | Q16: 0.17361111
C17: 結束 | D17: 0.77638889 | E17: 0.66041667 | F17: 0.6125 | G17: 0.6875 | H17: 0.67152778 | I17: 0.78333333 | J17: 0.83680556 | K17: 0.80902778 | L17: 0.93055556 | M17: 0.95138889 | N17: 0.99236111 | O17: 0.82986111 | P17: 0.60902778 | Q17: 0.69791667
B18: 產線異常 (5分鐘以上)
B20: 短暫停線 (5分鐘以下) | D20: 1
E21: 1 | G21: 2
B22: 配置人數 | D22: 19.3 | E22: 17 | F22: 15.75 | G22: 5.75 | H22: 6.6 | I22: 16.428571 | J22: 19.142857 | K22: 15.571429 | L22: 17.75 | M22: 19.125 | N22: 17.833333 | O22: 17.25 | P22: 11.8 | Q22: 11.2
B23: 主要應用設備 | D23: ET-600 | E23: ET-600 | F23: ET-600 | G23: 八爪機 | H23: 十爪機 | I23: ET-55 | J23: ET-55 | K23: ET-55 | L23: ET-55 | M23: ET-55 | N23: ET-55 | O23: ET-55 | P23: 伺服包裝機 | Q23: 伺服包裝機
B24: 次要應用設備
B25: 備註 | E25: 熱麵固定線 | G25: 烤飯糰 | H25: 烤飯糰 | K25: 吸收產線 | P25: 大口固定線
B27: 溫層 | D27: ➂18度C 一配-各編組展開 | I27: ➃18度C 二配-各編組展開
B28: 編組 | D28: 1 | E28: 2 | F28: 3 | G28: 4 | H28: 5 | I28: 1 | J28: 2 | K28: 3 | L28: 4 | M28: 5
D29: 連續式 海苔機 | E29: 3300型 飯糰機A | F29: 3300型 飯糰機B | G29: 3600型 飯糰機A | H29: 3600型 飯糰機B | I29: 夾心型 飯糰機 | J29: 3300型 飯糰機A | K29: 3300型 飯糰機B | L29: 3600型 飯糰機A | M29: 3600型 飯糰機B
B30: 人時性 | C30: 排關 | D30: 320 | E30: 825 | F30: 825 | G30: 900 | H30: 900 | I30: 680 | J30: 825 | K30: 900 | L30: 900 | M30: 900
C31: 實績 | D31: 271.26211 | E31: 682.77779 | F31: 918.18509 | G31: 880.51711 | H31: 949.24016 | I31: 0 | J31: 798.5697 | K31: 634.15887 | L31: 907.2828 | M31: 897.71875
C32: 達成率 | D32: =D31/D30 -> 0.8476941 | E32: =E31/E30 -> 0.82760944 | F32: =F31/F30 -> 1.1129516 | G32: =G31/G30 -> 0.97835235 | H32: =H31/H30 -> 1.0547113 | I32: =I31/I30 -> 0 | J32: =J31/J30 -> 0.96796327 | K32: =K31/K30 -> 0.70462097 | ... M32: =M31/M30 -> 0.99746528
B33: 作業 時間 | C33: 開始 | D33: 0.18055556 | E33: 0.18055556 | F33: 0.18055556 | G33: 3178.9286 | H33: 0.18055556 | I33: 0 | J33: 0.72222222 | K33: 0.72222222 | L33: 0.72222222 | M33: 0.72222222
C34: 結束 | D34: 0.23472222 | E34: 0.35694444 | F34: 0.24583333 | G34: 1059.6429 | H34: 0.44236111 | I34: 0 | J34: 0.83125 | K34: 0.86805556 | L34: 46085.108 | M34: 0.93055556
B35: 配置人數 | D35: 5.5 | E35: 4 | F35: 3 | G35: 3.75 | H35: 3.2 | I35: 0 | J35: 3.6666667 | K35: 3.6666667 | L35: 3.4 | M35: 3.5
B36: 主要應用設備 | D36: 連續式 海苔機 | E36: 3300型 | F36: 3300型 | G36: 3600型 | H36: 3600型 | I36: 夾心型 | J36: 3300型 | K36: 3300型 | L36: 3600型 | M36: 3600型
B37: 次要應用設備
B38: 備註

Sheet 晉欣18度C0303
A1: 晉欣廠18度C日報分析 | D1: 總生產量 | E1: =SUM(G5:G124) -> 89213 | F1: 營業額 | G1: =SUM(H5:H124) -> 1703091 | H1: 出勤人數 | I1: =+J16+J64+J24+J38+J51+J81+J100+J91+J57+J124+J111 -> 41.683333 | J1: 生產實績 | M1: 日報登錄
A2: 03月03日 星期二 | D2: 人時性 | E2: =AVERAGE(L16,L24,L38,L51,L100,L111,L91) -> 621.20847 | F2: 平均廠價 | G2: =G1/E1 -> 19.090166 | H2: 多次生產數 | I2: =COUNT(I5:I124) -> 0
A3: 線別 | B3: 品類 | D3: 品名 | F3: 廠價 | G3: 生產量 | H3: 營收 | I3: 多次 生產 | J3: 人數 | K3: 產能/時 | L3: 人時性 | M3: 生產時間 | O3: 換線/分 | P3: 稼動時間/分 | Q3: 休息時間
M4: 開始 | N4: 結束 | Q4: 開始 | R4: 結束
A5: 壽司線 | B5: 飯糰 | D5: 麻油雞飯糰 | F5: 29.965493 | G5: 2010 | H5: =F5*G5 -> 60230.642 | J5: 13 | K5: =G5/P5*60 -> 1340 | L5: =K5/J5 -> 103.07692 | M5: 0.17361111 | N5: 0.23611111 | O5: 10 | P5: =(N5-M5)*24*60 -> 90
B6: 0 | D6: 雙饗雙手卷(捲) | F6: 0 | G6: 1337 | H6: =F6*G6 -> 0 | J6: 9 | K6: =G6/P6*60 -> 1604.4 | L6: =K6/J6 -> 178.26667 | M6: 0.23958333 | N6: 0.27430556 | O6: 5 | P6: =(N6-M6)*24*60 -> 50
B7: 0 | D7: 海饌雙手卷(捲) | F7: 0 | G7: 1391 | H7: =F7*G7 -> 0 | J7: 9 | K7: =G7/P7*60 -> 1517.4545 | L7: =K7/J7 -> 168.60606 | M7: 0.27777778 | N7: 0.31597222 | O7: 5 | P7: =(N7-M7)*24*60 -> 55
B8: 壽司手卷 | D8: 雙倍德腸飯卷 | F8: 36.45 | G8: 1947 | H8: =F8*G8 -> 70968.15 | J8: 10 | K8: =G8/P8*60 -> 1460.25 | L8: =K8/J8 -> 146.025 | M8: 0.31944444 | N8: 0.375 | O8: 5 | P8: =(N8-M8)*24*60 -> 80
B9: 壽司手卷 | D9: 明太子泡菜牛飯卷 | F9: 27.05 | G9: 574 | H9: =F9*G9 -> 15526.7 | J9: 13 | K9: =G9/P9*60 -> 1377.6 | L9: =K9/J9 -> 105.96923 | M9: 0.37847222 | N9: 0.39583333 | O9: 5 | P9: =(N9-M9)*24*60 -> 25 | Q9: 0.39583333 | R9: 0.4375
B10: 壽司手卷 | D10: 日式鮪魚美乃滋脆卷 | F10: 17.87 | G10: 3270 | H10: =F10*G10 -> 58434.9 | J10: 12 | K10: =G10/P10*60 -> 1189.0909 | L10: =K10/J10 -> 99.090909 | M10: 0.4375 | N10: 0.55208333 | O10: 5 | P10: =(N10-M10)*24*60 -> 165
B11: 壽司手卷 | D11: 長野稻荷壽司 | F11: 25.64 | G11: 702 | H11: =F11*G11 -> 17999.28 | J11: 10 | K11: =G11/P11*60 -> 1404 | L11: =K11/J11 -> 140.4 | M11: 0.55555556 | N11: 0.57638889 | O11: 5 | P11: =(N11-M11)*24*60 -> 30
B12: 壽司手卷 | D12: 雙饗雙手卷 | F12: 29.52 | G12: 1337 | H12: =F12*G12 -> 39468.24 | J12: 13 | K12: =G12/P12*60 -> 1782.6667 | L12: =K12/J12 -> 137.12821 | M12: 0.57986111 | N12: 0.61111111 | O12: 5 | P12: =(N12-M12)*24*60 -> 45
B13: 壽司手卷 | D13: 海饌雙手卷 | F13: 29.857 | G13: 1391 | H13: =F13*G13 -> 41531.087 | J13: 13 | K13: =G13/P13*60 -> 1854.6667 | L13: =K13/J13 -> 142.66667 | M13: 0.61458333 | N13: 0.64583333 | O13: 5 | P13: =(N13-M13)*24*60 -> 45
B14: 飯糰 | D14: 兩粒飯糰(鮪魚.焦糖鮭魚) | F14: 28.57 | G14: 1645 | H14: =F14*G14 -> 46997.65 | J14: 10 | K14: =G14/P14*60 -> 1410 | L14: =K14/J14 -> 141 | M14: 0.64930556 | N14: 0.69791667 | O14: 5 | P14: =(N14-M14)*24*60 -> 70
B15: 0 | F15: 0 | H15: =F15*G15 -> 0
B16: 0 | C16: 壽司線 | D16: 平均 | J16: =AVERAGE(J5:J15) -> 11.2 | K16: =AVERAGE(K5:K15) -> 1494.0129 | L16: =AVERAGE(L5:L15) -> 136.22297
A17: 捲壽司機 | B17: 壽司手卷 | D17: 雙鬆細卷 | F17: 14.03 | G17: 572 | H17: =F17*G17 -> 8025.16 | J17: 6 | K17: =G17/P17*60 -> 1492.1739 | L17: =K17/J17 -> 248.69565 | M17: 0.18055556 | N17: 0.19652778 | O17: 20 | P17: =(N17-M17)*24*60 -> 23
B18: 飯糰 | D18: 經典鮪魚沙拉細卷 | F18: 14.49 | G18: 857 | H18: =F18*G18 -> 12417.93 | J18: 5 | K18: =G18/P18*60 -> 1469.1429 | L18: =K18/J18 -> 293.82857 | M18: 0.21041667 | N18: 0.23472222 | O18: 20 | P18: =(N18-M18)*24*60 -> 35
B19: 0 | F19: 0 | H19: =F19*G19 -> 0
B20: 0 | F20: 0 | H20: =F20*G20 -> 0
B21: 0 | F21: 0 | H21: =F21*G21 -> 0
B22: 0 | F22: 0 | H22: =F22*G22 -> 0
B23: 0 | F23: 0 | H23: =F23*G23 -> 0
B24: 0 | C24: 連續式 海苔機 | D24: 平均 | J24: =AVERAGE(J17:J23) -> 5.5 | K24: =AVERAGE(K17:K23) -> 1480.6584 | L24: =AVERAGE(L17:L23) -> 271.26211
A25: 3300型 飯糰機A | B25: 飯糰 | D25: 壹號醬炙烤牛飯糰 | F25: 22.281818 | G25: 657 | H25: =F25*G25 -> 14639.155 | J25: 4 | K25: =G25/P25*60 -> 2628 | L25: =K25/J25 -> 657 | M25: 0.18055556 | N25: 0.19097222 | O25: 20 | P25: =(N25-M25)*24*60 -> 15
B26: 飯糰 | D26: 碳烤燒肉飯飯糰(區) | F26: 18.18 | G26: 3103 | H26: =F26*G26 -> 56412.54 | J26: 4 | K26: =G26/P26*60 -> 2778.806 | L26: =K26/J26 -> 694.70149 | M26: 0.20486111 | N26: 0.25138889 | O26: 20 | P26: =(N26-M26)*24*60 -> 67
B27: 飯糰 | D27: 紅運烏魚子紹興飯糰 | F27: 27.27 | G27: 1185 | H27: =F27*G27 -> 32314.95 | J27: 4 | K27: =G27/P27*60 -> 2734.6154 | L27: =K27/J27 -> 683.65385 | M27: 0.26527778 | N27: 0.28333333 | O27: 20 | P27: =(N27-M27)*24*60 -> 26
B28: 飯糰 | D28: 煙燻培根飯糰(區) | F28: 15.03 | G28: 3989 | H28: =F28*G28 -> 59954.67 | J28: 4 | K28: =G28/P28*60 -> 2783.0233 | L28: =K28/J28 -> 695.75581 | M28: 0.29722222 | N28: 0.35694444 | O28: 20 | P28: =(N28-M28)*24*60 -> 86
B29: 0 | F29: 0 | H29: =F29*G29 -> 0
B30: 0 | F30: 0 | H30: =F30*G30 -> 0
B31: 0 | F31: 0 | H31: =F31*G31 -> 0
B32: 0 | F32: 0 | H32: =F32*G32 -> 0
B33: 0 | F33: 0 | H33: =F33*G33 -> 0
B34: 0 | F34: 0 | H34: =F34*G34 -> 0
B35: 0 | F35: 0 | H35: =F35*G35 -> 0
B36: 0 | F36: 0 | H36: =F36*G36 -> 0
B37: 0 | F37: 0 | H37: =F37*G37 -> 0
B38: 0 | C38: 3300型 飯糰機A | D38: 平均 | J38: =AVERAGE(J25:J37) -> 4 | K38: =AVERAGE(K25:K37) -> 2731.1112 | L38: =AVERAGE(L25:L37) -> 682.77779
A39: 3300型B 飯糰機 | B39: 飯糰 | D39: 照燒雞肉飯糰 | F39: 21.45 | G39: 961 | H39: =F39*G39 -> 20613.45 | J39: 3 | K39: =G39/P39*60 -> 2745.7143 | L39: =K39/J39 -> 915.2381 | M39: 0.18055556 | N39: 0.19513889 | O39: 20 | P39: =(N39-M39)*24*60 -> 21
B40: 飯糰 | D40: 鮭魚奶油醬油飯糰 | F40: 18.53 | G40: 2441 | H40: =F40*G40 -> 45231.73 | J40: 3 | K40: =G40/P40*60 -> 2763.3962 | L40: =K40/J40 -> 921.13208 | M40: 0.20902778 | N40: 0.24583333 | O40: 20 | P40: =(N40-M40)*24*60 -> 53
...

Sheet 晉欣4度C0303
A1: 晉欣廠四度C日報分析 | D1: 總生產量 | E1: =SUM(G5:G173) -> 171134.6 | F1: 營業額 | G1: =SUM(H5:H173) -> 6954778.4 | H1: 出勤人數 | I1: =M17+M30+M43+M56+M69+M82+M95+M108+M121+M134+M147+M160+M173 -> 199.30119 | J1: 產線配置圖 | M1: 生產實績 | P1: 人時性差異分析 | T1: 日報登錄 | Z1: 合計 次數 | AA1: 合計 時間/分 | AB1: 產線異常分析 說明(5分鐘以上) | AD1: 合計 次數 | AE1: 合計 設備次數 | AF1: 產能差異分析
A2: 03月03日 星期二 | D2: 人時性 | E2: =AVERAGE(O17,O30,O43,O56,O69,O82,O95,O108,O121,O134,O147,O160,O173) -> 123.10188 | F2: 平均廠價 | G2: =G1/E1 -> 40.63923 | H2: 多次生產數 | I2: =COUNT(I5:I173) -> 4 | Z2: =Z17+Z30+Z43+Z56+Z69+Z82+Z95+Z108+Z121+Z134+Z147+Z160+Z173 -> 0 | AA2: =AA17+AA30+AA43+AA56+AA69+AA82+AA95+AA108+AA121+AA134+AA147+AA160+AA173 -> 0 | AD2: =AD17+AD30+AD43+AD56+AD69+AD82+AD95+AD108+AD121+AD134+AD147+AD160+AD173 -> 1 | AE2: =AE17+AE30+AE43+AE56+AE69+AE82+AE95+AE108+AE121+AE134+AE147+AE160+AE173 -> 3
A3: 線別 | B3: 品類 | D3: 品名 | F3: 廠價 | G3: 生產量 | H3: 營收 | I3: 多次 生產 | J3: 人數 | K3: 產能/時 | L3: 人時性 | M3: 人數 | N3: 產能/時 | O3: 人時性 | P3: 人數 | Q3: 人時性 | R3: 達成率 | S3: 達成率平均 | T3: 生產時間 | V3: 前置、換線時間/分 | W3: 稼動時間/分 | X3: 休息時間 | Z3: 產線異常統計 (5分鐘以上) | AB3: 分析說明 | AD3: 短暫停線統計 (5分鐘以下) | AF3: 產能/時 | AG3: 達成率 | AH3: 達成率平均
T4: 開始 | U4: 結束 | X4: 開始 | Y4: 結束 | Z4: 次數 | AA4: 時間/分 | AD4: 總次數 | AE4: 設備因素(次數)
A5: 四度一組 (ET-600) | B5: 季節調理麵 | D5: 椒麻香蔥雞涼拌麵 | F5: 37.94 | G5: 2917.2 | H5: =F5*G5 -> 110678.57 | J5: 20 | K5: 2400 | L5: 120 | M5: 20 | N5: =G5/W5*60 -> 2244 | O5: =N5/M5 -> 112.2 | P5: =M5-J5 -> 0 | Q5: =O5-L5 -> -7.8 | R5: =O5/L5 -> 0.935 | S5: =R17 -> 0.93350559 | T5: 0.29166667 | U5: 0.34583333 | V5: 5 | W5: =(U5-T5)*24*60 -> 78 | AF5: =N5-K5 -> -156 | AG5: =N5/K5 -> 0.935 | AH5: =AG17 -> 0.97933059
B6: 季節調理麵 | D6: 台式麻醬涼麵 | F6: 31.266132 | G6: 1828.45 | H6: =F6*G6 -> 57168.559 | J6: 18 | K6: 2600 | L6: 144.44444 | M6: 19 | N6: =G6/W6*60 -> 2612.0714 | O6: =N6/M6 -> 137.47744 | P6: =M6-J6 -> 1 | Q6: =O6-L6 -> -6.9670008 | R6: =O6/L6 -> 0.95176692 | T6: 0.35 | U6: 0.37916667 | V6: 6 | W6: =(U6-T6)*24*60 -> 42 | AF6: =N6-K6 -> 12.071429 | AG6: =N6/K6 -> 1.0046429
B7: 季節調理麵 | D7: 大滿足香辣涼麵 | F7: 38.630952 | G7: 2608.45 | H7: =F7*G7 -> 100766.91 | J7: 18 | K7: 2600 | L7: 144.44444 | M7: 19 | N7: =G7/W7*60 -> 2652.661 | O7: =N7/M7 -> 139.61374 | P7: =M7-J7 -> 1 | Q7: =O7-L7 -> -4.8307067 | R7: =O7/L7 -> 0.96655665 | T7: 0.39444444 | U7: 0.43541667 | V7: 22 | W7: =(U7-T7)*24*60 -> 59 | X7: 0.38263889 | Y7: 0.39166667 | AF7: =N7-K7 -> 52.661017 | AG7: =N7/K7 -> 1.0202542
B8: 季節調理麵 | D8: 大滿足麻醬涼麵 | F8: 38 | G8: 3771.6 | H8: =F8*G8 -> 143320.8 | J8: 19 | K8: 2600 | L8: 136.84211 | M8: 20 | N8: =G8/W8*60 -> 2631.3488 | O8: =N8/M8 -> 131.56744 | P8: =M8-J8 -> 1 | Q8: =O8-L8 -> -5.2746634 | R8: =O8/L8 -> 0.96145438 | T8: 0.43958333 | U8: 0.49930556 | V8: 6 | W8: =(U8-T8)*24*60 -> 86 | AF8: =N8-K8 -> 31.348837 | AG8: =N8/K8 -> 1.0120572
B9: 熱食義麵 | D9: 辣腐乳麻醬拌麵 | F9: 38.1 | G9: 1389.3 | H9: =F9*G9 -> 52932.33 | J9: 17 | K9: 1500 | L9: 88.235294 | M9: 17 | N9: =G9/W9*60 -> 1323.1429 | O9: =N9/M9 -> 77.831933 | P9: =M9-J9 -> 0 | Q9: =O9-L9 -> -10.403361 | R9: =O9/L9 -> 0.88209524 | T9: 0.54097222 | U9: 0.58472222 | V9: 7 | W9: =(U9-T9)*24*60 -> 63 | AF9: =N9-K9 -> -176.85714 | AG9: =N9/K9 -> 0.88209524
B10: 季節調理麵 | D10: 大滿足麻醬涼麵 | F10: 38 | G10: 1616.4 | H10: =F10*G10 -> 61423.2 | J10: 19 | K10: 2600 | L10: 136.84211 | M10: 20 | N10: =G10/W10*60 -> 2621.1892 | O10: =N10/M10 -> 131.05946 | P10: =M10-J10 -> 1 | Q10: =O10-L10 -> -5.7826458 | R10: =O10/L10 -> 0.9577422 | T10: 0.58888889 | U10: 0.61458333 | V10: 6 | W10: =(U10-T10)*24*60 -> 37 | AF10: =N10-K10 -> 21.189189 | AG10: =N10/K10 -> 1.0081497
B11: 季節調理麵 | D11: 大滿足香辣涼麵 | F11: 38.630952 | G11: 1404.55 | H11: =F11*G11 -> 54259.104 | J11: 18 | K11: 2600 | L11: 144.44444 | M11: 20 | N11: =G11/W11*60 -> 2633.5312 | O11: =N11/M11 -> 131.67656 | P11: =M11-J11 -> 2 | Q11: =O11-L11 -> -12.767882 | R11: =O11/L11 -> 0.91160697 | T11: 0.62013889 | U11: 0.64236111 | V11: 8 | W11: =(U11-T11)*24*60 -> 32 | AF11: =N11-K11 -> 33.53125 | AG11: =N11/K11 -> 1.0128966
B12: 季節調理麵 | D12: 台式麻醬涼麵 | F12: 31.266132 | G12: 984.55 | H12: =F12*G12 -> 30783.07 | J12: 18 | K12: 2600 | L12: 144.44444 | M12: 20 | N12: =G12/W12*60 -> 2568.3913 | O12: =N12/M12 -> 128.41957 | P12: =M12-J12 -> 2 | Q12: =O12-L12 -> -16.024879 | R12: =O12/L12 -> 0.88905853 | T12: 0.65833333 | U12: 0.67430556 | V12: 23 | W12: =(U12-T12)*24*60 -> 23 | X12: 0.64583333 | Y12: 0.65555556 | AF12: =N12-K12 -> -31.608696 | AG12: =N12/K12 -> 0.98784281
B13: 季節調理麵 | D13: 椒麻香蔥雞涼拌麵 | F13: 37.94 | G13: 1570.8 | H13: =F13*G13 -> 59596.152 | J13: 20 | K13: 2400 | L13: 120 | M13: 20 | N13: =G13/W13*60 -> 2244 | O13: =N13/M13 -> 112.2 | P13: =M13-J13 -> 0 | Q13: =O13-L13 -> -7.8 | R13: =O13/L13 -> 0.935 | T13: 0.67847222 | U13: 0.70763889 | V13: 6 | W13: =(U13-T13)*24*60 -> 42 | AF13: =N13-K13 -> -156 | AG13: =N13/K13 -> 0.935
B14: 微波主食 | D14: 二配濃起司燻腸紅醬焗烤飯 | F14: 50.67 | G14: 1801.8 | H14: =F14*G14 -> 91297.206 | J14: 18 | K14: 1500 | L14: 83.333333 | M14: 18 | N14: =G14/W14*60 -> 1386 | O14: =N14/M14 -> 77 | P14: =M14-J14 -> 0 | Q14: =O14-L14 -> -6.3333333 | R14: =O14/L14 -> 0.924 | T14: 0.72222222 | U14: 0.77638889 | V14: 21 | W14: =(U14-T14)*24*60 -> 78 | X14: 0.71111111 | Y14: 0.71944444 | AD14: 1
B15: 0 | F15: 0 | H15: =F15*G15 -> 0 | W15: =(U15-T15)*24*60 -> 0
B16: 0 | F16: 0 | H16: =F16*G16 -> 0 | W16: =(U16-T16)*24*60 -> 0
B17: 0 | C17: 4度一組 | D17: 平均 | J17: 18.5 | K17: 2340 | L17: 126.30306 | M17: =AVERAGE(M5:M16) -> 19.3 | N17: =AVERAGE(N5:N16) -> 2291.6336 | O17: =AVERAGE(O5:O16) -> 117.90461 | P17: =M17-J17 -> 0.8 | Q17: =O17-L17 -> -8.3984473 | R17: =O17/L17 -> 0.93350559 | W17: =(U17-T17)*24*60 -> 0 | Z17: =SUM(Z5:Z16) -> 0 | AA17: =SUM(AA5:AA16) -> 0 | AD17: =SUM(AD5:AD16) -> 1 | AE17: =SUM(AE5:AE16) -> 0 | AF17: =N17-K17 -> -48.366412 | AG17: =N17/K17 -> 0.97933059
A18: 四度二組A 熱麵 固定線 (ET-55) | B18: 季節調理麵 | D18: 日式蕎麥沾麵 | F18: 36.86 | G18: 2710 | H18: =F18*G18 -> 99890.6 | J18: 17 | K18: 2250 | L18: 132.35294 | M18: 18 | N18: =G18/W18*60 -> 2168 | O18: =N18/M18 -> 120.44444 | P18: =M18-J18 -> 1 | Q18: =O18-L18 -> -11.908497 | R18: =O18/L18 -> 0.91002469 | S18: =R30 -> 0.89487511 | T18: 0.16666667 | U18: 0.21875 | V18: 5 | W18: =(U18-T18)*24*60 -> 75 | AE18: 1 | AF18: =N18-K18 -> -82 | AG18: =N18/K18 -> 0.96355556 | AH18: =AG30 -> 0.91958067
B19: 熱食義麵 | D19: 愛恨椒芝麵 | F19: 38.39 | G19: 2277.8 | H19: =F19*G19 -> 87444.742 | J19: 16 | K19: 1636 | L19: 102.25 | M19: 17 | N19: =G19/W19*60 -> 1438.6105 | O19: =N19/M19 -> 84.624149 | P19: =M19-J19 -> 1 | Q19: =O19-L19 -> -17.625851 | R19: =O19/L19 -> 0.82762004 | T19: 0.22361111 | U19: 0.28958333 | V19: 7 | W19: =(U19-T19)*24*60 -> 95 | AF19: =N19-K19 -> -197.38947 | AG19: =N19/K19 -> 0.87934629
B20: 小菜微波 | D20: 古早味炒炊粉 | F20: 43.14 | G20: 2106 | H20: =F20*G20 -> 90852.84 | J20: 16 | K20: 1440 | L20: 90 | M20: 16 | N20: =G20/W20*60 -> 1388.5714 | O20: =N20/M20 -> 86.785714 | P20: =M20-J20 -> 0 | Q20: =O20-L20 -> -3.2142857 | R20: =O20/L20 -> 0.96428571 | T20: 0.30486111 | U20: 0.36805556 | V20: 22 | W20: =(U20-T20)*24*60 -> 91 | X20: 0.29305556 | Y20: 0.30208333 | AF20: =N20-K20 -> -51.428571 | AG20: =N20/K20 -> 0.96428571
B21: 熱食義麵 | D21: 辣腐乳麻醬拌麵 | F21: 38.1 | G21: 3704.8 | H21: =F21*G21 -> 141152.88 | J21: 17 | K21: 1500 | L21: 88.235294 | M21: 17 | N21: =G21/W21*60 -> 1331.0659 | O21: =N21/M21 -> 78.297992 | P21: =M21-J21 -> 0 | Q21: =O21-L21 -> -9.9373019 | R21: =O21/L21 -> 0.88737725 | T21: 0.37291667 | U21: 0.48888889 | V21: 7 | W21: =(U21-T21)*24*60 -> 167 | AF21: =N21-K21 -> -168.93413 | AG21: =N21/K21 -> 0.88737725
B22: 熱食義麵 | D22: 辣腐乳麻醬拌麵 | F22: 38.1 | G22: 4167.9 | H22: =F22*G22 -> 158796.99 | J22: 17 | K22: 1500 | L22: 88.235294 | M22: 17 | N22: =G22/W22*60 -> 1330.1809 | O22: =N22/M22 -> 78.245932 | P22: =M22-J22 -> 0 | Q22: =O22-L22 -> -9.9893617 | R22: =O22/L22 -> 0.88678723 | T22: 0.52986111 | U22: 0.66041667 | V22: 6 | W22: =(U22-T22)*24*60 -> 188 | AF22: =N22-K22 -> -169.81915 | AG22: =N22/K22 -> 0.88678723
B23: 0 | F23: 0 | H23: =F23*G23 -> 0 | W23: =(U23-T23)*24*60 -> 0 | AF23: =N23-K23 -> 0 | AG23: =N23/K23 -> #DIV/0!
B24: 0 | F24: 0 | H24: =F24*G24 -> 0 | W24: =(U24-T24)*24*60 -> 0 | AF24: =N24-K24 -> 0 | AG24: =N24/K24 -> #DIV/0!
B25: 0 | F25: 0 | H25: =F25*G25 -> 0 | AF25: =N25-K25 -> 0 | AG25: =N25/K25 -> #DIV/0!
B26: 0 | F26: 0 | H26: =F26*G26 -> 0 | W26: =(U26-T26)*24*60 -> 0 | AF26: =N26-K26 -> 0 | AG26: =N26/K26 -> #DIV/0!
B27: 0 | F27: 0 | H27: =F27*G27 -> 0 | W27: =(U27-T27)*24*60 -> 0 | AF27: =N27-K27 -> 0 | AG27: =N27/K27 -> #DIV/0!
B28: 0 | F28: 0 | H28: =F28*G28 -> 0 | W28: =(U28-T28)*24*60 -> 0 | AF28: =N28-K28 -> 0 | AG28: =N28/K28 -> #DIV/0!
B29: 0 | F29: 0 | H29: =F29*G29 -> 0 | W29: =(U29-T29)*24*60 -> 0 | AF29: =N29-K29 -> 0
B30: 0 | C30: 4度二組A | D30: 平均 | J30: 16.6 | K30: 1665.2 | L30: 100.21471 | M30: =AVERAGE(M18:M29) -> 17 | N30: =AVERAGE(N18:N29) -> 1531.2857 | O30: =AVERAGE(O18:O29) -> 89.679646 | P30: =M30-J30 -> 0.4 | Q30: =O30-L30 -> -10.535059 | R30: =O30/L30 -> 0.89487511 | Z30: =SUM(Z18:Z29) -> 0 | AA30: =SUM(AA18:AA29) -> 0 | AD30: =SUM(AD18:AD29) -> 0 | AE30: =SUM(AE18:AE29) -> 1 | AF30: =N30-K30 -> -133.91427 | AG30: =N30/K30 -> 0.91958067
A31: 四度二組 (ET-55) | B31: 飯糰 | D31: 大口金黃薯牛堡飯糰 | F31: 34.23 | G31: 2166 | H31: =F31*G31 -> 74142.18 | J31: 13 | K31: 2250 | L31: 173.07692 | M31: 13 | N31: =G31/W31*60 -> 2096.129 | O31: =N31/M31 -> 161.24069 | P31: =M31-J31 -> 0 | Q31: =O31-L31 -> -11.836228 | R31: =O31/L31 -> 0.9316129 | S31: =R43 -> 0.88790221 | T31: 0.16666667 | U31: 0.20972222 | V31: 5 | W31: =(U31-T31)*24*60 -> 62 | AF31: =N31-K31 -> -153.87097 | AG31: =N31/K31 -> 0.9316129 | AH31: =AG43 -> 0.88855107
B32: 飯糰 | D32: 大口日式塔塔醬蝦排飯糰 | F32: 35.33 | G32: 2242 | H32: =F32*G32 -> 79209.86 | J32: 12 | K32: 2118 | L32: 176.5 | M32: 12 | N32: =G32/W32*60 -> 2101.875 | O32: =N32/M32 -> 175.15625 | P32: =M32-J32 -> 0 | Q32: =O32-L32 -> -1.34375 | R32: =O32/L32 -> 0.99238669 | T32: 0.21458333 | U32: 0.25902778 | V32: 7 | W32: =(U32-T32)*24*60 -> 64 | AF32: =N32-K32 -> -16.125 | AG32: =N32/K32 -> 0.99238669
B33: 飯糰 | D33: 大口義式香草雞腿排飯糰 | F33: 36.41 | G33: 2388.05 | H33: =F33*G33 -> 86948.9 | J33: 10 | K33: 2769 | L33: 276.9 | M33: 10 | N33: =G33/W33*60 -> 2274.3333 | O33: =N33/M33 -> 227.43333 | P33: =M33-J33 -> 0 | Q33: =O33-L33 -> -49.466667 | R33: =O33/L33 -> 0.82135548 | T33: 0.275 | U33: 0.31875 | V33: 23 | W33: =(U33-T33)*24*60 -> 63 | X33: 0.2625 | Y33: 0.27222222 | AF33: =N33-K33 -> -494.66667 | AG33: =N33/K33 -> 0.82135548
B34: 微波主食 | D34: 日式野菜烘蛋燴飯 | F34: 49.91 | G34: 832 | H34: =F34*G34 -> 41525.12 | J34: 17 | K34: 1500 | L34: 88.235294 | M34: 17 | N34: =G34/W34*60 -> 1313.6842 | O34: =N34/M34 -> 77.275542 | P34: =M34-J34 -> 0 | Q34: =O34-L34 -> -10.959752 | R34: =O34/L34 -> 0.87578947 | T34: 0.32291667 | U34: 0.34930556 | V34: 6 | W34: =(U34-T34)*24*60 -> 38 | AF34: =N34-K34 -> -186.31579 | AG34: =N34/K34 -> 0.87578947
B35: 微波主食 | D35: 壽喜燒牛丼 | F35: 53.27 | G35: 1443 | H35: =F35*G35 -> 76868.61 | J35: 18 | K35: 1500 | L35: 83.333333 | M35: 18 | N35: =G35/W35*60 -> 1332 | O35: =N35/M35 -> 74 | P35: =M35-J35 -> 0 | Q35: =O35-L35 -> -9.3333333 | R35: =O35/L35 -> 0.888 | T35: 0.36736111 | U35: 0.4125 | V35: 22 | W35: =(U35-T35)*24*60 -> 65 | X35: 0.35277778 | Y35: 0.36180556 | AF35: =N35-K35 -> -168 | AG35: =N35/K35 -> 0.888
B36: 小菜微波 | D36: 香辣醬粉絲煲 | F36: 29.11315 | G36: 2724.54 | H36: =F36*G36 -> 79319.941 | J36: 20 | K36: 1500 | L36: 75 | M36: 20 | N36: =G36/W36*60 -> 1329.0439 | O36: =N36/M36 -> 66.452195 | P36: =M36-J36 -> 0 | Q36: =O36-L36 -> -8.5478049 | R36: =O36/L36 -> 0.88602927 | T36: 0.42708333 | U36: 0.5125 | V36: 21 | W36: =(U36-T36)*24*60 -> 123 | X36: 0.41597222 | Y36: 0.42430556 | AF36: =N36-K36 -> -170.9561 | AG36: =N36/K36 -> 0.88602927
B37: 熱食義麵 | D37: 愛恨椒芝麵 | F37: 38.39 | G37: 976.2 | H37: =F37*G37 -> 37476.318 | I37: 2 | J37: 16 | K37: 1636 | L37: 102.25 | M37: 16 | N37: =G37/W37*60 -> 1362.1395 | O37: =N37/M37 -> 85.133721 | P37: =M37-J37 -> 0 | Q37: =O37-L37 -> -17.116279 | R37: =O37/L37 -> 0.83260363 | T37: 0.55347222 | U37: 0.58333333 | V37: 6 | W37: =(U37-T37)*24*60 -> 43 | AF37: =N37-K37 -> -273.86047 | AG37: =N37/K37 -> 0.83260363
B38: 小菜微波 | D38: 香辣醬粉絲煲 | F38: 29.11315 | G38: 768.46 | H38: =F38*G38 -> 22372.291 | J38: 20 | K38: 1500 | L38: 75 | M38: 20 | N38: =G38/W38*60 -> 1317.36 | O38: =N38/M38 -> 65.868 | P38: =M38-J38 -> 0 | Q38: =O38-L38 -> -9.132 | R38: =O38/L38 -> 0.87824 | T38: 0.58819444 | U38: 0.6125 | V38: 7 | W38: =(U38-T38)*24*60 -> 35 | AF38: =N38-K38 -> -182.64 | AG38: =N38/K38 -> 0.87824
B39: 0 | F39: 0 | H39: =F39*G39 -> 0 | W39: =(U39-T39)*24*60 -> 0 | AF39: =N39-K39 -> 0 | AG39: =N39/K39 -> #DIV/0!
B40: 0 | F40: 0 | H40: =F40*G40 -> 0 | W40: =(U40-T40)*24*60 -> 0 | AF40: =N40-K40 -> 0 | AG40: =N40/K40 -> #DIV/0!
...

Sheet 0304
B1: 晉欣廠組合室生產人時性分析
B3: 日期 | D3: 03月04日 星期三 | F3: 訂單量 | H3: 239059.4 | J3: 營業額 | L3: 7786045.8
B4: 項目 | D4: 項目 | F4: ➀ | H4: ➁ | J4: ➂ | L4: ➃ | N4: 異常停線 | P4: 短暫停線
B5: 人時性 | D5: 組合室 | F5: 全溫層 | H5: 4度C(含4度飯糰) | J5: 18度C 一配 | L5: 18度C 二配 | N5: 合計次數 | O5: 時間 | P5: 合計次數 | Q5: 設備次數
D6: 排關平均 | F6: =AVERAGE(D13:O13,P13:Q13,D30:F30,H30,J30:M30) -> 378.22012 | H6: =AVERAGE(D13:P13,Q13) -> 137.56018 | J6: =AVERAGE(D30:H30) -> 754 | L6: =AVERAGE(J30:M30) -> 881.25 | N6: 0 | O6: 0 | P6: 2 | Q6: 2
D7: 實績平均 | F7: =AVERAGE(D14:O14,P14:Q14,D31:F31,J31:M31,H31) -> 350.63525 | H7: =AVERAGE(D14:P14,Q14) -> 123.30822 | J7: =AVERAGE(D31:H31) -> 768.51367 | L7: =AVERAGE(J31:M31) -> 759.37572
D8: 達成率平均 | F8: =AVERAGE(D15:O15,P15:Q15,D32:F32,H32,J32:K32,L32) -> 0.90507217 | H8: =AVERAGE(D15:O15,P15:Q15) -> 0.88952599 | J8: =AVERAGE(D32:H32) -> 1.0020475 | L8: =AVERAGE(J32:M32) -> 0.86213688
B10: 溫層 | D10: ➁4度C-各編組展開
B11: 編組 | D11: 1 | E11: 2 | F11: 3 | G11: 4 | H11: 5 | I11: 6 | J11: 7 | K11: 8 | L11: 9 | M11: 10 | N11: 11 | O11: 12 | P11: 13 | Q11: 14
D12: 4度一組 | E12: 4度二組A | F12: 4度二組B | G12: 4度二組C1 | H12: 4度一組B | I12: 4度三組 | J12: 4度四組 | K12: 4度五組 | L12: 綜合一組 | M12: 綜合二組 | N12: 綜合三組 | O12: 綜合四組 | P12: 便當組 | Q12: 壽司線
B13: 人時性 | C13: 排關 | D13: 126.30306 | E13: 100.21471 | F13: 131.28694 | G13: 368.5 | H13: 228.57143 | I13: 92.599129 | J13: 75.913945 | K13: 113.47619 | L13: 85.272067 | M13: 81.34291 | N13: 83.75586 | O13: 87.786458 | P13: 200.81986 | Q13: 150
C14: 實績 | D14: 119.65111 | E14: 89.65453 | F14: 115.43889 | G14: 326.43782 | H14: 209.81149 | I14: 79.991837 | J14: 64.176253 | K14: 96.892882 | L14: 74.411995 | M14: 72.926084 | N14: 76.422787 | O14: 70.979054 | P14: 190.69368 | Q14: 138.82666
C15: 達成率 | D15: =D14/D13 -> 0.94733345 | E15: =E14/E13 -> 0.89462448 | F15: =F14/F13 -> 0.8792869 | G15: =G14/G13 -> 0.88585568 | H15: =H14/H13 -> 0.91792525 | I15: =I14/I13 -> 0.86385086 | J15: =J14/J13 -> 0.84538162 | K15: =K14/K13 -> 0.8538609 | ... Q15: =Q14/Q13 -> 0.92551108
B16: 作業 時間 | C16: 開始 | D16: 0.29166667 | E16: 0.16666667 | F16: 0.16666667 | G16: 0.16666667 | H16: 0.16666667 | I16: 0.29166667 | J16: 0.33333333 | K16: 0.33333333 | L16: 0.5 | M16: 0.5 | N16: 0.70833333 | O16: 0.70833333 | P16: 0.16666667 | Q16: 0.17361111
C17: 結束 | D17: 0.775 | E17: 0.55416667 | F17: 0.59722222 | G17: 0.65486111 | H17: 0.62152778 | I17: 0.72777778 | J17: 0.79236111 | K17: 0.77013889 | L17: 0.90069444 | M17: 0.93888889 | N17: 0.97291667 | O17: 0.82291667 | P17: 0.59583333 | Q17: 0.66319444
B18: 產線異常 (5分鐘以上)
B20: 短暫停線 (5分鐘以下) | L20: 1 | N20: 1
O21: 2
B22: 配置人數 | D22: 19 | E22: 17 | F22: 15.875 | G22: 5.75 | H22: 7 | I22: 16.333333 | J22: 19.285714 | K22: 15.571429 | L22: 17.75 | M22: 19.125 | N22: 17.833333 | O22: 17.25 | P22: 11.8 | Q22: 11.3
B23: 主要應用設備 | D23: ET-600 | E23: ET-600 | F23: ET-600 | G23: 八爪機 | H23: 十爪機 | I23: ET-55 | J23: ET-55 | K23: ET-55 | L23: ET-55 | M23: ET-55 | N23: ET-55 | O23: ET-55 | P23: 伺服包裝機 | Q23: 伺服包裝機
B24: 次要應用設備
B25: 備註 | E25: 熱麵固定線 | G25: 烤飯糰 | H25: 烤飯糰 | K25: 吸收產線 | P25: 大口固定線
B27: 溫層 | D27: ➂18度C 一配-各編組展開 | I27: ➃18度C 二配-各編組展開
B28: 編組 | D28: 1 | E28: 2 | F28: 3 | G28: 4 | H28: 5 | I28: 1 | J28: 2 | K28: 3 | L28: 4 | M28: 5
D29: 連續式 海苔機 | E29: 3300型 飯糰機A | F29: 3300型 飯糰機B | G29: 3600型 飯糰機A | H29: 3600型 飯糰機B | I29: 夾心型 飯糰機 | J29: 3300型 飯糰機A | K29: 3300型 飯糰機B | L29: 3600型 飯糰機A | M29: 3600型 飯糰機B
B30: 人時性 | C30: 排關 | D30: 320 | E30: 825 | F30: 825 | G30: 900 | H30: 900 | I30: 680 | J30: 825 | K30: 900 | L30: 900 | M30: 900
C31: 實績 | D31: 284.59503 | E31: 720.18859 | F31: 938.79552 | G31: 892.41085 | H31: 1006.5784 | I31: 0 | J31: 728.08889 | K31: 598.06667 | L31: 888.68823 | M31: 822.65909
C32: 達成率 | D32: =D31/D30 -> 0.88935947 | E32: =E31/E30 -> 0.87295587 | F32: =F31/F30 -> 1.137934 | G32: =G31/G30 -> 0.99156761 | H32: =H31/H30 -> 1.1184204 | I32: =I31/I30 -> 0 | J32: =J31/J30 -> 0.88253199 | K32: =K31/K30 -> 0.66451852 | ... M32: =M31/M30 -> 0.91406566
B33: 作業 時間 | C33: 開始 | D33: 0.18055556 | E33: 0.18055556 | F33: 0.17361111 | G33: 3229.0909 | H33: 0.18055556 | I33: 0 | J33: 0.72222222 | K33: 0.72222222 | L33: 0.72222222 | M33: 0.72222222
C34: 結束 | D34: 0.23472222 | E34: 0.33125 | F34: 0.2375 | G34: 1076.3636 | H34: 0.43055556 | I34: 0 | J34: 0.84027778 | K34: 0.875 | L34: 46086.101 | M34: 0.92708333
B35: 配置人數 | D35: 5.5 | E35: 4 | F35: 3 | G35: 3.75 | H35: 3.2 | I35: 0 | J35: 3.6666667 | K35: 3.6666667 | L35: 3.4 | M35: 3.5
B36: 主要應用設備 | D36: 連續式 海苔機 | E36: 3300型 | F36: 3300型 | G36: 3600型 | H36: 3600型 | I36: 夾心型 | J36: 3300型 | K36: 3300型 | L36: 3600型 | M36: 3600型
B37: 次要應用設備
B38: 備註

Sheet 晉欣18度C0304
A1: 晉欣廠18度C日報分析 | D1: 總生產量 | E1: =SUM(G5:G124) -> 85989 | F1: 營業額 | G1: =SUM(H5:H124) -> 1649621.2 | H1: 出勤人數 | I1: =+J16+J64+J24+J38+J51+J81+J100+J91+J57+J124+J111 -> 41.783333 | J1: 生產實績 | M1: 日報登錄
A2: 03月04日 星期三 | D2: 人時性 | E2: =AVERAGE(L16,L24,L38,L51,L100,L111,L91) -> 613.8928 | F2: 平均廠價 | G2: =G1/E1 -> 19.184095 | H2: 多次生產數 | I2: =COUNT(I5:I124) -> 0
A3: 線別 | B3: 品類 | D3: 品名 | F3: 廠價 | G3: 生產量 | H3: 營收 | I3: 多次 生產 | J3: 人數 | K3: 產能/時 | L3: 人時性 | M3: 生產時間 | O3: 換線/分 | P3: 稼動時間/分 | Q3: 休息時間
M4: 開始 | N4: 結束 | Q4: 開始 | R4: 結束
A5: 壽司線 | B5: 飯糰 | D5: 麻油雞飯糰 | F5: 29.965493 | G5: 1827 | H5: =F5*G5 -> 54746.957 | J5: 13 | K5: =G5/P5*60 -> 1289.6471 | L5: =K5/J5 -> 99.20362 | M5: 0.17361111 | N5: 0.23263889 | O5: 10 | P5: =(N5-M5)*24*60 -> 85
B6: 0 | D6: 雙饗雙手卷(捲) | F6: 0 | G6: 1416 | H6: =F6*G6 -> 0 | J6: 9 | K6: =G6/P6*60 -> 1544.7273 | L6: =K6/J6 -> 171.63636 | M6: 0.23958333 | N6: 0.27777778 | O6: 10 | P6: =(N6-M6)*24*60 -> 55
B7: 0 | D7: 海饌雙手卷(捲) | F7: 0 | G7: 1510 | H7: =F7*G7 -> 0 | J7: 9 | K7: =G7/P7*60 -> 1647.2727 | L7: =K7/J7 -> 183.0303 | M7: 0.28125 | N7: 0.31944444 | O7: 5 | P7: =(N7-M7)*24*60 -> 55
B8: 壽司手卷 | D8: 雙倍德腸飯卷 | F8: 36.45 | G8: 2074 | H8: =F8*G8 -> 75597.3 | J8: 13 | K8: =G8/P8*60 -> 1464 | L8: =K8/J8 -> 112.61538 | M8: 0.32291667 | N8: 0.38194444 | O8: 5 | P8: =(N8-M8)*24*60 -> 85
B9: 壽司手卷 | D9: 明太子泡菜牛飯卷 | F9: 27.05 | G9: 536 | H9: =F9*G9 -> 14498.8 | J9: 13 | K9: =G9/P9*60 -> 1608 | L9: =K9/J9 -> 123.69231 | M9: 0.38541667 | N9: 0.39930556 | O9: 5 | P9: =(N9-M9)*24*60 -> 20 | Q9: 0.39930556 | R9: 0.44097222
B10: 壽司手卷 | D10: 日式鮪魚美乃滋脆卷 | F10: 17.87 | G10: 2087 | H10: =F10*G10 -> 37294.69 | J10: 12 | K10: =G10/P10*60 -> 1192.5714 | L10: =K10/J10 -> 99.380952 | M10: 0.44097222 | N10: 0.51388889 | O10: 5 | P10: =(N10-M10)*24*60 -> 105
B11: 壽司手卷 | D11: 長野稻荷壽司 | F11: 25.64 | G11: 769 | H11: =F11*G11 -> 19717.16 | J11: 10 | K11: =G11/P11*60 -> 1538 | L11: =K11/J11 -> 153.8 | M11: 0.51736111 | N11: 0.53819444 | O11: 5 | P11: =(N11-M11)*24*60 -> 30
B12: 壽司手卷 | D12: 雙饗雙手卷 | F12: 29.52 | G12: 1416 | H12: =F12*G12 -> 41800.32 | J12: 12 | K12: =G12/P12*60 -> 1699.2 | L12: =K12/J12 -> 141.6 | M12: 0.54166667 | N12: 0.57638889 | O12: 5 | P12: =(N12-M12)*24*60 -> 50
B13: 壽司手卷 | D13: 海饌雙手卷 | F13: 29.857 | G13: 1510 | H13: =F13*G13 -> 45084.07 | J13: 12 | K13: =G13/P13*60 -> 1812 | L13: =K13/J13 -> 151 | M13: 0.57986111 | N13: 0.61458333 | O13: 5 | P13: =(N13-M13)*24*60 -> 50
B14: 飯糰 | D14: 兩粒飯糰(鮪魚.焦糖鮭魚) | F14: 28.57 | G14: 1650 | H14: =F14*G14 -> 47140.5 | J14: 10 | K14: =G14/P14*60 -> 1523.0769 | L14: =K14/J14 -> 152.30769 | M14: 0.61805556 | N14: 0.66319444 | O14: 5 | P14: =(N14-M14)*24*60 -> 65
B15: 0 | F15: 0 | H15: =F15*G15 -> 0
B16: 0 | C16: 壽司線 | D16: 平均 | J16: =AVERAGE(J5:J15) -> 11.3 | K16: =AVERAGE(K5:K15) -> 1531.8495 | L16: =AVERAGE(L5:L15) -> 138.82666
A17: 捲壽司機 | B17: 壽司手卷 | D17: 雙鬆細卷 | F17: 14.03 | G17: 601 | H17: =F17*G17 -> 8432.03 | J17: 6 | K17: =G17/P17*60 -> 1567.8261 | L17: =K17/J17 -> 261.30435 | M17: 0.18055556 | N17: 0.19652778 | O17: 20 | P17: =(N17-M17)*24*60 -> 23
B18: 飯糰 | D18: 經典鮪魚沙拉細卷 | F18: 14.49 | G18: 898 | H18: =F18*G18 -> 13012.02 | J18: 5 | K18: =G18/P18*60 -> 1539.4286 | L18: =K18/J18 -> 307.88571 | M18: 0.21041667 | N18: 0.23472222 | O18: 20 | P18: =(N18-M18)*24*60 -> 35
B19: 0 | F19: 0 | H19: =F19*G19 -> 0
B20: 0 | F20: 0 | H20: =F20*G20 -> 0
B21: 0 | F21: 0 | H21: =F21*G21 -> 0
B22: 0 | F22: 0 | H22: =F22*G22 -> 0
B23: 0 | F23: 0 | H23: =F23*G23 -> 0
B24: 0 | C24: 連續式 海苔機 | D24: 平均 | J24: =AVERAGE(J17:J23) -> 5.5 | K24: =AVERAGE(K17:K23) -> 1553.6273 | L24: =AVERAGE(L17:L23) -> 284.59503
A25: 3300型 飯糰機A | B25: 飯糰 | D25: 壹號醬炙烤牛飯糰 | F25: 22.281818 | G25: 642 | H25: =F25*G25 -> 14304.927 | J25: 4 | K25: =G25/P25*60 -> 2963.0769 | L25: =K25/J25 -> 740.76923 | M25: 0.18055556 | N25: 0.18958333 | O25: 20 | P25: =(N25-M25)*24*60 -> 13
B26: 飯糰 | D26: 碳烤燒肉飯飯糰(區) | F26: 18.18 | G26: 3041 | H26: =F26*G26 -> 55285.38 | J26: 4 | K26: =G26/P26*60 -> 2807.0769 | L26: =K26/J26 -> 701.76923 | M26: 0.20347222 | N26: 0.24861111 | O26: 20 | P26: =(N26-M26)*24*60 -> 65
B27: 飯糰 | D27: 紅運烏魚子紹興飯糰 | F27: 27.27 | G27: 1157 | H27: =F27*G27 -> 31551.39 | J27: 4 | K27: =G27/P27*60 -> 2892.5 | L27: =K27/J27 -> 723.125 | M27: 0.2625 | N27: 0.27916667 | O27: 20 | P27: =(N27-M27)*24*60 -> 24
B28: 飯糰 | D28: 煙燻培根飯糰(區) | F28: 15.03 | G28: 2622 | H28: =F28*G28 -> 39408.66 | J28: 4 | K28: =G28/P28*60 -> 2860.3636 | L28: =K28/J28 -> 715.09091 | M28: 0.29305556 | N28: 0.33125 | O28: 20 | P28: =(N28-M28)*24*60 -> 55
B29: 0 | F29: 0 | H29: =F29*G29 -> 0
B30: 0 | F30: 0 | H30: =F30*G30 -> 0
B31: 0 | F31: 0 | H31: =F31*G31 -> 0
B32: 0 | F32: 0 | H32: =F32*G32 -> 0
B33: 0 | F33: 0 | H33: =F33*G33 -> 0
B34: 0 | F34: 0 | H34: =F34*G34 -> 0
B35: 0 | F35: 0 | H35: =F35*G35 -> 0
B36: 0 | F36: 0 | H36: =F36*G36 -> 0
B37: 0 | F37: 0 | H37: =F37*G37 -> 0
B38: 0 | C38: 3300型 飯糰機A | D38: 平均 | J38: =AVERAGE(J25:J37) -> 4 | K38: =AVERAGE(K25:K37) -> 2880.7544 | L38: =AVERAGE(L25:L37) -> 720.18859
A39: 3300型B 飯糰機 | B39: 飯糰 | D39: 照燒雞肉飯糰 | F39: 21.45 | G39: 982 | H39: =F39*G39 -> 21063.9 | J39: 3 | K39: =G39/P39*60 -> 2805.7143 | L39: =K39/J39 -> 935.2381 | M39: 0.17361111 | N39: 0.18819444 | O39: 10 | P39: =(N39-M39)*24*60 -> 21
B40: 飯糰 | D40: 鮭魚奶油醬油飯糰 | F40: 18.53 | G40: 2403 | H40: =F40*G40 -> 44527.59 | J40: 3 | K40: =G40/P40*60 -> 2827.0588 | L40: =K40/J40 -> 942.35294 | M40: 0.20208333 | N40: 0.2375 | O40: 20 | P40: =(N40-M40)*24*60 -> 51
...

Sheet 晉欣4度C0304
A1: 晉欣廠四度C日報分析 | D1: 總生產量 | E1: =SUM(G5:G173) -> 153070.4 | F1: 營業額 | G1: =SUM(H5:H173) -> 6136424.6 | H1: 出勤人數 | I1: =M17+M30+M43+M56+M69+M82+M95+M108+M121+M134+M147+M160+M173 -> 199.57381 | J1: 產線配置圖 | M1: 生產實績 | P1: 人時性差異分析 | T1: 日報登錄 | Z1: 合計 次數 | AA1: 合計 時間/分 | AB1: 產線異常分析 說明(5分鐘以上) | AD1: 合計 次數 | AE1: 合計 設備次數 | AF1: 產能差異分析
A2: 03月04日 星期三 | D2: 人時性 | E2: =AVERAGE(O17,O30,O43,O56,O69,O82,O95,O108,O121,O134,O147,O160,O173) -> 122.11449 | F2: 平均廠價 | G2: =G1/E1 -> 40.088904 | H2: 多次生產數 | I2: =COUNT(I5:I173) -> 3 | Z2: =Z17+Z30+Z43+Z56+Z69+Z82+Z95+Z108+Z121+Z134+Z147+Z160+Z173 -> 0 | AA2: =AA17+AA30+AA43+AA56+AA69+AA82+AA95+AA108+AA121+AA134+AA147+AA160+AA173 -> 0 | AD2: =AD17+AD30+AD43+AD56+AD69+AD82+AD95+AD108+AD121+AD134+AD147+AD160+AD173 -> 2 | AE2: =AE17+AE30+AE43+AE56+AE69+AE82+AE95+AE108+AE121+AE134+AE147+AE160+AE173 -> 2
A3: 線別 | B3: 品類 | D3: 品名 | F3: 廠價 | G3: 生產量 | H3: 營收 | I3: 多次 生產 | J3: 人數 | K3: 產能/時 | L3: 人時性 | M3: 人數 | N3: 產能/時 | O3: 人時性 | P3: 人數 | Q3: 人時性 | R3: 達成率 | S3: 達成率平均 | T3: 生產時間 | V3: 前置、換線時間/分 | W3: 稼動時間/分 | X3: 休息時間 | Z3: 產線異常統計 (5分鐘以上) | AB3: 分析說明 | AD3: 短暫停線統計 (5分鐘以下) | AF3: 產能/時 | AG3: 達成率 | AH3: 達成率平均
T4: 開始 | U4: 結束 | X4: 開始 | Y4: 結束 | Z4: 次數 | AA4: 時間/分 | AD4: 總次數 | AE4: 設備因素(次數)
A5: 四度一組 (ET-600) | B5: 季節調理麵 | D5: 椒麻香蔥雞涼拌麵 | F5: 37.94 | G5: 3207.1 | H5: =F5*G5 -> 121677.37 | J5: 20 | K5: 2400 | L5: 120 | M5: 20 | N5: =G5/W5*60 -> 2237.5116 | O5: =N5/M5 -> 111.87558 | P5: =M5-J5 -> 0 | Q5: =O5-L5 -> -8.1244186 | R5: =O5/L5 -> 0.93229651 | S5: =R17 -> 0.94733345 | T5: 0.29166667 | U5: 0.35138889 | V5: 5 | W5: =(U5-T5)*24*60 -> 86 | AF5: =N5-K5 -> -162.48837 | AG5: =N5/K5 -> 0.93229651 | AH5: =AG17 -> 0.97861657
B6: 季節調理麵 | D6: 台式麻醬涼麵 | F6: 31.266132 | G6: 1899.95 | H6: =F6*G6 -> 59404.087 | J6: 18 | K6: 2600 | L6: 144.44444 | M6: 19 | N6: =G6/W6*60 -> 2590.8409 | O6: =N6/M6 -> 136.36005 | P6: =M6-J6 -> 1 | Q6: =O6-L6 -> -8.0843966 | R6: =O6/L6 -> 0.9440311 | T6: 0.35625 | U6: 0.38680556 | V6: 7 | W6: =(U6-T6)*24*60 -> 44 | AF6: =N6-K6 -> -9.1590909 | AG6: =N6/K6 -> 0.99647727
B7: 季節調理麵 | D7: 大滿足香辣涼麵 | F7: 38.630952 | G7: 2269.8 | H7: =F7*G7 -> 87684.536 | J7: 18 | K7: 2600 | L7: 144.44444 | M7: 19 | N7: =G7/W7*60 -> 2619 | O7: =N7/M7 -> 137.84211 | P7: =M7-J7 -> 1 | Q7: =O7-L7 -> -6.6023392 | R7: =O7/L7 -> 0.9542915 | T7: 0.40277778 | U7: 0.43888889 | V7: 23 | W7: =(U7-T7)*24*60 -> 52 | X7: 0.39027778 | Y7: 0.4 | AF7: =N7-K7 -> 19 | AG7: =N7/K7 -> 1.0073077
B8: 季節調理麵 | D8: 大滿足麻醬涼麵 | F8: 38 | G8: 4720.8 | H8: =F8*G8 -> 179390.4 | J8: 19 | K8: 2600 | L8: 136.84211 | M8: 20 | N8: =G8/W8*60 -> 2672.1509 | O8: =N8/M8 -> 133.60755 | P8: =M8-J8 -> 1 | Q8: =O8-L8 -> -3.2345581 | R8: =O8/L8 -> 0.97636284 | T8: 0.44375 | U8: 0.51736111 | V8: 7 | W8: =(U8-T8)*24*60 -> 106 | AF8: =N8-K8 -> 72.150943 | AG8: =N8/K8 -> 1.0277504
B9: 熱食義麵 | D9: 辣腐乳麻醬拌麵 | F9: 38.1 | G9: 832.65 | H9: =F9*G9 -> 31723.965 | J9: 17 | K9: 1500 | L9: 88.235294 | M9: 16 | N9: =G9/W9*60 -> 1314.7105 | O9: =N9/M9 -> 82.169408 | P9: =M9-J9 -> -1 | Q9: =O9-L9 -> -6.0658862 | R9: =O9/L9 -> 0.93125329 | T9: 0.55833333 | U9: 0.58472222 | V9: 6 | W9: =(U9-T9)*24*60 -> 38 | AF9: =N9-K9 -> -185.28947 | AG9: =N9/K9 -> 0.87647368
B10: 季節調理麵 | D10: 大滿足麻醬涼麵 | F10: 38 | G10: 2023.2 | H10: =F10*G10 -> 76881.6 | J10: 19 | K10: 2600 | L10: 136.84211 | M10: 20 | N10: =G10/W10*60 -> 2638.9565 | O10: =N10/M10 -> 131.94783 | P10: =M10-J10 -> 1 | Q10: =O10-L10 -> -4.8942792 | R10: =O10/L10 -> 0.96423411 | T10: 0.58958333 | U10: 0.62152778 | V10: 7 | W10: =(U10-T10)*24*60 -> 46 | AF10: =N10-K10 -> 38.956522 | AG10: =N10/K10 -> 1.0149833
B11: 季節調理麵 | D11: 大滿足香辣涼麵 | F11: 38.630952 | G11: 1222.2 | H11: =F11*G11 -> 47214.75 | J11: 18 | K11: 2600 | L11: 144.44444 | M11: 19 | N11: =G11/W11*60 -> 2619 | O11: =N11/M11 -> 137.84211 | P11: =M11-J11 -> 1 | Q11: =O11-L11 -> -6.6023392 | R11: =O11/L11 -> 0.9542915 | T11: 0.62569444 | U11: 0.64513889 | V11: 6 | W11: =(U11-T11)*24*60 -> 28 | AF11: =N11-K11 -> 19 | AG11: =N11/K11 -> 1.0073077
B12: 季節調理麵 | D12: 台式麻醬涼麵 | F12: 31.266132 | G12: 1023.05 | H12: =F12*G12 -> 31986.816 | J12: 18 | K12: 2600 | L12: 144.44444 | M12: 19 | N12: =G12/W12*60 -> 2557.625 | O12: =N12/M12 -> 134.61184 | P12: =M12-J12 -> 1 | Q12: =O12-L12 -> -9.8326023 | R12: =O12/L12 -> 0.93192814 | T12: 0.66041667 | U12: 0.67708333 | V12: 22 | W12: =(U12-T12)*24*60 -> 24 | X12: 0.64861111 | Y12: 0.65763889 | AF12: =N12-K12 -> -42.375 | AG12: =N12/K12 -> 0.98370192
B13: 季節調理麵 | D13: 椒麻香蔥雞涼拌麵 | F13: 37.94 | G13: 1726.9 | H13: =F13*G13 -> 65518.586 | J13: 20 | K13: 2400 | L13: 120 | M13: 20 | N13: =G13/W13*60 -> 2252.4783 | O13: =N13/M13 -> 112.62391 | P13: =M13-J13 -> 0 | Q13: =O13-L13 -> -7.376087 | R13: =O13/L13 -> 0.93853261 | T13: 0.68194444 | U13: 0.71388889 | V13: 7 | W13: =(U13-T13)*24*60 -> 46 | AF13: =N13-K13 -> -147.52174 | AG13: =N13/K13 -> 0.93853261
B14: 微波主食 | D14: 二配濃起司燻腸紅醬焗烤飯 | F14: 50.67 | G14: 1513.8 | H14: =F14*G14 -> 76704.246 | J14: 18 | K14: 1500 | L14: 83.333333 | M14: 18 | N14: =G14/W14*60 -> 1397.3538 | O14: =N14/M14 -> 77.630769 | P14: =M14-J14 -> 0 | Q14: =O14-L14 -> -5.7025641 | R14: =O14/L14 -> 0.93156923 | T14: 0.72986111 | U14: 0.775 | V14: 23 | W14: =(U14-T14)*24*60 -> 65 | X14: 0.71736111 | Y14: 0.72708333
B15: 0 | F15: 0 | H15: =F15*G15 -> 0 | W15: =(U15-T15)*24*60 -> 0
B16: 0 | F16: 0 | H16: =F16*G16 -> 0 | W16: =(U16-T16)*24*60 -> 0
B17: 0 | C17: 4度一組 | D17: 平均 | J17: 18.5 | K17: 2340 | L17: 126.30306 | M17: =AVERAGE(M5:M16) -> 19 | N17: =AVERAGE(N5:N16) -> 2289.9628 | O17: =AVERAGE(O5:O16) -> 119.65111 | P17: =M17-J17 -> 0.5 | Q17: =O17-L17 -> -6.651947 | R17: =O17/L17 -> 0.94733345 | W17: =(U17-T17)*24*60 -> 0 | Z17: =SUM(Z5:Z16) -> 0 | AA17: =SUM(AA5:AA16) -> 0 | AD17: =SUM(AD5:AD16) -> 0 | AE17: =SUM(AE5:AE16) -> 0 | AF17: =N17-K17 -> -50.037236 | AG17: =N17/K17 -> 0.97861657
A18: 四度二組A 熱麵 固定線 (ET-55) | B18: 季節調理麵 | D18: 日式蕎麥沾麵 | F18: 36.86 | G18: 2845 | H18: =F18*G18 -> 104866.7 | J18: 17 | K18: 2250 | L18: 132.35294 | M18: 18 | N18: =G18/W18*60 -> 2188.4615 | O18: =N18/M18 -> 121.5812 | P18: =M18-J18 -> 1 | Q18: =O18-L18 -> -10.771745 | R18: =O18/L18 -> 0.91861349 | S18: =R30 -> 0.89462448 | T18: 0.16666667 | U18: 0.22083333 | V18: 5 | W18: =(U18-T18)*24*60 -> 78 | AF18: =N18-K18 -> -61.538462 | AG18: =N18/K18 -> 0.97264957 | AH18: =AG30 -> 0.91935307
B19: 熱食義麵 | D19: 愛恨椒芝麵 | F19: 38.39 | G19: 1937.6 | H19: =F19*G19 -> 74384.464 | J19: 16 | K19: 1636 | L19: 102.25 | M19: 17 | N19: =G19/W19*60 -> 1417.7561 | O19: =N19/M19 -> 83.397418 | P19: =M19-J19 -> 1 | Q19: =O19-L19 -> -18.852582 | R19: =O19/L19 -> 0.81562267 | T19: 0.225 | U19: 0.28194444 | V19: 6 | W19: =(U19-T19)*24*60 -> 82 | AF19: =N19-K19 -> -218.2439 | AG19: =N19/K19 -> 0.86659908
B20: 小菜微波 | D20: 古早味炒炊粉 | F20: 43.14 | G20: 2081 | H20: =F20*G20 -> 89774.34 | J20: 16 | K20: 1440 | L20: 90 | M20: 16 | N20: =G20/W20*60 -> 1402.9213 | O20: =N20/M20 -> 87.682584 | P20: =M20-J20 -> 0 | Q20: =O20-L20 -> -2.3174157 | R20: =O20/L20 -> 0.97425094 | T20: 0.29791667 | U20: 0.35972222 | V20: 23 | W20: =(U20-T20)*24*60 -> 89 | X20: 0.28541667 | Y20: 0.29513889 | AF20: =N20-K20 -> -37.078652 | AG20: =N20/K20 -> 0.97425094
B21: 熱食義麵 | D21: 辣腐乳麻醬拌麵 | F21: 38.1 | G21: 2220.4 | H21: =F21*G21 -> 84597.24 | J21: 17 | K21: 1500 | L21: 88.235294 | M21: 17 | N21: =G21/W21*60 -> 1319.0495 | O21: =N21/M21 -> 77.591147 | P21: =M21-J21 -> 0 | Q21: =O21-L21 -> -10.644147 | R21: =O21/L21 -> 0.87936634 | T21: 0.36527778 | U21: 0.43541667 | V21: 8 | W21: =(U21-T21)*24*60 -> 101 | AF21: =N21-K21 -> -180.9505 | AG21: =N21/K21 -> 0.87936634
B22: 熱食義麵 | D22: 辣腐乳麻醬拌麵 | F22: 38.1 | G22: 2497.95 | H22: =F22*G22 -> 95171.895 | J22: 17 | K22: 1500 | L22: 88.235294 | M22: 17 | N22: =G22/W22*60 -> 1326.3451 | O22: =N22/M22 -> 78.020302 | P22: =M22-J22 -> 0 | Q22: =O22-L22 -> -10.214992 | R22: =O22/L22 -> 0.88423009 | T22: 0.47569444 | U22: 0.55416667 | V22: 5 | W22: =(U22-T22)*24*60 -> 113 | AF22: =N22-K22 -> -173.65487 | AG22: =N22/K22 -> 0.88423009
B23: 0 | F23: 0 | H23: =F23*G23 -> 0 | W23: =(U23-T23)*24*60 -> 0 | AF23: =N23-K23 -> 0 | AG23: =N23/K23 -> #DIV/0!
B24: 0 | F24: 0 | H24: =F24*G24 -> 0 | W24: =(U24-T24)*24*60 -> 0 | AF24: =N24-K24 -> 0 | AG24: =N24/K24 -> #DIV/0!
B25: 0 | F25: 0 | H25: =F25*G25 -> 0 | W25: =(U25-T25)*24*60 -> 0 | AF25: =N25-K25 -> 0 | AG25: =N25/K25 -> #DIV/0!
B26: 0 | F26: 0 | H26: =F26*G26 -> 0 | W26: =(U26-T26)*24*60 -> 0 | AF26: =N26-K26 -> 0 | AG26: =N26/K26 -> #DIV/0!
B27: 0 | F27: 0 | H27: =F27*G27 -> 0 | W27: =(U27-T27)*24*60 -> 0 | AF27: =N27-K27 -> 0 | AG27: =N27/K27 -> #DIV/0!
B28: 0 | F28: 0 | H28: =F28*G28 -> 0 | W28: =(U28-T28)*24*60 -> 0 | AF28: =N28-K28 -> 0 | AG28: =N28/K28 -> #DIV/0!
B29: 0 | F29: 0 | H29: =F29*G29 -> 0 | W29: =(U29-T29)*24*60 -> 0 | AF29: =N29-K29 -> 0
B30: 0 | C30: 4度二組A | D30: 平均 | J30: 16.6 | K30: 1665.2 | L30: 100.21471 | M30: =AVERAGE(M18:M29) -> 17 | N30: =AVERAGE(N18:N29) -> 1530.9067 | O30: =AVERAGE(O18:O29) -> 89.65453 | P30: =M30-J30 -> 0.4 | Q30: =O30-L30 -> -10.560176 | R30: =O30/L30 -> 0.89462448 | Z30: =SUM(Z18:Z29) -> 0 | AA30: =SUM(AA18:AA29) -> 0 | AD30: =SUM(AD18:AD29) -> 0 | AE30: =SUM(AE18:AE29) -> 0 | AF30: =N30-K30 -> -134.29328 | AG30: =N30/K30 -> 0.91935307
A31: 四度二組 (ET-55) | B31: 飯糰 | D31: 大口金黃薯牛堡飯糰 | F31: 34.23 | G31: 2136 | H31: =F31*G31 -> 73115.28 | J31: 13 | K31: 2250 | L31: 173.07692 | M31: 13 | N31: =G31/W31*60 -> 2067.0968 | O31: =N31/M31 -> 159.00744 | P31: =M31-J31 -> 0 | Q31: =O31-L31 -> -14.069479 | R31: =O31/L31 -> 0.91870968 | S31: =R43 -> 0.8792869 | T31: 0.16666667 | U31: 0.20972222 | V31: 5 | W31: =(U31-T31)*24*60 -> 62 | AF31: =N31-K31 -> -182.90323 | AG31: =N31/K31 -> 0.91870968 | AH31: =AG43 -> 0.88453795
B32: 飯糰 | D32: 大口日式塔塔醬蝦排飯糰 | F32: 35.33 | G32: 2243 | H32: =F32*G32 -> 79245.19 | J32: 12 | K32: 2118 | L32: 176.5 | M32: 12 | N32: =G32/W32*60 -> 2070.4615 | O32: =N32/M32 -> 172.53846 | P32: =M32-J32 -> 0 | Q32: =O32-L32 -> -3.9615385 | R32: =O32/L32 -> 0.97755502 | T32: 0.21527778 | U32: 0.26041667 | V32: 8 | W32: =(U32-T32)*24*60 -> 65 | AF32: =N32-K32 -> -47.538462 | AG32: =N32/K32 -> 0.97755502
B33: 飯糰 | D33: 大口義式香草雞腿排飯糰 | F33: 36.41 | G33: 2445.1 | H33: =F33*G33 -> 89026.091 | J33: 10 | K33: 2769 | L33: 276.9 | M33: 10 | N33: =G33/W33*60 -> 2292.2812 | O33: =N33/M33 -> 229.22812 | P33: =M33-J33 -> 0 | Q33: =O33-L33 -> -47.671875 | R33: =O33/L33 -> 0.82783722 | T33: 0.27569444 | U33: 0.32013889 | V33: 22 | W33: =(U33-T33)*24*60 -> 64 | X33: 0.26388889 | Y33: 0.27291667 | AF33: =N33-K33 -> -476.71875 | AG33: =N33/K33 -> 0.82783722
B34: 微波主食 | D34: 日式野菜烘蛋燴飯 | F34: 49.91 | G34: 724 | H34: =F34*G34 -> 36134.84 | J34: 17 | K34: 1500 | L34: 88.235294 | M34: 17 | N34: =G34/W34*60 -> 1316.3636 | O34: =N34/M34 -> 77.433155 | P34: =M34-J34 -> 0 | Q34: =O34-L34 -> -10.802139 | R34: =O34/L34 -> 0.87757576 | T34: 0.325 | U34: 0.34791667 | V34: 7 | W34: =(U34-T34)*24*60 -> 33 | AF34: =N34-K34 -> -183.63636 | AG34: =N34/K34 -> 0.87757576
B35: 微波主食 | D35: 壽喜燒牛丼 | F35: 53.27 | G35: 1260 | H35: =F35*G35 -> 67120.2 | J35: 18 | K35: 1500 | L35: 83.333333 | M35: 18 | N35: =G35/W35*60 -> 1326.3158 | O35: =N35/M35 -> 73.684211 | P35: =M35-J35 -> 0 | Q35: =O35-L35 -> -9.6491228 | R35: =O35/L35 -> 0.88421053 | T35: 0.3625 | U35: 0.40208333 | V35: 21 | W35: =(U35-T35)*24*60 -> 57 | X35: 0.35138889 | Y35: 0.35972222 | AF35: =N35-K35 -> -173.68421 | AG35: =N35/K35 -> 0.88421053
B36: 小菜微波 | D36: 香辣醬粉絲煲 | F36: 29.11315 | G36: 2570.88 | H36: =F36*G36 -> 74846.415 | J36: 20 | K36: 1500 | L36: 75 | M36: 20 | N36: =G36/W36*60 -> 1329.7655 | O36: =N36/M36 -> 66.488276 | P36: =M36-J36 -> 0 | Q36: =O36-L36 -> -8.5117241 | R36: =O36/L36 -> 0.88651034 | T36: 0.41805556 | U36: 0.49861111 | V36: 23 | W36: =(U36-T36)*24*60 -> 116 | X36: 0.40555556 | Y36: 0.41527778 | AF36: =N36-K36 -> -170.23448 | AG36: =N36/K36 -> 0.88651034
B37: 熱食義麵 | D37: 愛恨椒芝麵 | F37: 38.39 | G37: 830.4 | H37: =F37*G37 -> 31879.056 | I37: 2 | J37: 16 | K37: 1636 | L37: 102.25 | M37: 17 | N37: =G37/W37*60 -> 1346.5946 | O37: =N37/M37 -> 79.211447 | P37: =M37-J37 -> 1 | Q37: =O37-L37 -> -23.038553 | R37: =O37/L37 -> 0.77468408 | T37: 0.54305556 | U37: 0.56875 | V37: 7 | W37: =(U37-T37)*24*60 -> 37 | AF37: =N37-K37 -> -289.40541 | AG37: =N37/K37 -> 0.82310183
B38: 小菜微波 | D38: 香辣醬粉絲煲 | F38: 29.11315 | G38: 725.12 | H38: =F38*G38 -> 21110.527 | I38: 2 | J38: 20 | K38: 1500 | L38: 75 | M38: 20 | N38: =G38/W38*60 -> 1318.4 | O38: =N38/M38 -> 65.92 | P38: =M38-J38 -> 0 | Q38: =O38-L38 -> -9.08 | R38: =O38/L38 -> 0.87893333 | T38: 0.57430556 | U38: 0.59722222 | V38: 8 | W38: =(U38-T38)*24*60 -> 33 | AF38: =N38-K38 -> -181.6 | AG38: =N38/K38 -> 0.87893333
B39: 0 | F39: 0 | H39: =F39*G39 -> 0 | W39: =(U39-T39)*24*60 -> 0 | AF39: =N39-K39 -> 0 | AG39: =N39/K39 -> #DIV/0!
B40: 0 | F40: 0 | H40: =F40*G40 -> 0 | W40: =(U40-T40)*24*60 -> 0 | AF40: =N40-K40 -> 0 | AG40: =N40/K40 -> #DIV/0!
...

Sheet 0305
B1: 晉欣廠組合室生產人時性分析
B3: 日期 | D3: 03月05日 星期四 | F3: 訂單量 | H3: 219457.8 | J3: 營業額 | L3: 7056112.2
B4: 項目 | D4: 項目 | F4: ➀ | H4: ➁ | J4: ➂ | L4: ➃ | N4: 異常停線 | P4: 短暫停線
B5: 人時性 | D5: 組合室 | F5: 全溫層 | H5: 4度C(含4度飯糰) | J5: 18度C 一配 | L5: 18度C 二配 | N5: 合計次數 | O5: 時間 | P5: 合計次數 | Q5: 設備次數
D6: 排關平均 | F6: =AVERAGE(D13:O13,P13:Q13,D30:F30,H30,J30:M30) -> 378.41238 | H6: =AVERAGE(D13:P13,Q13) -> 137.86231 | J6: =AVERAGE(D30:H30) -> 754 | L6: =AVERAGE(J30:M30) -> 881.25 | N6: 0 | O6: 0 | P6: 1 | Q6: 0
D7: 實績平均 | F7: =AVERAGE(D14:O14,P14:Q14,D31:F31,J31:M31,H31) -> 357.43896 | H7: =AVERAGE(D14:P14,Q14) -> 122.57858 | J7: =AVERAGE(D31:H31) -> 745.29643 | L7: =AVERAGE(J31:M31) -> 821.82475
D8: 達成率平均 | F8: =AVERAGE(D15:O15,P15:Q15,D32:F32,H32,J32:K32,L32) -> 0.90516521 | H8: =AVERAGE(D15:O15,P15:Q15) -> 0.88441195 | J8: =AVERAGE(D32:H32) -> 0.96942047 | L8: =AVERAGE(J32:M32) -> 0.93434021
B10: 溫層 | D10: ➁4度C-各編組展開
B11: 編組 | D11: 1 | E11: 2 | F11: 3 | G11: 4 | H11: 5 | I11: 6 | J11: 7 | K11: 8 | L11: 9 | M11: 10 | N11: 11 | O11: 12 | P11: 13 | Q11: 14
D12: 4度一組 | E12: 4度二組A | F12: 4度二組B | G12: 4度二組C1 | H12: 4度一組B | I12: 4度三組 | J12: 4度四組 | K12: 4度五組 | L12: 綜合一組 | M12: 綜合二組 | N12: 綜合三組 | O12: 綜合四組 | P12: 便當組 | Q12: 壽司線
B13: 人時性 | C13: 排關 | D13: 130.53281 | E13: 100.21471 | F13: 131.28694 | G13: 368.5 | H13: 228.57143 | I13: 92.599129 | J13: 75.913945 | K13: 113.47619 | L13: 85.272067 | M13: 81.34291 | N13: 83.75586 | O13: 87.786458 | P13: 200.81986 | Q13: 150
C14: 實績 | D14: 123.97829 | E14: 89.953753 | F14: 115.86827 | G14: 317.08008 | H14: 210.11766 | I14: 80.16876 | J14: 62.862716 | K14: 96.994624 | L14: 74.158531 | M14: 70.535632 | N14: 75.809671 | O14: 72.972307 | P14: 189.89019 | Q14: 135.70961
C15: 達成率 | D15: =D14/D13 -> 0.94978643 | E15: =E14/E13 -> 0.89761031 | F15: =F14/F13 -> 0.88255745 | G15: =G14/G13 -> 0.86046156 | H15: =H14/H13 -> 0.91926476 | I15: =I14/I13 -> 0.8657615 | J15: =J14/J13 -> 0.82807864 | K15: =K14/K13 -> 0.85475749 | ... Q15: =Q14/Q13 -> 0.90473076
B16: 作業 時間 | C16: 開始 | D16: 0.29166667 | E16: 0.16666667 | F16: 0.16666667 | G16: 0.16666667 | H16: 0.16666667 | I16: 0.29166667 | J16: 0.33333333 | K16: 0.33333333 | L16: 0.5 | M16: 0.5 | N16: 0.70833333 | O16: 0.70833333 | P16: 0.16666667 | Q16: 0.17361111
C17: 結束 | D17: 0.73055556 | E17: 0.54513889 | F17: 0.57847222 | G17: 0.65555556 | H17: 0.63472222 | I17: 0.72638889 | J17: 0.78194444 | K17: 0.76458333 | L17: 0.87430556 | M17: 0.90555556 | N17: 0.94097222 | O17: 0.80972222 | P17: 0.57986111 | Q17: 0.63194444
B18: 產線異常 (5分鐘以上)
B20: 短暫停線 (5分鐘以下) | F20: 1
B22: 配置人數 | D22: 19.333333 | E22: 17 | F22: 15.875 | G22: 5.75 | H22: 7 | I22: 16.166667 | J22: 19.285714 | K22: 15.571429 | L22: 17.75 | M22: 19.125 | N22: 17.833333 | O22: 17.25 | P22: 11.8 | Q22: 11.2
B23: 主要應用設備 | D23: ET-600 | E23: ET-600 | F23: ET-600 | G23: 八爪機 | H23: 十爪機 | I23: ET-55 | J23: ET-55 | K23: ET-55 | L23: ET-55 | M23: ET-55 | N23: ET-55 | O23: ET-55 | P23: 伺服包裝機 | Q23: 伺服包裝機
B24: 次要應用設備
B25: 備註 | E25: 熱麵固定線 | G25: 烤飯糰 | H25: 烤飯糰 | K25: 吸收產線 | P25: 大口固定線
B27: 溫層 | D27: ➂18度C 一配-各編組展開 | I27: ➃18度C 二配-各編組展開
B28: 編組 | D28: 1 | E28: 2 | F28: 3 | G28: 4 | H28: 5 | I28: 1 | J28: 2 | K28: 3 | L28: 4 | M28: 5
D29: 連續式 海苔機 | E29: 3300型 飯糰機A | F29: 3300型 飯糰機B | G29: 3600型 飯糰機A | H29: 3600型 飯糰機B | I29: 夾心型 飯糰機 | J29: 3300型 飯糰機A | K29: 3300型 飯糰機B | L29: 3600型 飯糰機A | M29: 3600型 飯糰機B
B30: 人時性 | C30: 排關 | D30: 320 | E30: 825 | F30: 825 | G30: 900 | H30: 900 | I30: 680 | J30: 825 | K30: 900 | L30: 900 | M30: 900
C31: 實績 | D31: 270.41905 | E31: 681.6132 | F31: 921.91667 | G31: 866.22413 | H31: 986.3091 | I31: 0 | J31: 839.58333 | K31: 642.29954 | L31: 909.65541 | M31: 895.76071
C32: 達成率 | D32: =D31/D30 -> 0.84505952 | E32: =E31/E30 -> 0.82619781 | F32: =F31/F30 -> 1.1174747 | G32: =G31/G30 -> 0.96247125 | H32: =H31/H30 -> 1.095899 | I32: =I31/I30 -> 0 | J32: =J31/J30 -> 1.0176768 | K32: =K31/K30 -> 0.71366615 | ... M32: =M31/M30 -> 0.99528968
B33: 作業 時間 | C33: 開始 | D33: 0.18055556 | E33: 0.18055556 | F33: 0.18055556 | G33: 3138.9474 | H33: 0.18055556 | I33: 0 | J33: 0.72222222 | K33: 0.72222222 | L33: 0.72222222 | M33: 0.72222222
C34: 結束 | D34: 0.23541667 | E34: 0.33333333 | F34: 0.24166667 | G34: 1070.5882 | H34: 0.42569444 | I34: 0 | J34: 0.82638889 | K34: 0.85416667 | L34: 46087.073 | M34: 0.90972222
B35: 配置人數 | D35: 5.5 | E35: 4 | F35: 3 | G35: 3.75 | H35: 3.2 | I35: 0 | J35: 3.6666667 | K35: 3.6666667 | L35: 3.4 | M35: 3.5
B36: 主要應用設備 | D36: 連續式 海苔機 | E36: 3300型 | F36: 3300型 | G36: 3600型 | H36: 3600型 | I36: 夾心型 | J36: 3300型 | K36: 3300型 | L36: 3600型 | M36: 3600型
B37: 次要應用設備
B38: 備註

Sheet 晉欣18度C0305
A1: 晉欣廠18度C日報分析 | D1: 總生產量 | E1: =SUM(G5:G124) -> 79881 | F1: 營業額 | G1: =SUM(H5:H124) -> 1533631 | H1: 出勤人數 | I1: =+J16+J64+J24+J38+J51+J81+J100+J91+J57+J124+J111 -> 41.683333 | J1: 生產實績 | M1: 日報登錄
A2: 03月05日 星期四 | D2: 人時性 | E2: =AVERAGE(L16,L24,L38,L51,L100,L111,L91) -> 628.7424 | F2: 平均廠價 | G2: =G1/E1 -> 19.198946 | H2: 多次生產數 | I2: =COUNT(I5:I124) -> 0
A3: 線別 | B3: 品類 | D3: 品名 | F3: 廠價 | G3: 生產量 | H3: 營收 | I3: 多次 生產 | J3: 人數 | K3: 產能/時 | L3: 人時性 | M3: 生產時間 | O3: 換線/分 | P3: 稼動時間/分 | Q3: 休息時間
M4: 開始 | N4: 結束 | Q4: 開始 | R4: 結束
A5: 壽司線 | B5: 飯糰 | D5: 麻油雞飯糰 | F5: 29.965493 | G5: 1541 | H5: =F5*G5 -> 46176.825 | J5: 13 | K5: =G5/P5*60 -> 1232.8 | L5: =K5/J5 -> 94.830769 | M5: 0.17361111 | N5: 0.22569444 | O5: 10 | P5: =(N5-M5)*24*60 -> 75
B6: 0 | D6: 雙饗雙手卷(捲) | F6: 0 | G6: 1356 | H6: =F6*G6 -> 0 | J6: 9 | K6: =G6/P6*60 -> 1479.2727 | L6: =K6/J6 -> 164.36364 | M6: 0.22916667 | N6: 0.26736111 | O6: 5 | P6: =(N6-M6)*24*60 -> 55
B7: 0 | D7: 海饌雙手卷(捲) | F7: 0 | G7: 1445 | H7: =F7*G7 -> 0 | J7: 9 | K7: =G7/P7*60 -> 1576.3636 | L7: =K7/J7 -> 175.15152 | M7: 0.27083333 | N7: 0.30902778 | O7: 5 | P7: =(N7-M7)*24*60 -> 55
B8: 壽司手卷 | D8: 雙倍德腸飯卷 | F8: 36.45 | G8: 2077 | H8: =F8*G8 -> 75706.65 | J8: 10 | K8: =G8/P8*60 -> 1466.1176 | L8: =K8/J8 -> 146.61176 | M8: 0.3125 | N8: 0.37152778 | O8: 5 | P8: =(N8-M8)*24*60 -> 85
B9: 壽司手卷 | D9: 明太子泡菜牛飯卷 | F9: 27.05 | G9: 500 | H9: =F9*G9 -> 13525 | J9: 13 | K9: =G9/P9*60 -> 1500 | L9: =K9/J9 -> 115.38462 | M9: 0.375 | N9: 0.38888889 | O9: 5 | P9: =(N9-M9)*24*60 -> 20 | Q9: 0.38888889 | R9: 0.43055556
B10: 壽司手卷 | D10: 日式鮪魚美乃滋脆卷 | F10: 17.87 | G10: 1536 | H10: =F10*G10 -> 27448.32 | J10: 12 | K10: =G10/P10*60 -> 1152 | L10: =K10/J10 -> 96 | M10: 0.43055556 | N10: 0.48611111 | O10: 5 | P10: =(N10-M10)*24*60 -> 80
B11: 壽司手卷 | D11: 長野稻荷壽司 | F11: 25.64 | G11: 743 | H11: =F11*G11 -> 19050.52 | J11: 12 | K11: =G11/P11*60 -> 1486 | L11: =K11/J11 -> 123.83333 | M11: 0.48958333 | N11: 0.51041667 | O11: 5 | P11: =(N11-M11)*24*60 -> 30
B12: 壽司手卷 | D12: 雙饗雙手卷 | F12: 29.52 | G12: 1356 | H12: =F12*G12 -> 40029.12 | J12: 12 | K12: =G12/P12*60 -> 1808 | L12: =K12/J12 -> 150.66667 | M12: 0.51388889 | N12: 0.54513889 | O12: 5 | P12: =(N12-M12)*24*60 -> 45
B13: 壽司手卷 | D13: 海饌雙手卷 | F13: 29.857 | G13: 1445 | H13: =F13*G13 -> 43143.365 | J13: 12 | K13: =G13/P13*60 -> 1734 | L13: =K13/J13 -> 144.5 | M13: 0.54861111 | N13: 0.58333333 | O13: 5 | P13: =(N13-M13)*24*60 -> 50
B14: 飯糰 | D14: 兩粒飯糰(鮪魚.焦糖鮭魚) | F14: 28.57 | G14: 1579 | H14: =F14*G14 -> 45112.03 | J14: 10 | K14: =G14/P14*60 -> 1457.5385 | L14: =K14/J14 -> 145.75385 | M14: 0.58680556 | N14: 0.63194444 | O14: 5 | P14: =(N14-M14)*24*60 -> 65
B15: 0 | F15: 0 | H15: =F15*G15 -> 0
B16: 0 | C16: 壽司線 | D16: 平均 | J16: =AVERAGE(J5:J15) -> 11.2 | K16: =AVERAGE(K5:K15) -> 1489.2092 | L16: =AVERAGE(L5:L15) -> 135.70961
A17: 捲壽司機 | B17: 壽司手卷 | D17: 雙鬆細卷 | F17: 14.03 | G17: 592 | H17: =F17*G17 -> 8305.76 | J17: 6 | K17: =G17/P17*60 -> 1480 | L17: =K17/J17 -> 246.66667 | M17: 0.18055556 | N17: 0.19722222 | O17: 20 | P17: =(N17-M17)*24*60 -> 24
B18: 飯糰 | D18: 經典鮪魚沙拉細卷 | F18: 14.49 | G18: 858 | H18: =F18*G18 -> 12432.42 | J18: 5 | K18: =G18/P18*60 -> 1470.8571 | L18: =K18/J18 -> 294.17143 | M18: 0.21111111 | N18: 0.23541667 | O18: 20 | P18: =(N18-M18)*24*60 -> 35
B19: 0 | F19: 0 | H19: =F19*G19 -> 0
B20: 0 | F20: 0 | H20: =F20*G20 -> 0
B21: 0 | F21: 0 | H21: =F21*G21 -> 0
B22: 0 | F22: 0 | H22: =F22*G22 -> 0
B23: 0 | F23: 0 | H23: =F23*G23 -> 0
B24: 0 | C24: 連續式 海苔機 | D24: 平均 | J24: =AVERAGE(J17:J23) -> 5.5 | K24: =AVERAGE(K17:K23) -> 1475.4286 | L24: =AVERAGE(L17:L23) -> 270.41905
A25: 3300型 飯糰機A | B25: 飯糰 | D25: 壹號醬炙烤牛飯糰 | F25: 22.281818 | G25: 628 | H25: =F25*G25 -> 13992.982 | J25: 4 | K25: =G25/P25*60 -> 2691.4286 | L25: =K25/J25 -> 672.85714 | M25: 0.18055556 | N25: 0.19027778 | O25: 20 | P25: =(N25-M25)*24*60 -> 14
B26: 飯糰 | D26: 碳烤燒肉飯飯糰(區) | F26: 18.18 | G26: 2901 | H26: =F26*G26 -> 52740.18 | J26: 4 | K26: =G26/P26*60 -> 2762.8571 | L26: =K26/J26 -> 690.71429 | M26: 0.20416667 | N26: 0.24791667 | O26: 20 | P26: =(N26-M26)*24*60 -> 63
B27: 飯糰 | D27: 紅運烏魚子紹興飯糰 | F27: 27.27 | G27: 1088 | H27: =F27*G27 -> 29669.76 | J27: 4 | K27: =G27/P27*60 -> 2720 | L27: =K27/J27 -> 680 | M27: 0.26180556 | N27: 0.27847222 | O27: 20 | P27: =(N27-M27)*24*60 -> 24
B28: 飯糰 | D28: 煙燻培根飯糰(區) | F28: 15.03 | G28: 2686 | H28: =F28*G28 -> 40370.58 | J28: 4 | K28: =G28/P28*60 -> 2731.5254 | L28: =K28/J28 -> 682.88136 | M28: 0.29236111 | N28: 0.33333333 | O28: 20 | P28: =(N28-M28)*24*60 -> 59
B29: 0 | F29: 0 | H29: =F29*G29 -> 0
B30: 0 | F30: 0 | H30: =F30*G30 -> 0
B31: 0 | F31: 0 | H31: =F31*G31 -> 0
B32: 0 | F32: 0 | H32: =F32*G32 -> 0
B33: 0 | F33: 0 | H33: =F33*G33 -> 0
B34: 0 | F34: 0 | H34: =F34*G34 -> 0
B35: 0 | F35: 0 | H35: =F35*G35 -> 0
B36: 0 | F36: 0 | H36: =F36*G36 -> 0
B37: 0 | F37: 0 | H37: =F37*G37 -> 0
B38: 0 | C38: 3300型 飯糰機A | D38: 平均 | J38: =AVERAGE(J25:J37) -> 4 | K38: =AVERAGE(K25:K37) -> 2726.4528 | L38: =AVERAGE(L25:L37) -> 681.6132
A39: 3300型B 飯糰機 | B39: 飯糰 | D39: 照燒雞肉飯糰 | F39: 21.45 | G39: 913 | H39: =F39*G39 -> 19583.85 | J39: 3 | K39: =G39/P39*60 -> 2739 | L39: =K39/J39 -> 913 | M39: 0.18055556 | N39: 0.19444444 | O39: 20 | P39: =(N39-M39)*24*60 -> 20
B40: 飯糰 | D40: 鮭魚奶油醬油飯糰 | F40: 18.53 | G40: 2234 | H40: =F40*G40 -> 41396.02 | J40: 3 | K40: =G40/P40*60 -> 2792.5 | L40: =K40/J40 -> 930.83333 | M40: 0.20833333 | N40: 0.24166667 | O40: 20 | P40: =(N40-M40)*24*60 -> 48
...

Sheet 晉欣4度C0305
A1: 晉欣廠四度C日報分析 | D1: 總生產量 | E1: =SUM(G5:G173) -> 139576.8 | F1: 營業額 | G1: =SUM(H5:H173) -> 5522481.2 | H1: 出勤人數 | I1: =M17+M30+M43+M56+M69+M82+M95+M108+M121+M134+M147+M160+M173 -> 199.74048 | J1: 產線配置圖 | M1: 生產實績 | P1: 人時性差異分析 | T1: 日報登錄 | Z1: 合計 次數 | AA1: 合計 時間/分 | AB1: 產線異常分析 說明(5分鐘以上) | AD1: 合計 次數 | AE1: 合計 設備次數 | AF1: 產能差異分析
A2: 03月05日 星期四 | D2: 人時性 | E2: =AVERAGE(O17,O30,O43,O56,O69,O82,O95,O108,O121,O134,O147,O160,O173) -> 121.5685 | F2: 平均廠價 | G2: =G1/E1 -> 39.565896 | H2: 多次生產數 | I2: =COUNT(I5:I173) -> 6 | Z2: =Z17+Z30+Z43+Z56+Z69+Z82+Z95+Z108+Z121+Z134+Z147+Z160+Z173 -> 0 | AA2: =AA17+AA30+AA43+AA56+AA69+AA82+AA95+AA108+AA121+AA134+AA147+AA160+AA173 -> 0 | AD2: =AD17+AD30+AD43+AD56+AD69+AD82+AD95+AD108+AD121+AD134+AD147+AD160+AD173 -> 1 | AE2: =AE17+AE30+AE43+AE56+AE69+AE82+AE95+AE108+AE121+AE134+AE147+AE160+AE173 -> 0
A3: 線別 | B3: 品類 | D3: 品名 | F3: 廠價 | G3: 生產量 | H3: 營收 | I3: 多次 生產 | J3: 人數 | K3: 產能/時 | L3: 人時性 | M3: 人數 | N3: 產能/時 | O3: 人時性 | P3: 人數 | Q3: 人時性 | R3: 達成率 | S3: 達成率平均 | T3: 生產時間 | V3: 前置、換線時間/分 | W3: 稼動時間/分 | X3: 休息時間 | Z3: 產線異常統計 (5分鐘以上) | AB3: 分析說明 | AD3: 短暫停線統計 (5分鐘以下) | AF3: 產能/時 | AG3: 達成率 | AH3: 達成率平均
T4: 開始 | U4: 結束 | X4: 開始 | Y4: 結束 | Z4: 次數 | AA4: 時間/分 | AD4: 總次數 | AE4: 設備因素(次數)
A5: 四度一組 (ET-600) | B5: 季節調理麵 | D5: 椒麻香蔥雞涼拌麵 | F5: 37.94 | G5: 2737.8 | H5: =F5*G5 -> 103872.13 | J5: 20 | K5: 2400 | L5: 120 | M5: 20 | N5: =G5/W5*60 -> 2281.5 | O5: =N5/M5 -> 114.075 | P5: =M5-J5 -> 0 | Q5: =O5-L5 -> -5.925 | R5: =O5/L5 -> 0.950625 | S5: =R17 -> 0.94978643 | T5: 0.29166667 | U5: 0.34166667 | V5: 5 | W5: =(U5-T5)*24*60 -> 72 | AF5: =N5-K5 -> -118.5 | AG5: =N5/K5 -> 0.950625 | AH5: =AG17 -> 0.98684619
B6: 季節調理麵 | D6: 台式麻醬涼麵 | F6: 31.266132 | G6: 1180.4 | H6: =F6*G6 -> 36906.542 | J6: 18 | K6: 2600 | L6: 144.44444 | M6: 19 | N6: =G6/W6*60 -> 2623.1111 | O6: =N6/M6 -> 138.05848 | P6: =M6-J6 -> 1 | Q6: =O6-L6 -> -6.3859649 | R6: =O6/L6 -> 0.95578947 | T6: 0.34722222 | U6: 0.36597222 | V6: 8 | W6: =(U6-T6)*24*60 -> 27 | AF6: =N6-K6 -> 23.111111 | AG6: =N6/K6 -> 1.0088889
B7: 季節調理麵 | D7: 大滿足香辣涼麵 | F7: 38.630952 | G7: 1933.75 | H7: =F7*G7 -> 74702.604 | J7: 18 | K7: 2600 | L7: 144.44444 | M7: 19 | N7: =G7/W7*60 -> 2636.9318 | O7: =N7/M7 -> 138.78589 | P7: =M7-J7 -> 1 | Q7: =O7-L7 -> -5.6585593 | R7: =O7/L7 -> 0.96082536 | T7: 0.38263889 | U7: 0.41319444 | V7: 24 | W7: =(U7-T7)*24*60 -> 44 | X7: 0.36944444 | Y7: 0.37986111 | AF7: =N7-K7 -> 36.931818 | AG7: =N7/K7 -> 1.0142045
B8: 季節調理麵 | D8: 大滿足麻醬涼麵 | F8: 38 | G8: 3367.7 | H8: =F8*G8 -> 127972.6 | J8: 19 | K8: 2600 | L8: 136.84211 | M8: 20 | N8: =G8/W8*60 -> 2624.1818 | O8: =N8/M8 -> 131.20909 | P8: =M8-J8 -> 1 | Q8: =O8-L8 -> -5.6330144 | R8: =O8/L8 -> 0.95883566 | T8: 0.41736111 | U8: 0.47083333 | V8: 6 | W8: =(U8-T8)*24*60 -> 77 | AF8: =N8-K8 -> 24.181818 | AG8: =N8/K8 -> 1.0093007
B9: 季節調理麵 | D9: 大滿足麻醬涼麵 | F9: 38 | G9: 1443.3 | H9: =F9*G9 -> 54845.4 | J9: 19 | K9: 2600 | L9: 136.84211 | M9: 20 | N9: =G9/W9*60 -> 2624.1818 | O9: =N9/M9 -> 131.20909 | P9: =M9-J9 -> 1 | Q9: =O9-L9 -> -5.6330144 | R9: =O9/L9 -> 0.95883566 | T9: 0.5125 | U9: 0.53541667 | V9: 7 | W9: =(U9-T9)*24*60 -> 33 | AF9: =N9-K9 -> 24.181818 | AG9: =N9/K9 -> 1.0093007
B10: 季節調理麵 | D10: 大滿足香辣涼麵 | F10: 38.630952 | G10: 1041.25 | H10: =F10*G10 -> 40224.479 | J10: 18 | K10: 2600 | L10: 144.44444 | M10: 19 | N10: =G10/W10*60 -> 2603.125 | O10: =N10/M10 -> 137.00658 | P10: =M10-J10 -> 1 | Q10: =O10-L10 -> -7.4378655 | R10: =O10/L10 -> 0.94850709 | T10: 0.54097222 | U10: 0.55763889 | V10: 8 | W10: =(U10-T10)*24*60 -> 24 | AF10: =N10-K10 -> 3.125 | AG10: =N10/K10 -> 1.0012019
B11: 季節調理麵 | D11: 台式麻醬涼麵 | F11: 31.266132 | G11: 635.6 | H11: =F11*G11 -> 19872.753 | J11: 18 | K11: 2600 | L11: 144.44444 | M11: 19 | N11: =G11/W11*60 -> 2542.4 | O11: =N11/M11 -> 133.81053 | P11: =M11-J11 -> 1 | Q11: =O11-L11 -> -10.633918 | R11: =O11/L11 -> 0.92638057 | T11: 0.56111111 | U11: 0.57152778 | V11: 5 | W11: =(U11-T11)*24*60 -> 15 | AF11: =N11-K11 -> -57.6 | AG11: =N11/K11 -> 0.97784615
